[2023-03-13T19:51:46.040+0000] {taskinstance.py:1083} INFO - Dependencies all met for <TaskInstance: AUTOMATISATION.Chargement_des_données_in_ELK scheduled__2023-03-13T00:00:27+00:00 [queued]>
[2023-03-13T19:51:46.051+0000] {taskinstance.py:1083} INFO - Dependencies all met for <TaskInstance: AUTOMATISATION.Chargement_des_données_in_ELK scheduled__2023-03-13T00:00:27+00:00 [queued]>
[2023-03-13T19:51:46.051+0000] {taskinstance.py:1279} INFO - 
--------------------------------------------------------------------------------
[2023-03-13T19:51:46.051+0000] {taskinstance.py:1280} INFO - Starting attempt 3 of 4
[2023-03-13T19:51:46.052+0000] {taskinstance.py:1281} INFO - 
--------------------------------------------------------------------------------
[2023-03-13T19:51:46.070+0000] {taskinstance.py:1300} INFO - Executing <Task(BashOperator): Chargement_des_données_in_ELK> on 2023-03-13 00:00:27+00:00
[2023-03-13T19:51:46.073+0000] {standard_task_runner.py:55} INFO - Started process 38647 to run task
[2023-03-13T19:51:46.077+0000] {standard_task_runner.py:82} INFO - Running: ['airflow', 'tasks', 'run', 'AUTOMATISATION', 'Chargement_des_données_in_ELK', 'scheduled__2023-03-13T00:00:27+00:00', '--job-id', '109', '--raw', '--subdir', 'DAGS_FOLDER/main.py', '--cfg-path', '/tmp/tmpd7nb_856']
[2023-03-13T19:51:46.079+0000] {standard_task_runner.py:83} INFO - Job 109: Subtask Chargement_des_données_in_ELK
[2023-03-13T19:51:46.142+0000] {task_command.py:388} INFO - Running <TaskInstance: AUTOMATISATION.Chargement_des_données_in_ELK scheduled__2023-03-13T00:00:27+00:00 [running]> on host dev
[2023-03-13T19:51:46.203+0000] {taskinstance.py:1507} INFO - Exporting the following env vars:
AIRFLOW_CTX_DAG_OWNER=airflow
AIRFLOW_CTX_DAG_ID=AUTOMATISATION
AIRFLOW_CTX_TASK_ID=Chargement_des_données_in_ELK
AIRFLOW_CTX_EXECUTION_DATE=2023-03-13T00:00:27+00:00
AIRFLOW_CTX_TRY_NUMBER=3
AIRFLOW_CTX_DAG_RUN_ID=scheduled__2023-03-13T00:00:27+00:00
[2023-03-13T19:51:46.205+0000] {subprocess.py:63} INFO - Tmp dir root location: 
 /tmp
[2023-03-13T19:51:46.206+0000] {subprocess.py:75} INFO - Running command: ['/usr/bin/bash', '-c', 'bin/logstash --path.config /etc/logstash/conf.d/data.conf']
[2023-03-13T19:51:46.214+0000] {subprocess.py:86} INFO - Output:
[2023-03-13T19:51:46.216+0000] {subprocess.py:93} INFO - /usr/bin/bash: ligne 1: bin/logstash: Aucun fichier ou dossier de ce type
[2023-03-13T19:51:46.216+0000] {subprocess.py:97} INFO - Command exited with return code 127
[2023-03-13T19:51:46.227+0000] {taskinstance.py:1768} ERROR - Task failed with exception
Traceback (most recent call last):
  File "/home/dev/airflow/airflow/lib/python3.10/site-packages/airflow/operators/bash.py", line 196, in execute
    raise AirflowException(
airflow.exceptions.AirflowException: Bash command failed. The command returned a non-zero exit code 127.
[2023-03-13T19:51:46.231+0000] {taskinstance.py:1318} INFO - Marking task as UP_FOR_RETRY. dag_id=AUTOMATISATION, task_id=Chargement_des_données_in_ELK, execution_date=20230313T000027, start_date=20230313T195146, end_date=20230313T195146
[2023-03-13T19:51:46.249+0000] {standard_task_runner.py:100} ERROR - Failed to execute job 109 for task Chargement_des_données_in_ELK (Bash command failed. The command returned a non-zero exit code 127.; 38647)
[2023-03-13T19:51:46.288+0000] {local_task_job.py:208} INFO - Task exited with return code 1
[2023-03-13T19:51:46.309+0000] {taskinstance.py:2578} INFO - 0 downstream tasks scheduled from follow-on schedule check
[2023-03-13T20:13:15.314+0000] {taskinstance.py:1083} INFO - Dependencies all met for <TaskInstance: AUTOMATISATION.Chargement_des_données_in_ELK scheduled__2023-03-13T00:00:27+00:00 [queued]>
[2023-03-13T20:13:15.327+0000] {taskinstance.py:1083} INFO - Dependencies all met for <TaskInstance: AUTOMATISATION.Chargement_des_données_in_ELK scheduled__2023-03-13T00:00:27+00:00 [queued]>
[2023-03-13T20:13:15.328+0000] {taskinstance.py:1279} INFO - 
--------------------------------------------------------------------------------
[2023-03-13T20:13:15.328+0000] {taskinstance.py:1280} INFO - Starting attempt 3 of 4
[2023-03-13T20:13:15.328+0000] {taskinstance.py:1281} INFO - 
--------------------------------------------------------------------------------
[2023-03-13T20:13:15.351+0000] {taskinstance.py:1300} INFO - Executing <Task(BashOperator): Chargement_des_données_in_ELK> on 2023-03-13 00:00:27+00:00
[2023-03-13T20:13:15.355+0000] {standard_task_runner.py:55} INFO - Started process 42508 to run task
[2023-03-13T20:13:15.359+0000] {standard_task_runner.py:82} INFO - Running: ['airflow', 'tasks', 'run', 'AUTOMATISATION', 'Chargement_des_données_in_ELK', 'scheduled__2023-03-13T00:00:27+00:00', '--job-id', '221', '--raw', '--subdir', 'DAGS_FOLDER/main.py', '--cfg-path', '/tmp/tmpkt4qzhyt']
[2023-03-13T20:13:15.362+0000] {standard_task_runner.py:83} INFO - Job 221: Subtask Chargement_des_données_in_ELK
[2023-03-13T20:13:15.429+0000] {task_command.py:388} INFO - Running <TaskInstance: AUTOMATISATION.Chargement_des_données_in_ELK scheduled__2023-03-13T00:00:27+00:00 [running]> on host dev
[2023-03-13T20:13:15.495+0000] {taskinstance.py:1507} INFO - Exporting the following env vars:
AIRFLOW_CTX_DAG_OWNER=airflow
AIRFLOW_CTX_DAG_ID=AUTOMATISATION
AIRFLOW_CTX_TASK_ID=Chargement_des_données_in_ELK
AIRFLOW_CTX_EXECUTION_DATE=2023-03-13T00:00:27+00:00
AIRFLOW_CTX_TRY_NUMBER=3
AIRFLOW_CTX_DAG_RUN_ID=scheduled__2023-03-13T00:00:27+00:00
[2023-03-13T20:13:15.497+0000] {subprocess.py:63} INFO - Tmp dir root location: 
 /tmp
[2023-03-13T20:13:15.498+0000] {subprocess.py:75} INFO - Running command: ['/usr/bin/bash', '-c', 'bin/logstash -f /home/dev/etc/logstash/conf.d/data.conf']
[2023-03-13T20:13:15.505+0000] {subprocess.py:86} INFO - Output:
[2023-03-13T20:13:15.507+0000] {subprocess.py:93} INFO - /usr/bin/bash: ligne 1: bin/logstash: Aucun fichier ou dossier de ce type
[2023-03-13T20:13:15.508+0000] {subprocess.py:97} INFO - Command exited with return code 127
[2023-03-13T20:13:15.518+0000] {taskinstance.py:1768} ERROR - Task failed with exception
Traceback (most recent call last):
  File "/home/dev/airflow/airflow/lib/python3.10/site-packages/airflow/operators/bash.py", line 196, in execute
    raise AirflowException(
airflow.exceptions.AirflowException: Bash command failed. The command returned a non-zero exit code 127.
[2023-03-13T20:13:15.523+0000] {taskinstance.py:1318} INFO - Marking task as UP_FOR_RETRY. dag_id=AUTOMATISATION, task_id=Chargement_des_données_in_ELK, execution_date=20230313T000027, start_date=20230313T201315, end_date=20230313T201315
[2023-03-13T20:13:15.543+0000] {standard_task_runner.py:100} ERROR - Failed to execute job 221 for task Chargement_des_données_in_ELK (Bash command failed. The command returned a non-zero exit code 127.; 42508)
[2023-03-13T20:13:15.571+0000] {local_task_job.py:208} INFO - Task exited with return code 1
[2023-03-13T20:13:15.591+0000] {taskinstance.py:2578} INFO - 0 downstream tasks scheduled from follow-on schedule check
