[2023-03-13T19:56:48.867+0000] {taskinstance.py:1083} INFO - Dependencies all met for <TaskInstance: AUTOMATISATION.Chargement_des_données_in_ELK scheduled__2023-03-13T00:00:27+00:00 [queued]>
[2023-03-13T19:56:48.880+0000] {taskinstance.py:1083} INFO - Dependencies all met for <TaskInstance: AUTOMATISATION.Chargement_des_données_in_ELK scheduled__2023-03-13T00:00:27+00:00 [queued]>
[2023-03-13T19:56:48.880+0000] {taskinstance.py:1279} INFO - 
--------------------------------------------------------------------------------
[2023-03-13T19:56:48.880+0000] {taskinstance.py:1280} INFO - Starting attempt 4 of 4
[2023-03-13T19:56:48.880+0000] {taskinstance.py:1281} INFO - 
--------------------------------------------------------------------------------
[2023-03-13T19:56:48.903+0000] {taskinstance.py:1300} INFO - Executing <Task(BashOperator): Chargement_des_données_in_ELK> on 2023-03-13 00:00:27+00:00
[2023-03-13T19:56:48.907+0000] {standard_task_runner.py:55} INFO - Started process 39390 to run task
[2023-03-13T19:56:48.912+0000] {standard_task_runner.py:82} INFO - Running: ['airflow', 'tasks', 'run', 'AUTOMATISATION', 'Chargement_des_données_in_ELK', 'scheduled__2023-03-13T00:00:27+00:00', '--job-id', '131', '--raw', '--subdir', 'DAGS_FOLDER/main.py', '--cfg-path', '/tmp/tmpdyfyobof']
[2023-03-13T19:56:48.915+0000] {standard_task_runner.py:83} INFO - Job 131: Subtask Chargement_des_données_in_ELK
[2023-03-13T19:56:48.981+0000] {task_command.py:388} INFO - Running <TaskInstance: AUTOMATISATION.Chargement_des_données_in_ELK scheduled__2023-03-13T00:00:27+00:00 [running]> on host dev
[2023-03-13T19:56:49.047+0000] {taskinstance.py:1507} INFO - Exporting the following env vars:
AIRFLOW_CTX_DAG_OWNER=airflow
AIRFLOW_CTX_DAG_ID=AUTOMATISATION
AIRFLOW_CTX_TASK_ID=Chargement_des_données_in_ELK
AIRFLOW_CTX_EXECUTION_DATE=2023-03-13T00:00:27+00:00
AIRFLOW_CTX_TRY_NUMBER=4
AIRFLOW_CTX_DAG_RUN_ID=scheduled__2023-03-13T00:00:27+00:00
[2023-03-13T19:56:49.049+0000] {subprocess.py:63} INFO - Tmp dir root location: 
 /tmp
[2023-03-13T19:56:49.049+0000] {subprocess.py:75} INFO - Running command: ['/usr/bin/bash', '-c', 'bin/logstash --path.config /etc/logstash/conf.d/data.conf']
[2023-03-13T19:56:49.058+0000] {subprocess.py:86} INFO - Output:
[2023-03-13T19:56:49.059+0000] {subprocess.py:93} INFO - /usr/bin/bash: ligne 1: bin/logstash: Aucun fichier ou dossier de ce type
[2023-03-13T19:56:49.060+0000] {subprocess.py:97} INFO - Command exited with return code 127
[2023-03-13T19:56:49.069+0000] {taskinstance.py:1768} ERROR - Task failed with exception
Traceback (most recent call last):
  File "/home/dev/airflow/airflow/lib/python3.10/site-packages/airflow/operators/bash.py", line 196, in execute
    raise AirflowException(
airflow.exceptions.AirflowException: Bash command failed. The command returned a non-zero exit code 127.
[2023-03-13T19:56:49.075+0000] {taskinstance.py:1318} INFO - Marking task as FAILED. dag_id=AUTOMATISATION, task_id=Chargement_des_données_in_ELK, execution_date=20230313T000027, start_date=20230313T195648, end_date=20230313T195649
[2023-03-13T19:56:49.095+0000] {standard_task_runner.py:100} ERROR - Failed to execute job 131 for task Chargement_des_données_in_ELK (Bash command failed. The command returned a non-zero exit code 127.; 39390)
[2023-03-13T19:56:49.123+0000] {local_task_job.py:208} INFO - Task exited with return code 1
[2023-03-13T19:56:49.144+0000] {taskinstance.py:2578} INFO - 0 downstream tasks scheduled from follow-on schedule check
[2023-03-13T20:18:25.307+0000] {taskinstance.py:1083} INFO - Dependencies all met for <TaskInstance: AUTOMATISATION.Chargement_des_données_in_ELK scheduled__2023-03-13T00:00:27+00:00 [queued]>
[2023-03-13T20:18:25.320+0000] {taskinstance.py:1083} INFO - Dependencies all met for <TaskInstance: AUTOMATISATION.Chargement_des_données_in_ELK scheduled__2023-03-13T00:00:27+00:00 [queued]>
[2023-03-13T20:18:25.320+0000] {taskinstance.py:1279} INFO - 
--------------------------------------------------------------------------------
[2023-03-13T20:18:25.320+0000] {taskinstance.py:1280} INFO - Starting attempt 4 of 4
[2023-03-13T20:18:25.320+0000] {taskinstance.py:1281} INFO - 
--------------------------------------------------------------------------------
[2023-03-13T20:18:25.342+0000] {taskinstance.py:1300} INFO - Executing <Task(BashOperator): Chargement_des_données_in_ELK> on 2023-03-13 00:00:27+00:00
[2023-03-13T20:18:25.346+0000] {standard_task_runner.py:55} INFO - Started process 43276 to run task
[2023-03-13T20:18:25.350+0000] {standard_task_runner.py:82} INFO - Running: ['airflow', 'tasks', 'run', 'AUTOMATISATION', 'Chargement_des_données_in_ELK', 'scheduled__2023-03-13T00:00:27+00:00', '--job-id', '247', '--raw', '--subdir', 'DAGS_FOLDER/main.py', '--cfg-path', '/tmp/tmptydlqonf']
[2023-03-13T20:18:25.352+0000] {standard_task_runner.py:83} INFO - Job 247: Subtask Chargement_des_données_in_ELK
[2023-03-13T20:18:25.420+0000] {task_command.py:388} INFO - Running <TaskInstance: AUTOMATISATION.Chargement_des_données_in_ELK scheduled__2023-03-13T00:00:27+00:00 [running]> on host dev
[2023-03-13T20:18:25.486+0000] {taskinstance.py:1507} INFO - Exporting the following env vars:
AIRFLOW_CTX_DAG_OWNER=airflow
AIRFLOW_CTX_DAG_ID=AUTOMATISATION
AIRFLOW_CTX_TASK_ID=Chargement_des_données_in_ELK
AIRFLOW_CTX_EXECUTION_DATE=2023-03-13T00:00:27+00:00
AIRFLOW_CTX_TRY_NUMBER=4
AIRFLOW_CTX_DAG_RUN_ID=scheduled__2023-03-13T00:00:27+00:00
[2023-03-13T20:18:25.488+0000] {subprocess.py:63} INFO - Tmp dir root location: 
 /tmp
[2023-03-13T20:18:25.489+0000] {subprocess.py:75} INFO - Running command: ['/usr/bin/bash', '-c', 'bin/logstash -f /home/dev/etc/logstash/conf.d/data.conf']
[2023-03-13T20:18:25.498+0000] {subprocess.py:86} INFO - Output:
[2023-03-13T20:18:25.500+0000] {subprocess.py:93} INFO - /usr/bin/bash: ligne 1: bin/logstash: Aucun fichier ou dossier de ce type
[2023-03-13T20:18:25.500+0000] {subprocess.py:97} INFO - Command exited with return code 127
[2023-03-13T20:18:25.510+0000] {taskinstance.py:1768} ERROR - Task failed with exception
Traceback (most recent call last):
  File "/home/dev/airflow/airflow/lib/python3.10/site-packages/airflow/operators/bash.py", line 196, in execute
    raise AirflowException(
airflow.exceptions.AirflowException: Bash command failed. The command returned a non-zero exit code 127.
[2023-03-13T20:18:25.515+0000] {taskinstance.py:1318} INFO - Marking task as FAILED. dag_id=AUTOMATISATION, task_id=Chargement_des_données_in_ELK, execution_date=20230313T000027, start_date=20230313T201825, end_date=20230313T201825
[2023-03-13T20:18:25.535+0000] {standard_task_runner.py:100} ERROR - Failed to execute job 247 for task Chargement_des_données_in_ELK (Bash command failed. The command returned a non-zero exit code 127.; 43276)
[2023-03-13T20:18:25.561+0000] {local_task_job.py:208} INFO - Task exited with return code 1
[2023-03-13T20:18:25.582+0000] {taskinstance.py:2578} INFO - 0 downstream tasks scheduled from follow-on schedule check
