[2023-03-13T19:35:39.594+0000] {taskinstance.py:1083} INFO - Dependencies all met for <TaskInstance: AUTOMATISATION.Chargement_des_données_in_ELK scheduled__2023-03-13T00:00:15+00:00 [queued]>
[2023-03-13T19:35:39.607+0000] {taskinstance.py:1083} INFO - Dependencies all met for <TaskInstance: AUTOMATISATION.Chargement_des_données_in_ELK scheduled__2023-03-13T00:00:15+00:00 [queued]>
[2023-03-13T19:35:39.607+0000] {taskinstance.py:1279} INFO - 
--------------------------------------------------------------------------------
[2023-03-13T19:35:39.607+0000] {taskinstance.py:1280} INFO - Starting attempt 2 of 4
[2023-03-13T19:35:39.607+0000] {taskinstance.py:1281} INFO - 
--------------------------------------------------------------------------------
[2023-03-13T19:35:39.629+0000] {taskinstance.py:1300} INFO - Executing <Task(BashOperator): Chargement_des_données_in_ELK> on 2023-03-13 00:00:15+00:00
[2023-03-13T19:35:39.633+0000] {standard_task_runner.py:55} INFO - Started process 35882 to run task
[2023-03-13T19:35:39.637+0000] {standard_task_runner.py:82} INFO - Running: ['airflow', 'tasks', 'run', 'AUTOMATISATION', 'Chargement_des_données_in_ELK', 'scheduled__2023-03-13T00:00:15+00:00', '--job-id', '41', '--raw', '--subdir', 'DAGS_FOLDER/main.py', '--cfg-path', '/tmp/tmpfb2nobsp']
[2023-03-13T19:35:39.639+0000] {standard_task_runner.py:83} INFO - Job 41: Subtask Chargement_des_données_in_ELK
[2023-03-13T19:35:39.705+0000] {task_command.py:388} INFO - Running <TaskInstance: AUTOMATISATION.Chargement_des_données_in_ELK scheduled__2023-03-13T00:00:15+00:00 [running]> on host dev
[2023-03-13T19:35:39.770+0000] {taskinstance.py:1507} INFO - Exporting the following env vars:
AIRFLOW_CTX_DAG_OWNER=airflow
AIRFLOW_CTX_DAG_ID=AUTOMATISATION
AIRFLOW_CTX_TASK_ID=Chargement_des_données_in_ELK
AIRFLOW_CTX_EXECUTION_DATE=2023-03-13T00:00:15+00:00
AIRFLOW_CTX_TRY_NUMBER=2
AIRFLOW_CTX_DAG_RUN_ID=scheduled__2023-03-13T00:00:15+00:00
[2023-03-13T19:35:39.771+0000] {subprocess.py:63} INFO - Tmp dir root location: 
 /tmp
[2023-03-13T19:35:39.772+0000] {subprocess.py:75} INFO - Running command: ['/usr/bin/bash', '-c', '/usr/bin/logstash --path.config /etc/logstash/conf.d/data.conf']
[2023-03-13T19:35:39.780+0000] {subprocess.py:86} INFO - Output:
[2023-03-13T19:35:39.782+0000] {subprocess.py:93} INFO - /usr/bin/bash: ligne 1: /usr/bin/logstash: Aucun fichier ou dossier de ce type
[2023-03-13T19:35:39.782+0000] {subprocess.py:97} INFO - Command exited with return code 127
[2023-03-13T19:35:39.792+0000] {taskinstance.py:1768} ERROR - Task failed with exception
Traceback (most recent call last):
  File "/home/dev/airflow/airflow/lib/python3.10/site-packages/airflow/operators/bash.py", line 196, in execute
    raise AirflowException(
airflow.exceptions.AirflowException: Bash command failed. The command returned a non-zero exit code 127.
[2023-03-13T19:35:39.797+0000] {taskinstance.py:1318} INFO - Marking task as UP_FOR_RETRY. dag_id=AUTOMATISATION, task_id=Chargement_des_données_in_ELK, execution_date=20230313T000015, start_date=20230313T193539, end_date=20230313T193539
[2023-03-13T19:35:39.816+0000] {standard_task_runner.py:100} ERROR - Failed to execute job 41 for task Chargement_des_données_in_ELK (Bash command failed. The command returned a non-zero exit code 127.; 35882)
[2023-03-13T19:35:39.848+0000] {local_task_job.py:208} INFO - Task exited with return code 1
[2023-03-13T19:35:39.868+0000] {taskinstance.py:2578} INFO - 0 downstream tasks scheduled from follow-on schedule check
[2023-03-13T19:46:12.570+0000] {taskinstance.py:1083} INFO - Dependencies all met for <TaskInstance: AUTOMATISATION.Chargement_des_données_in_ELK scheduled__2023-03-13T00:00:15+00:00 [queued]>
[2023-03-13T19:46:12.584+0000] {taskinstance.py:1083} INFO - Dependencies all met for <TaskInstance: AUTOMATISATION.Chargement_des_données_in_ELK scheduled__2023-03-13T00:00:15+00:00 [queued]>
[2023-03-13T19:46:12.584+0000] {taskinstance.py:1279} INFO - 
--------------------------------------------------------------------------------
[2023-03-13T19:46:12.585+0000] {taskinstance.py:1280} INFO - Starting attempt 2 of 4
[2023-03-13T19:46:12.585+0000] {taskinstance.py:1281} INFO - 
--------------------------------------------------------------------------------
[2023-03-13T19:46:12.607+0000] {taskinstance.py:1300} INFO - Executing <Task(BashOperator): Chargement_des_données_in_ELK> on 2023-03-13 00:00:15+00:00
[2023-03-13T19:46:12.611+0000] {standard_task_runner.py:55} INFO - Started process 37806 to run task
[2023-03-13T19:46:12.615+0000] {standard_task_runner.py:82} INFO - Running: ['airflow', 'tasks', 'run', 'AUTOMATISATION', 'Chargement_des_données_in_ELK', 'scheduled__2023-03-13T00:00:15+00:00', '--job-id', '89', '--raw', '--subdir', 'DAGS_FOLDER/main.py', '--cfg-path', '/tmp/tmpfi9wn86o']
[2023-03-13T19:46:12.617+0000] {standard_task_runner.py:83} INFO - Job 89: Subtask Chargement_des_données_in_ELK
[2023-03-13T19:46:12.685+0000] {task_command.py:388} INFO - Running <TaskInstance: AUTOMATISATION.Chargement_des_données_in_ELK scheduled__2023-03-13T00:00:15+00:00 [running]> on host dev
[2023-03-13T19:46:12.754+0000] {taskinstance.py:1507} INFO - Exporting the following env vars:
AIRFLOW_CTX_DAG_OWNER=airflow
AIRFLOW_CTX_DAG_ID=AUTOMATISATION
AIRFLOW_CTX_TASK_ID=Chargement_des_données_in_ELK
AIRFLOW_CTX_EXECUTION_DATE=2023-03-13T00:00:15+00:00
AIRFLOW_CTX_TRY_NUMBER=2
AIRFLOW_CTX_DAG_RUN_ID=scheduled__2023-03-13T00:00:15+00:00
[2023-03-13T19:46:12.756+0000] {subprocess.py:63} INFO - Tmp dir root location: 
 /tmp
[2023-03-13T19:46:12.756+0000] {subprocess.py:75} INFO - Running command: ['/usr/bin/bash', '-c', 'bin/logstash --path.config /etc/logstash/conf.d/data.conf']
[2023-03-13T19:46:12.765+0000] {subprocess.py:86} INFO - Output:
[2023-03-13T19:46:12.767+0000] {subprocess.py:93} INFO - /usr/bin/bash: ligne 1: bin/logstash: Aucun fichier ou dossier de ce type
[2023-03-13T19:46:12.767+0000] {subprocess.py:97} INFO - Command exited with return code 127
[2023-03-13T19:46:12.778+0000] {taskinstance.py:1768} ERROR - Task failed with exception
Traceback (most recent call last):
  File "/home/dev/airflow/airflow/lib/python3.10/site-packages/airflow/operators/bash.py", line 196, in execute
    raise AirflowException(
airflow.exceptions.AirflowException: Bash command failed. The command returned a non-zero exit code 127.
[2023-03-13T19:46:12.783+0000] {taskinstance.py:1318} INFO - Marking task as UP_FOR_RETRY. dag_id=AUTOMATISATION, task_id=Chargement_des_données_in_ELK, execution_date=20230313T000015, start_date=20230313T194612, end_date=20230313T194612
[2023-03-13T19:46:12.803+0000] {standard_task_runner.py:100} ERROR - Failed to execute job 89 for task Chargement_des_données_in_ELK (Bash command failed. The command returned a non-zero exit code 127.; 37806)
[2023-03-13T19:46:12.826+0000] {local_task_job.py:208} INFO - Task exited with return code 1
[2023-03-13T19:46:12.849+0000] {taskinstance.py:2578} INFO - 0 downstream tasks scheduled from follow-on schedule check
[2023-03-13T20:07:38.785+0000] {taskinstance.py:1083} INFO - Dependencies all met for <TaskInstance: AUTOMATISATION.Chargement_des_données_in_ELK scheduled__2023-03-13T00:00:15+00:00 [queued]>
[2023-03-13T20:07:38.798+0000] {taskinstance.py:1083} INFO - Dependencies all met for <TaskInstance: AUTOMATISATION.Chargement_des_données_in_ELK scheduled__2023-03-13T00:00:15+00:00 [queued]>
[2023-03-13T20:07:38.798+0000] {taskinstance.py:1279} INFO - 
--------------------------------------------------------------------------------
[2023-03-13T20:07:38.798+0000] {taskinstance.py:1280} INFO - Starting attempt 2 of 4
[2023-03-13T20:07:38.799+0000] {taskinstance.py:1281} INFO - 
--------------------------------------------------------------------------------
[2023-03-13T20:07:38.821+0000] {taskinstance.py:1300} INFO - Executing <Task(BashOperator): Chargement_des_données_in_ELK> on 2023-03-13 00:00:15+00:00
[2023-03-13T20:07:38.825+0000] {standard_task_runner.py:55} INFO - Started process 41684 to run task
[2023-03-13T20:07:38.829+0000] {standard_task_runner.py:82} INFO - Running: ['airflow', 'tasks', 'run', 'AUTOMATISATION', 'Chargement_des_données_in_ELK', 'scheduled__2023-03-13T00:00:15+00:00', '--job-id', '201', '--raw', '--subdir', 'DAGS_FOLDER/main.py', '--cfg-path', '/tmp/tmp3v5rdljv']
[2023-03-13T20:07:38.831+0000] {standard_task_runner.py:83} INFO - Job 201: Subtask Chargement_des_données_in_ELK
[2023-03-13T20:07:38.897+0000] {task_command.py:388} INFO - Running <TaskInstance: AUTOMATISATION.Chargement_des_données_in_ELK scheduled__2023-03-13T00:00:15+00:00 [running]> on host dev
[2023-03-13T20:07:38.961+0000] {taskinstance.py:1507} INFO - Exporting the following env vars:
AIRFLOW_CTX_DAG_OWNER=airflow
AIRFLOW_CTX_DAG_ID=AUTOMATISATION
AIRFLOW_CTX_TASK_ID=Chargement_des_données_in_ELK
AIRFLOW_CTX_EXECUTION_DATE=2023-03-13T00:00:15+00:00
AIRFLOW_CTX_TRY_NUMBER=2
AIRFLOW_CTX_DAG_RUN_ID=scheduled__2023-03-13T00:00:15+00:00
[2023-03-13T20:07:38.963+0000] {subprocess.py:63} INFO - Tmp dir root location: 
 /tmp
[2023-03-13T20:07:38.964+0000] {subprocess.py:75} INFO - Running command: ['/usr/bin/bash', '-c', 'bin/logstash -f /home/dev/etc/logstash/conf.d/data.conf']
[2023-03-13T20:07:38.973+0000] {subprocess.py:86} INFO - Output:
[2023-03-13T20:07:38.974+0000] {subprocess.py:93} INFO - /usr/bin/bash: ligne 1: bin/logstash: Aucun fichier ou dossier de ce type
[2023-03-13T20:07:38.975+0000] {subprocess.py:97} INFO - Command exited with return code 127
[2023-03-13T20:07:38.986+0000] {taskinstance.py:1768} ERROR - Task failed with exception
Traceback (most recent call last):
  File "/home/dev/airflow/airflow/lib/python3.10/site-packages/airflow/operators/bash.py", line 196, in execute
    raise AirflowException(
airflow.exceptions.AirflowException: Bash command failed. The command returned a non-zero exit code 127.
[2023-03-13T20:07:38.991+0000] {taskinstance.py:1318} INFO - Marking task as UP_FOR_RETRY. dag_id=AUTOMATISATION, task_id=Chargement_des_données_in_ELK, execution_date=20230313T000015, start_date=20230313T200738, end_date=20230313T200738
[2023-03-13T20:07:39.010+0000] {standard_task_runner.py:100} ERROR - Failed to execute job 201 for task Chargement_des_données_in_ELK (Bash command failed. The command returned a non-zero exit code 127.; 41684)
[2023-03-13T20:07:39.040+0000] {local_task_job.py:208} INFO - Task exited with return code 1
[2023-03-13T20:07:39.060+0000] {taskinstance.py:2578} INFO - 0 downstream tasks scheduled from follow-on schedule check
