[2023-03-13T19:51:15.135+0000] {taskinstance.py:1083} INFO - Dependencies all met for <TaskInstance: AUTOMATISATION.Chargement_des_données_in_ELK scheduled__2023-03-13T00:00:15+00:00 [queued]>
[2023-03-13T19:51:15.146+0000] {taskinstance.py:1083} INFO - Dependencies all met for <TaskInstance: AUTOMATISATION.Chargement_des_données_in_ELK scheduled__2023-03-13T00:00:15+00:00 [queued]>
[2023-03-13T19:51:15.147+0000] {taskinstance.py:1279} INFO - 
--------------------------------------------------------------------------------
[2023-03-13T19:51:15.147+0000] {taskinstance.py:1280} INFO - Starting attempt 3 of 4
[2023-03-13T19:51:15.147+0000] {taskinstance.py:1281} INFO - 
--------------------------------------------------------------------------------
[2023-03-13T19:51:15.166+0000] {taskinstance.py:1300} INFO - Executing <Task(BashOperator): Chargement_des_données_in_ELK> on 2023-03-13 00:00:15+00:00
[2023-03-13T19:51:15.169+0000] {standard_task_runner.py:55} INFO - Started process 38559 to run task
[2023-03-13T19:51:15.173+0000] {standard_task_runner.py:82} INFO - Running: ['airflow', 'tasks', 'run', 'AUTOMATISATION', 'Chargement_des_données_in_ELK', 'scheduled__2023-03-13T00:00:15+00:00', '--job-id', '105', '--raw', '--subdir', 'DAGS_FOLDER/main.py', '--cfg-path', '/tmp/tmpifug4xbw']
[2023-03-13T19:51:15.175+0000] {standard_task_runner.py:83} INFO - Job 105: Subtask Chargement_des_données_in_ELK
[2023-03-13T19:51:15.237+0000] {task_command.py:388} INFO - Running <TaskInstance: AUTOMATISATION.Chargement_des_données_in_ELK scheduled__2023-03-13T00:00:15+00:00 [running]> on host dev
[2023-03-13T19:51:15.300+0000] {taskinstance.py:1507} INFO - Exporting the following env vars:
AIRFLOW_CTX_DAG_OWNER=airflow
AIRFLOW_CTX_DAG_ID=AUTOMATISATION
AIRFLOW_CTX_TASK_ID=Chargement_des_données_in_ELK
AIRFLOW_CTX_EXECUTION_DATE=2023-03-13T00:00:15+00:00
AIRFLOW_CTX_TRY_NUMBER=3
AIRFLOW_CTX_DAG_RUN_ID=scheduled__2023-03-13T00:00:15+00:00
[2023-03-13T19:51:15.302+0000] {subprocess.py:63} INFO - Tmp dir root location: 
 /tmp
[2023-03-13T19:51:15.303+0000] {subprocess.py:75} INFO - Running command: ['/usr/bin/bash', '-c', 'bin/logstash --path.config /etc/logstash/conf.d/data.conf']
[2023-03-13T19:51:15.311+0000] {subprocess.py:86} INFO - Output:
[2023-03-13T19:51:15.313+0000] {subprocess.py:93} INFO - /usr/bin/bash: ligne 1: bin/logstash: Aucun fichier ou dossier de ce type
[2023-03-13T19:51:15.313+0000] {subprocess.py:97} INFO - Command exited with return code 127
[2023-03-13T19:51:15.323+0000] {taskinstance.py:1768} ERROR - Task failed with exception
Traceback (most recent call last):
  File "/home/dev/airflow/airflow/lib/python3.10/site-packages/airflow/operators/bash.py", line 196, in execute
    raise AirflowException(
airflow.exceptions.AirflowException: Bash command failed. The command returned a non-zero exit code 127.
[2023-03-13T19:51:15.327+0000] {taskinstance.py:1318} INFO - Marking task as UP_FOR_RETRY. dag_id=AUTOMATISATION, task_id=Chargement_des_données_in_ELK, execution_date=20230313T000015, start_date=20230313T195115, end_date=20230313T195115
[2023-03-13T19:51:15.345+0000] {standard_task_runner.py:100} ERROR - Failed to execute job 105 for task Chargement_des_données_in_ELK (Bash command failed. The command returned a non-zero exit code 127.; 38559)
[2023-03-13T19:51:15.384+0000] {local_task_job.py:208} INFO - Task exited with return code 1
[2023-03-13T19:51:15.404+0000] {taskinstance.py:2578} INFO - 0 downstream tasks scheduled from follow-on schedule check
[2023-03-13T20:12:42.289+0000] {taskinstance.py:1083} INFO - Dependencies all met for <TaskInstance: AUTOMATISATION.Chargement_des_données_in_ELK scheduled__2023-03-13T00:00:15+00:00 [queued]>
[2023-03-13T20:12:42.303+0000] {taskinstance.py:1083} INFO - Dependencies all met for <TaskInstance: AUTOMATISATION.Chargement_des_données_in_ELK scheduled__2023-03-13T00:00:15+00:00 [queued]>
[2023-03-13T20:12:42.304+0000] {taskinstance.py:1279} INFO - 
--------------------------------------------------------------------------------
[2023-03-13T20:12:42.304+0000] {taskinstance.py:1280} INFO - Starting attempt 3 of 4
[2023-03-13T20:12:42.304+0000] {taskinstance.py:1281} INFO - 
--------------------------------------------------------------------------------
[2023-03-13T20:12:42.325+0000] {taskinstance.py:1300} INFO - Executing <Task(BashOperator): Chargement_des_données_in_ELK> on 2023-03-13 00:00:15+00:00
[2023-03-13T20:12:42.329+0000] {standard_task_runner.py:55} INFO - Started process 42442 to run task
[2023-03-13T20:12:42.333+0000] {standard_task_runner.py:82} INFO - Running: ['airflow', 'tasks', 'run', 'AUTOMATISATION', 'Chargement_des_données_in_ELK', 'scheduled__2023-03-13T00:00:15+00:00', '--job-id', '217', '--raw', '--subdir', 'DAGS_FOLDER/main.py', '--cfg-path', '/tmp/tmpsd165ams']
[2023-03-13T20:12:42.335+0000] {standard_task_runner.py:83} INFO - Job 217: Subtask Chargement_des_données_in_ELK
[2023-03-13T20:12:42.406+0000] {task_command.py:388} INFO - Running <TaskInstance: AUTOMATISATION.Chargement_des_données_in_ELK scheduled__2023-03-13T00:00:15+00:00 [running]> on host dev
[2023-03-13T20:12:42.475+0000] {taskinstance.py:1507} INFO - Exporting the following env vars:
AIRFLOW_CTX_DAG_OWNER=airflow
AIRFLOW_CTX_DAG_ID=AUTOMATISATION
AIRFLOW_CTX_TASK_ID=Chargement_des_données_in_ELK
AIRFLOW_CTX_EXECUTION_DATE=2023-03-13T00:00:15+00:00
AIRFLOW_CTX_TRY_NUMBER=3
AIRFLOW_CTX_DAG_RUN_ID=scheduled__2023-03-13T00:00:15+00:00
[2023-03-13T20:12:42.476+0000] {subprocess.py:63} INFO - Tmp dir root location: 
 /tmp
[2023-03-13T20:12:42.477+0000] {subprocess.py:75} INFO - Running command: ['/usr/bin/bash', '-c', 'bin/logstash -f /home/dev/etc/logstash/conf.d/data.conf']
[2023-03-13T20:12:42.485+0000] {subprocess.py:86} INFO - Output:
[2023-03-13T20:12:42.487+0000] {subprocess.py:93} INFO - /usr/bin/bash: ligne 1: bin/logstash: Aucun fichier ou dossier de ce type
[2023-03-13T20:12:42.487+0000] {subprocess.py:97} INFO - Command exited with return code 127
[2023-03-13T20:12:42.498+0000] {taskinstance.py:1768} ERROR - Task failed with exception
Traceback (most recent call last):
  File "/home/dev/airflow/airflow/lib/python3.10/site-packages/airflow/operators/bash.py", line 196, in execute
    raise AirflowException(
airflow.exceptions.AirflowException: Bash command failed. The command returned a non-zero exit code 127.
[2023-03-13T20:12:42.502+0000] {taskinstance.py:1318} INFO - Marking task as UP_FOR_RETRY. dag_id=AUTOMATISATION, task_id=Chargement_des_données_in_ELK, execution_date=20230313T000015, start_date=20230313T201242, end_date=20230313T201242
[2023-03-13T20:12:42.522+0000] {standard_task_runner.py:100} ERROR - Failed to execute job 217 for task Chargement_des_données_in_ELK (Bash command failed. The command returned a non-zero exit code 127.; 42442)
[2023-03-13T20:12:42.544+0000] {local_task_job.py:208} INFO - Task exited with return code 1
[2023-03-13T20:12:42.565+0000] {taskinstance.py:2578} INFO - 0 downstream tasks scheduled from follow-on schedule check
