[2023-03-13T19:56:18.634+0000] {taskinstance.py:1083} INFO - Dependencies all met for <TaskInstance: AUTOMATISATION.Chargement_des_données_in_ELK scheduled__2023-03-13T00:00:15+00:00 [queued]>
[2023-03-13T19:56:18.649+0000] {taskinstance.py:1083} INFO - Dependencies all met for <TaskInstance: AUTOMATISATION.Chargement_des_données_in_ELK scheduled__2023-03-13T00:00:15+00:00 [queued]>
[2023-03-13T19:56:18.649+0000] {taskinstance.py:1279} INFO - 
--------------------------------------------------------------------------------
[2023-03-13T19:56:18.650+0000] {taskinstance.py:1280} INFO - Starting attempt 4 of 4
[2023-03-13T19:56:18.650+0000] {taskinstance.py:1281} INFO - 
--------------------------------------------------------------------------------
[2023-03-13T19:56:18.671+0000] {taskinstance.py:1300} INFO - Executing <Task(BashOperator): Chargement_des_données_in_ELK> on 2023-03-13 00:00:15+00:00
[2023-03-13T19:56:18.675+0000] {standard_task_runner.py:55} INFO - Started process 39287 to run task
[2023-03-13T19:56:18.680+0000] {standard_task_runner.py:82} INFO - Running: ['airflow', 'tasks', 'run', 'AUTOMATISATION', 'Chargement_des_données_in_ELK', 'scheduled__2023-03-13T00:00:15+00:00', '--job-id', '125', '--raw', '--subdir', 'DAGS_FOLDER/main.py', '--cfg-path', '/tmp/tmpbau28j26']
[2023-03-13T19:56:18.682+0000] {standard_task_runner.py:83} INFO - Job 125: Subtask Chargement_des_données_in_ELK
[2023-03-13T19:56:18.748+0000] {task_command.py:388} INFO - Running <TaskInstance: AUTOMATISATION.Chargement_des_données_in_ELK scheduled__2023-03-13T00:00:15+00:00 [running]> on host dev
[2023-03-13T19:56:18.816+0000] {taskinstance.py:1507} INFO - Exporting the following env vars:
AIRFLOW_CTX_DAG_OWNER=airflow
AIRFLOW_CTX_DAG_ID=AUTOMATISATION
AIRFLOW_CTX_TASK_ID=Chargement_des_données_in_ELK
AIRFLOW_CTX_EXECUTION_DATE=2023-03-13T00:00:15+00:00
AIRFLOW_CTX_TRY_NUMBER=4
AIRFLOW_CTX_DAG_RUN_ID=scheduled__2023-03-13T00:00:15+00:00
[2023-03-13T19:56:18.818+0000] {subprocess.py:63} INFO - Tmp dir root location: 
 /tmp
[2023-03-13T19:56:18.819+0000] {subprocess.py:75} INFO - Running command: ['/usr/bin/bash', '-c', 'bin/logstash --path.config /etc/logstash/conf.d/data.conf']
[2023-03-13T19:56:18.828+0000] {subprocess.py:86} INFO - Output:
[2023-03-13T19:56:18.829+0000] {subprocess.py:93} INFO - /usr/bin/bash: ligne 1: bin/logstash: Aucun fichier ou dossier de ce type
[2023-03-13T19:56:18.830+0000] {subprocess.py:97} INFO - Command exited with return code 127
[2023-03-13T19:56:18.840+0000] {taskinstance.py:1768} ERROR - Task failed with exception
Traceback (most recent call last):
  File "/home/dev/airflow/airflow/lib/python3.10/site-packages/airflow/operators/bash.py", line 196, in execute
    raise AirflowException(
airflow.exceptions.AirflowException: Bash command failed. The command returned a non-zero exit code 127.
[2023-03-13T19:56:18.846+0000] {taskinstance.py:1318} INFO - Marking task as FAILED. dag_id=AUTOMATISATION, task_id=Chargement_des_données_in_ELK, execution_date=20230313T000015, start_date=20230313T195618, end_date=20230313T195618
[2023-03-13T19:56:18.866+0000] {standard_task_runner.py:100} ERROR - Failed to execute job 125 for task Chargement_des_données_in_ELK (Bash command failed. The command returned a non-zero exit code 127.; 39287)
[2023-03-13T19:56:18.891+0000] {local_task_job.py:208} INFO - Task exited with return code 1
[2023-03-13T19:56:18.911+0000] {taskinstance.py:2578} INFO - 0 downstream tasks scheduled from follow-on schedule check
[2023-03-13T20:17:50.211+0000] {taskinstance.py:1083} INFO - Dependencies all met for <TaskInstance: AUTOMATISATION.Chargement_des_données_in_ELK scheduled__2023-03-13T00:00:15+00:00 [queued]>
[2023-03-13T20:17:50.226+0000] {taskinstance.py:1083} INFO - Dependencies all met for <TaskInstance: AUTOMATISATION.Chargement_des_données_in_ELK scheduled__2023-03-13T00:00:15+00:00 [queued]>
[2023-03-13T20:17:50.226+0000] {taskinstance.py:1279} INFO - 
--------------------------------------------------------------------------------
[2023-03-13T20:17:50.227+0000] {taskinstance.py:1280} INFO - Starting attempt 4 of 4
[2023-03-13T20:17:50.227+0000] {taskinstance.py:1281} INFO - 
--------------------------------------------------------------------------------
[2023-03-13T20:17:50.250+0000] {taskinstance.py:1300} INFO - Executing <Task(BashOperator): Chargement_des_données_in_ELK> on 2023-03-13 00:00:15+00:00
[2023-03-13T20:17:50.254+0000] {standard_task_runner.py:55} INFO - Started process 43155 to run task
[2023-03-13T20:17:50.258+0000] {standard_task_runner.py:82} INFO - Running: ['airflow', 'tasks', 'run', 'AUTOMATISATION', 'Chargement_des_données_in_ELK', 'scheduled__2023-03-13T00:00:15+00:00', '--job-id', '238', '--raw', '--subdir', 'DAGS_FOLDER/main.py', '--cfg-path', '/tmp/tmpnmcxjdvy']
[2023-03-13T20:17:50.260+0000] {standard_task_runner.py:83} INFO - Job 238: Subtask Chargement_des_données_in_ELK
[2023-03-13T20:17:50.327+0000] {task_command.py:388} INFO - Running <TaskInstance: AUTOMATISATION.Chargement_des_données_in_ELK scheduled__2023-03-13T00:00:15+00:00 [running]> on host dev
[2023-03-13T20:17:50.392+0000] {taskinstance.py:1507} INFO - Exporting the following env vars:
AIRFLOW_CTX_DAG_OWNER=airflow
AIRFLOW_CTX_DAG_ID=AUTOMATISATION
AIRFLOW_CTX_TASK_ID=Chargement_des_données_in_ELK
AIRFLOW_CTX_EXECUTION_DATE=2023-03-13T00:00:15+00:00
AIRFLOW_CTX_TRY_NUMBER=4
AIRFLOW_CTX_DAG_RUN_ID=scheduled__2023-03-13T00:00:15+00:00
[2023-03-13T20:17:50.394+0000] {subprocess.py:63} INFO - Tmp dir root location: 
 /tmp
[2023-03-13T20:17:50.395+0000] {subprocess.py:75} INFO - Running command: ['/usr/bin/bash', '-c', 'bin/logstash -f /home/dev/etc/logstash/conf.d/data.conf']
[2023-03-13T20:17:50.403+0000] {subprocess.py:86} INFO - Output:
[2023-03-13T20:17:50.405+0000] {subprocess.py:93} INFO - /usr/bin/bash: ligne 1: bin/logstash: Aucun fichier ou dossier de ce type
[2023-03-13T20:17:50.405+0000] {subprocess.py:97} INFO - Command exited with return code 127
[2023-03-13T20:17:50.415+0000] {taskinstance.py:1768} ERROR - Task failed with exception
Traceback (most recent call last):
  File "/home/dev/airflow/airflow/lib/python3.10/site-packages/airflow/operators/bash.py", line 196, in execute
    raise AirflowException(
airflow.exceptions.AirflowException: Bash command failed. The command returned a non-zero exit code 127.
[2023-03-13T20:17:50.420+0000] {taskinstance.py:1318} INFO - Marking task as FAILED. dag_id=AUTOMATISATION, task_id=Chargement_des_données_in_ELK, execution_date=20230313T000015, start_date=20230313T201750, end_date=20230313T201750
[2023-03-13T20:17:50.438+0000] {standard_task_runner.py:100} ERROR - Failed to execute job 238 for task Chargement_des_données_in_ELK (Bash command failed. The command returned a non-zero exit code 127.; 43155)
[2023-03-13T20:17:50.469+0000] {local_task_job.py:208} INFO - Task exited with return code 1
[2023-03-13T20:17:50.490+0000] {taskinstance.py:2578} INFO - 0 downstream tasks scheduled from follow-on schedule check
