[2023-03-13T19:57:16.151+0000] {taskinstance.py:1083} INFO - Dependencies all met for <TaskInstance: AUTOMATISATION.Chargement_des_données_in_ELK scheduled__2023-03-13T00:00:36+00:00 [queued]>
[2023-03-13T19:57:16.164+0000] {taskinstance.py:1083} INFO - Dependencies all met for <TaskInstance: AUTOMATISATION.Chargement_des_données_in_ELK scheduled__2023-03-13T00:00:36+00:00 [queued]>
[2023-03-13T19:57:16.165+0000] {taskinstance.py:1279} INFO - 
--------------------------------------------------------------------------------
[2023-03-13T19:57:16.165+0000] {taskinstance.py:1280} INFO - Starting attempt 4 of 4
[2023-03-13T19:57:16.165+0000] {taskinstance.py:1281} INFO - 
--------------------------------------------------------------------------------
[2023-03-13T19:57:16.188+0000] {taskinstance.py:1300} INFO - Executing <Task(BashOperator): Chargement_des_données_in_ELK> on 2023-03-13 00:00:36+00:00
[2023-03-13T19:57:16.192+0000] {standard_task_runner.py:55} INFO - Started process 39492 to run task
[2023-03-13T19:57:16.197+0000] {standard_task_runner.py:82} INFO - Running: ['airflow', 'tasks', 'run', 'AUTOMATISATION', 'Chargement_des_données_in_ELK', 'scheduled__2023-03-13T00:00:36+00:00', '--job-id', '137', '--raw', '--subdir', 'DAGS_FOLDER/main.py', '--cfg-path', '/tmp/tmpt6ve9thw']
[2023-03-13T19:57:16.199+0000] {standard_task_runner.py:83} INFO - Job 137: Subtask Chargement_des_données_in_ELK
[2023-03-13T19:57:16.267+0000] {task_command.py:388} INFO - Running <TaskInstance: AUTOMATISATION.Chargement_des_données_in_ELK scheduled__2023-03-13T00:00:36+00:00 [running]> on host dev
[2023-03-13T19:57:16.331+0000] {taskinstance.py:1507} INFO - Exporting the following env vars:
AIRFLOW_CTX_DAG_OWNER=airflow
AIRFLOW_CTX_DAG_ID=AUTOMATISATION
AIRFLOW_CTX_TASK_ID=Chargement_des_données_in_ELK
AIRFLOW_CTX_EXECUTION_DATE=2023-03-13T00:00:36+00:00
AIRFLOW_CTX_TRY_NUMBER=4
AIRFLOW_CTX_DAG_RUN_ID=scheduled__2023-03-13T00:00:36+00:00
[2023-03-13T19:57:16.333+0000] {subprocess.py:63} INFO - Tmp dir root location: 
 /tmp
[2023-03-13T19:57:16.334+0000] {subprocess.py:75} INFO - Running command: ['/usr/bin/bash', '-c', 'bin/logstash --path.config /etc/logstash/conf.d/data.conf']
[2023-03-13T19:57:16.342+0000] {subprocess.py:86} INFO - Output:
[2023-03-13T19:57:16.344+0000] {subprocess.py:93} INFO - /usr/bin/bash: ligne 1: bin/logstash: Aucun fichier ou dossier de ce type
[2023-03-13T19:57:16.344+0000] {subprocess.py:97} INFO - Command exited with return code 127
[2023-03-13T19:57:16.355+0000] {taskinstance.py:1768} ERROR - Task failed with exception
Traceback (most recent call last):
  File "/home/dev/airflow/airflow/lib/python3.10/site-packages/airflow/operators/bash.py", line 196, in execute
    raise AirflowException(
airflow.exceptions.AirflowException: Bash command failed. The command returned a non-zero exit code 127.
[2023-03-13T19:57:16.361+0000] {taskinstance.py:1318} INFO - Marking task as FAILED. dag_id=AUTOMATISATION, task_id=Chargement_des_données_in_ELK, execution_date=20230313T000036, start_date=20230313T195716, end_date=20230313T195716
[2023-03-13T19:57:16.383+0000] {standard_task_runner.py:100} ERROR - Failed to execute job 137 for task Chargement_des_données_in_ELK (Bash command failed. The command returned a non-zero exit code 127.; 39492)
[2023-03-13T19:57:16.408+0000] {local_task_job.py:208} INFO - Task exited with return code 1
[2023-03-13T19:57:16.428+0000] {taskinstance.py:2578} INFO - 0 downstream tasks scheduled from follow-on schedule check
[2023-03-13T20:18:46.437+0000] {taskinstance.py:1083} INFO - Dependencies all met for <TaskInstance: AUTOMATISATION.Chargement_des_données_in_ELK scheduled__2023-03-13T00:00:36+00:00 [queued]>
[2023-03-13T20:18:46.449+0000] {taskinstance.py:1083} INFO - Dependencies all met for <TaskInstance: AUTOMATISATION.Chargement_des_données_in_ELK scheduled__2023-03-13T00:00:36+00:00 [queued]>
[2023-03-13T20:18:46.449+0000] {taskinstance.py:1279} INFO - 
--------------------------------------------------------------------------------
[2023-03-13T20:18:46.449+0000] {taskinstance.py:1280} INFO - Starting attempt 4 of 4
[2023-03-13T20:18:46.450+0000] {taskinstance.py:1281} INFO - 
--------------------------------------------------------------------------------
[2023-03-13T20:18:46.471+0000] {taskinstance.py:1300} INFO - Executing <Task(BashOperator): Chargement_des_données_in_ELK> on 2023-03-13 00:00:36+00:00
[2023-03-13T20:18:46.474+0000] {standard_task_runner.py:55} INFO - Started process 43364 to run task
[2023-03-13T20:18:46.478+0000] {standard_task_runner.py:82} INFO - Running: ['airflow', 'tasks', 'run', 'AUTOMATISATION', 'Chargement_des_données_in_ELK', 'scheduled__2023-03-13T00:00:36+00:00', '--job-id', '253', '--raw', '--subdir', 'DAGS_FOLDER/main.py', '--cfg-path', '/tmp/tmpcij3mh82']
[2023-03-13T20:18:46.480+0000] {standard_task_runner.py:83} INFO - Job 253: Subtask Chargement_des_données_in_ELK
[2023-03-13T20:18:46.549+0000] {task_command.py:388} INFO - Running <TaskInstance: AUTOMATISATION.Chargement_des_données_in_ELK scheduled__2023-03-13T00:00:36+00:00 [running]> on host dev
[2023-03-13T20:18:46.615+0000] {taskinstance.py:1507} INFO - Exporting the following env vars:
AIRFLOW_CTX_DAG_OWNER=airflow
AIRFLOW_CTX_DAG_ID=AUTOMATISATION
AIRFLOW_CTX_TASK_ID=Chargement_des_données_in_ELK
AIRFLOW_CTX_EXECUTION_DATE=2023-03-13T00:00:36+00:00
AIRFLOW_CTX_TRY_NUMBER=4
AIRFLOW_CTX_DAG_RUN_ID=scheduled__2023-03-13T00:00:36+00:00
[2023-03-13T20:18:46.617+0000] {subprocess.py:63} INFO - Tmp dir root location: 
 /tmp
[2023-03-13T20:18:46.618+0000] {subprocess.py:75} INFO - Running command: ['/usr/bin/bash', '-c', 'bin/logstash -f /home/dev/etc/logstash/conf.d/data.conf']
[2023-03-13T20:18:46.626+0000] {subprocess.py:86} INFO - Output:
[2023-03-13T20:18:46.628+0000] {subprocess.py:93} INFO - /usr/bin/bash: ligne 1: bin/logstash: Aucun fichier ou dossier de ce type
[2023-03-13T20:18:46.628+0000] {subprocess.py:97} INFO - Command exited with return code 127
[2023-03-13T20:18:46.639+0000] {taskinstance.py:1768} ERROR - Task failed with exception
Traceback (most recent call last):
  File "/home/dev/airflow/airflow/lib/python3.10/site-packages/airflow/operators/bash.py", line 196, in execute
    raise AirflowException(
airflow.exceptions.AirflowException: Bash command failed. The command returned a non-zero exit code 127.
[2023-03-13T20:18:46.643+0000] {taskinstance.py:1318} INFO - Marking task as FAILED. dag_id=AUTOMATISATION, task_id=Chargement_des_données_in_ELK, execution_date=20230313T000036, start_date=20230313T201846, end_date=20230313T201846
[2023-03-13T20:18:46.663+0000] {standard_task_runner.py:100} ERROR - Failed to execute job 253 for task Chargement_des_données_in_ELK (Bash command failed. The command returned a non-zero exit code 127.; 43364)
[2023-03-13T20:18:46.689+0000] {local_task_job.py:208} INFO - Task exited with return code 1
[2023-03-13T20:18:46.709+0000] {taskinstance.py:2578} INFO - 0 downstream tasks scheduled from follow-on schedule check
