[2023-03-13T19:50:52.236+0000] {taskinstance.py:1083} INFO - Dependencies all met for <TaskInstance: AUTOMATISATION.Chargement_des_données_in_ELK scheduled__2023-03-13T00:00:06+00:00 [queued]>
[2023-03-13T19:50:52.247+0000] {taskinstance.py:1083} INFO - Dependencies all met for <TaskInstance: AUTOMATISATION.Chargement_des_données_in_ELK scheduled__2023-03-13T00:00:06+00:00 [queued]>
[2023-03-13T19:50:52.248+0000] {taskinstance.py:1279} INFO - 
--------------------------------------------------------------------------------
[2023-03-13T19:50:52.248+0000] {taskinstance.py:1280} INFO - Starting attempt 3 of 4
[2023-03-13T19:50:52.248+0000] {taskinstance.py:1281} INFO - 
--------------------------------------------------------------------------------
[2023-03-13T19:50:52.268+0000] {taskinstance.py:1300} INFO - Executing <Task(BashOperator): Chargement_des_données_in_ELK> on 2023-03-13 00:00:06+00:00
[2023-03-13T19:50:52.271+0000] {standard_task_runner.py:55} INFO - Started process 38494 to run task
[2023-03-13T19:50:52.275+0000] {standard_task_runner.py:82} INFO - Running: ['airflow', 'tasks', 'run', 'AUTOMATISATION', 'Chargement_des_données_in_ELK', 'scheduled__2023-03-13T00:00:06+00:00', '--job-id', '102', '--raw', '--subdir', 'DAGS_FOLDER/main.py', '--cfg-path', '/tmp/tmp7f73j2ij']
[2023-03-13T19:50:52.277+0000] {standard_task_runner.py:83} INFO - Job 102: Subtask Chargement_des_données_in_ELK
[2023-03-13T19:50:52.365+0000] {task_command.py:388} INFO - Running <TaskInstance: AUTOMATISATION.Chargement_des_données_in_ELK scheduled__2023-03-13T00:00:06+00:00 [running]> on host dev
[2023-03-13T19:50:52.424+0000] {taskinstance.py:1507} INFO - Exporting the following env vars:
AIRFLOW_CTX_DAG_OWNER=airflow
AIRFLOW_CTX_DAG_ID=AUTOMATISATION
AIRFLOW_CTX_TASK_ID=Chargement_des_données_in_ELK
AIRFLOW_CTX_EXECUTION_DATE=2023-03-13T00:00:06+00:00
AIRFLOW_CTX_TRY_NUMBER=3
AIRFLOW_CTX_DAG_RUN_ID=scheduled__2023-03-13T00:00:06+00:00
[2023-03-13T19:50:52.426+0000] {subprocess.py:63} INFO - Tmp dir root location: 
 /tmp
[2023-03-13T19:50:52.426+0000] {subprocess.py:75} INFO - Running command: ['/usr/bin/bash', '-c', 'bin/logstash --path.config /etc/logstash/conf.d/data.conf']
[2023-03-13T19:50:52.433+0000] {subprocess.py:86} INFO - Output:
[2023-03-13T19:50:52.435+0000] {subprocess.py:93} INFO - /usr/bin/bash: ligne 1: bin/logstash: Aucun fichier ou dossier de ce type
[2023-03-13T19:50:52.435+0000] {subprocess.py:97} INFO - Command exited with return code 127
[2023-03-13T19:50:52.445+0000] {taskinstance.py:1768} ERROR - Task failed with exception
Traceback (most recent call last):
  File "/home/dev/airflow/airflow/lib/python3.10/site-packages/airflow/operators/bash.py", line 196, in execute
    raise AirflowException(
airflow.exceptions.AirflowException: Bash command failed. The command returned a non-zero exit code 127.
[2023-03-13T19:50:52.450+0000] {taskinstance.py:1318} INFO - Marking task as UP_FOR_RETRY. dag_id=AUTOMATISATION, task_id=Chargement_des_données_in_ELK, execution_date=20230313T000006, start_date=20230313T195052, end_date=20230313T195052
[2023-03-13T19:50:52.467+0000] {standard_task_runner.py:100} ERROR - Failed to execute job 102 for task Chargement_des_données_in_ELK (Bash command failed. The command returned a non-zero exit code 127.; 38494)
[2023-03-13T19:50:52.486+0000] {local_task_job.py:208} INFO - Task exited with return code 1
[2023-03-13T19:50:52.509+0000] {taskinstance.py:2578} INFO - 0 downstream tasks scheduled from follow-on schedule check
[2023-03-13T20:12:19.227+0000] {taskinstance.py:1083} INFO - Dependencies all met for <TaskInstance: AUTOMATISATION.Chargement_des_données_in_ELK scheduled__2023-03-13T00:00:06+00:00 [queued]>
[2023-03-13T20:12:19.241+0000] {taskinstance.py:1083} INFO - Dependencies all met for <TaskInstance: AUTOMATISATION.Chargement_des_données_in_ELK scheduled__2023-03-13T00:00:06+00:00 [queued]>
[2023-03-13T20:12:19.241+0000] {taskinstance.py:1279} INFO - 
--------------------------------------------------------------------------------
[2023-03-13T20:12:19.241+0000] {taskinstance.py:1280} INFO - Starting attempt 3 of 4
[2023-03-13T20:12:19.241+0000] {taskinstance.py:1281} INFO - 
--------------------------------------------------------------------------------
[2023-03-13T20:12:19.265+0000] {taskinstance.py:1300} INFO - Executing <Task(BashOperator): Chargement_des_données_in_ELK> on 2023-03-13 00:00:06+00:00
[2023-03-13T20:12:19.268+0000] {standard_task_runner.py:55} INFO - Started process 42372 to run task
[2023-03-13T20:12:19.272+0000] {standard_task_runner.py:82} INFO - Running: ['airflow', 'tasks', 'run', 'AUTOMATISATION', 'Chargement_des_données_in_ELK', 'scheduled__2023-03-13T00:00:06+00:00', '--job-id', '214', '--raw', '--subdir', 'DAGS_FOLDER/main.py', '--cfg-path', '/tmp/tmp56drhj2n']
[2023-03-13T20:12:19.274+0000] {standard_task_runner.py:83} INFO - Job 214: Subtask Chargement_des_données_in_ELK
[2023-03-13T20:12:19.343+0000] {task_command.py:388} INFO - Running <TaskInstance: AUTOMATISATION.Chargement_des_données_in_ELK scheduled__2023-03-13T00:00:06+00:00 [running]> on host dev
[2023-03-13T20:12:19.412+0000] {taskinstance.py:1507} INFO - Exporting the following env vars:
AIRFLOW_CTX_DAG_OWNER=airflow
AIRFLOW_CTX_DAG_ID=AUTOMATISATION
AIRFLOW_CTX_TASK_ID=Chargement_des_données_in_ELK
AIRFLOW_CTX_EXECUTION_DATE=2023-03-13T00:00:06+00:00
AIRFLOW_CTX_TRY_NUMBER=3
AIRFLOW_CTX_DAG_RUN_ID=scheduled__2023-03-13T00:00:06+00:00
[2023-03-13T20:12:19.414+0000] {subprocess.py:63} INFO - Tmp dir root location: 
 /tmp
[2023-03-13T20:12:19.415+0000] {subprocess.py:75} INFO - Running command: ['/usr/bin/bash', '-c', 'bin/logstash -f /home/dev/etc/logstash/conf.d/data.conf']
[2023-03-13T20:12:19.424+0000] {subprocess.py:86} INFO - Output:
[2023-03-13T20:12:19.426+0000] {subprocess.py:93} INFO - /usr/bin/bash: ligne 1: bin/logstash: Aucun fichier ou dossier de ce type
[2023-03-13T20:12:19.426+0000] {subprocess.py:97} INFO - Command exited with return code 127
[2023-03-13T20:12:19.437+0000] {taskinstance.py:1768} ERROR - Task failed with exception
Traceback (most recent call last):
  File "/home/dev/airflow/airflow/lib/python3.10/site-packages/airflow/operators/bash.py", line 196, in execute
    raise AirflowException(
airflow.exceptions.AirflowException: Bash command failed. The command returned a non-zero exit code 127.
[2023-03-13T20:12:19.441+0000] {taskinstance.py:1318} INFO - Marking task as UP_FOR_RETRY. dag_id=AUTOMATISATION, task_id=Chargement_des_données_in_ELK, execution_date=20230313T000006, start_date=20230313T201219, end_date=20230313T201219
[2023-03-13T20:12:19.460+0000] {standard_task_runner.py:100} ERROR - Failed to execute job 214 for task Chargement_des_données_in_ELK (Bash command failed. The command returned a non-zero exit code 127.; 42372)
[2023-03-13T20:12:19.483+0000] {local_task_job.py:208} INFO - Task exited with return code 1
[2023-03-13T20:12:19.503+0000] {taskinstance.py:2578} INFO - 0 downstream tasks scheduled from follow-on schedule check
