[2023-03-13T19:55:57.388+0000] {taskinstance.py:1083} INFO - Dependencies all met for <TaskInstance: AUTOMATISATION.Chargement_des_données_in_ELK scheduled__2023-03-13T00:00:06+00:00 [queued]>
[2023-03-13T19:55:57.401+0000] {taskinstance.py:1083} INFO - Dependencies all met for <TaskInstance: AUTOMATISATION.Chargement_des_données_in_ELK scheduled__2023-03-13T00:00:06+00:00 [queued]>
[2023-03-13T19:55:57.401+0000] {taskinstance.py:1279} INFO - 
--------------------------------------------------------------------------------
[2023-03-13T19:55:57.401+0000] {taskinstance.py:1280} INFO - Starting attempt 4 of 4
[2023-03-13T19:55:57.401+0000] {taskinstance.py:1281} INFO - 
--------------------------------------------------------------------------------
[2023-03-13T19:55:57.426+0000] {taskinstance.py:1300} INFO - Executing <Task(BashOperator): Chargement_des_données_in_ELK> on 2023-03-13 00:00:06+00:00
[2023-03-13T19:55:57.429+0000] {standard_task_runner.py:55} INFO - Started process 39201 to run task
[2023-03-13T19:55:57.434+0000] {standard_task_runner.py:82} INFO - Running: ['airflow', 'tasks', 'run', 'AUTOMATISATION', 'Chargement_des_données_in_ELK', 'scheduled__2023-03-13T00:00:06+00:00', '--job-id', '119', '--raw', '--subdir', 'DAGS_FOLDER/main.py', '--cfg-path', '/tmp/tmpuszlx7go']
[2023-03-13T19:55:57.436+0000] {standard_task_runner.py:83} INFO - Job 119: Subtask Chargement_des_données_in_ELK
[2023-03-13T19:55:57.505+0000] {task_command.py:388} INFO - Running <TaskInstance: AUTOMATISATION.Chargement_des_données_in_ELK scheduled__2023-03-13T00:00:06+00:00 [running]> on host dev
[2023-03-13T19:55:57.569+0000] {taskinstance.py:1507} INFO - Exporting the following env vars:
AIRFLOW_CTX_DAG_OWNER=airflow
AIRFLOW_CTX_DAG_ID=AUTOMATISATION
AIRFLOW_CTX_TASK_ID=Chargement_des_données_in_ELK
AIRFLOW_CTX_EXECUTION_DATE=2023-03-13T00:00:06+00:00
AIRFLOW_CTX_TRY_NUMBER=4
AIRFLOW_CTX_DAG_RUN_ID=scheduled__2023-03-13T00:00:06+00:00
[2023-03-13T19:55:57.571+0000] {subprocess.py:63} INFO - Tmp dir root location: 
 /tmp
[2023-03-13T19:55:57.572+0000] {subprocess.py:75} INFO - Running command: ['/usr/bin/bash', '-c', 'bin/logstash --path.config /etc/logstash/conf.d/data.conf']
[2023-03-13T19:55:57.581+0000] {subprocess.py:86} INFO - Output:
[2023-03-13T19:55:57.582+0000] {subprocess.py:93} INFO - /usr/bin/bash: ligne 1: bin/logstash: Aucun fichier ou dossier de ce type
[2023-03-13T19:55:57.583+0000] {subprocess.py:97} INFO - Command exited with return code 127
[2023-03-13T19:55:57.592+0000] {taskinstance.py:1768} ERROR - Task failed with exception
Traceback (most recent call last):
  File "/home/dev/airflow/airflow/lib/python3.10/site-packages/airflow/operators/bash.py", line 196, in execute
    raise AirflowException(
airflow.exceptions.AirflowException: Bash command failed. The command returned a non-zero exit code 127.
[2023-03-13T19:55:57.597+0000] {taskinstance.py:1318} INFO - Marking task as FAILED. dag_id=AUTOMATISATION, task_id=Chargement_des_données_in_ELK, execution_date=20230313T000006, start_date=20230313T195557, end_date=20230313T195557
[2023-03-13T19:55:57.615+0000] {standard_task_runner.py:100} ERROR - Failed to execute job 119 for task Chargement_des_données_in_ELK (Bash command failed. The command returned a non-zero exit code 127.; 39201)
[2023-03-13T19:55:57.645+0000] {local_task_job.py:208} INFO - Task exited with return code 1
[2023-03-13T19:55:57.668+0000] {taskinstance.py:2578} INFO - 0 downstream tasks scheduled from follow-on schedule check
[2023-03-13T20:17:27.586+0000] {taskinstance.py:1083} INFO - Dependencies all met for <TaskInstance: AUTOMATISATION.Chargement_des_données_in_ELK scheduled__2023-03-13T00:00:06+00:00 [queued]>
[2023-03-13T20:17:27.607+0000] {taskinstance.py:1083} INFO - Dependencies all met for <TaskInstance: AUTOMATISATION.Chargement_des_données_in_ELK scheduled__2023-03-13T00:00:06+00:00 [queued]>
[2023-03-13T20:17:27.608+0000] {taskinstance.py:1279} INFO - 
--------------------------------------------------------------------------------
[2023-03-13T20:17:27.608+0000] {taskinstance.py:1280} INFO - Starting attempt 4 of 4
[2023-03-13T20:17:27.608+0000] {taskinstance.py:1281} INFO - 
--------------------------------------------------------------------------------
[2023-03-13T20:17:28.240+0000] {taskinstance.py:1300} INFO - Executing <Task(BashOperator): Chargement_des_données_in_ELK> on 2023-03-13 00:00:06+00:00
[2023-03-13T20:17:28.243+0000] {standard_task_runner.py:55} INFO - Started process 43067 to run task
[2023-03-13T20:17:28.247+0000] {standard_task_runner.py:82} INFO - Running: ['airflow', 'tasks', 'run', 'AUTOMATISATION', 'Chargement_des_données_in_ELK', 'scheduled__2023-03-13T00:00:06+00:00', '--job-id', '232', '--raw', '--subdir', 'DAGS_FOLDER/main.py', '--cfg-path', '/tmp/tmp8nbbbgk5']
[2023-03-13T20:17:28.249+0000] {standard_task_runner.py:83} INFO - Job 232: Subtask Chargement_des_données_in_ELK
[2023-03-13T20:17:28.435+0000] {task_command.py:388} INFO - Running <TaskInstance: AUTOMATISATION.Chargement_des_données_in_ELK scheduled__2023-03-13T00:00:06+00:00 [running]> on host dev
[2023-03-13T20:17:28.833+0000] {taskinstance.py:1507} INFO - Exporting the following env vars:
AIRFLOW_CTX_DAG_OWNER=airflow
AIRFLOW_CTX_DAG_ID=AUTOMATISATION
AIRFLOW_CTX_TASK_ID=Chargement_des_données_in_ELK
AIRFLOW_CTX_EXECUTION_DATE=2023-03-13T00:00:06+00:00
AIRFLOW_CTX_TRY_NUMBER=4
AIRFLOW_CTX_DAG_RUN_ID=scheduled__2023-03-13T00:00:06+00:00
[2023-03-13T20:17:28.835+0000] {subprocess.py:63} INFO - Tmp dir root location: 
 /tmp
[2023-03-13T20:17:28.836+0000] {subprocess.py:75} INFO - Running command: ['/usr/bin/bash', '-c', 'bin/logstash -f /home/dev/etc/logstash/conf.d/data.conf']
[2023-03-13T20:17:28.844+0000] {subprocess.py:86} INFO - Output:
[2023-03-13T20:17:28.846+0000] {subprocess.py:93} INFO - /usr/bin/bash: ligne 1: bin/logstash: Aucun fichier ou dossier de ce type
[2023-03-13T20:17:28.846+0000] {subprocess.py:97} INFO - Command exited with return code 127
[2023-03-13T20:17:28.856+0000] {taskinstance.py:1768} ERROR - Task failed with exception
Traceback (most recent call last):
  File "/home/dev/airflow/airflow/lib/python3.10/site-packages/airflow/operators/bash.py", line 196, in execute
    raise AirflowException(
airflow.exceptions.AirflowException: Bash command failed. The command returned a non-zero exit code 127.
[2023-03-13T20:17:28.860+0000] {taskinstance.py:1318} INFO - Marking task as FAILED. dag_id=AUTOMATISATION, task_id=Chargement_des_données_in_ELK, execution_date=20230313T000006, start_date=20230313T201727, end_date=20230313T201728
[2023-03-13T20:17:29.091+0000] {standard_task_runner.py:100} ERROR - Failed to execute job 232 for task Chargement_des_données_in_ELK (Bash command failed. The command returned a non-zero exit code 127.; 43067)
[2023-03-13T20:17:29.100+0000] {local_task_job.py:208} INFO - Task exited with return code 1
[2023-03-13T20:17:29.120+0000] {taskinstance.py:2578} INFO - 0 downstream tasks scheduled from follow-on schedule check
