[2023-03-13T19:36:25.676+0000] {taskinstance.py:1083} INFO - Dependencies all met for <TaskInstance: AUTOMATISATION.Chargement_des_données_in_ELK scheduled__2023-03-13T00:00:33+00:00 [queued]>
[2023-03-13T19:36:25.689+0000] {taskinstance.py:1083} INFO - Dependencies all met for <TaskInstance: AUTOMATISATION.Chargement_des_données_in_ELK scheduled__2023-03-13T00:00:33+00:00 [queued]>
[2023-03-13T19:36:25.690+0000] {taskinstance.py:1279} INFO - 
--------------------------------------------------------------------------------
[2023-03-13T19:36:25.690+0000] {taskinstance.py:1280} INFO - Starting attempt 2 of 4
[2023-03-13T19:36:25.690+0000] {taskinstance.py:1281} INFO - 
--------------------------------------------------------------------------------
[2023-03-13T19:36:25.714+0000] {taskinstance.py:1300} INFO - Executing <Task(BashOperator): Chargement_des_données_in_ELK> on 2023-03-13 00:00:33+00:00
[2023-03-13T19:36:25.717+0000] {standard_task_runner.py:55} INFO - Started process 36020 to run task
[2023-03-13T19:36:25.721+0000] {standard_task_runner.py:82} INFO - Running: ['airflow', 'tasks', 'run', 'AUTOMATISATION', 'Chargement_des_données_in_ELK', 'scheduled__2023-03-13T00:00:33+00:00', '--job-id', '47', '--raw', '--subdir', 'DAGS_FOLDER/main.py', '--cfg-path', '/tmp/tmpq6bq9sf7']
[2023-03-13T19:36:25.723+0000] {standard_task_runner.py:83} INFO - Job 47: Subtask Chargement_des_données_in_ELK
[2023-03-13T19:36:25.788+0000] {task_command.py:388} INFO - Running <TaskInstance: AUTOMATISATION.Chargement_des_données_in_ELK scheduled__2023-03-13T00:00:33+00:00 [running]> on host dev
[2023-03-13T19:36:25.854+0000] {taskinstance.py:1507} INFO - Exporting the following env vars:
AIRFLOW_CTX_DAG_OWNER=airflow
AIRFLOW_CTX_DAG_ID=AUTOMATISATION
AIRFLOW_CTX_TASK_ID=Chargement_des_données_in_ELK
AIRFLOW_CTX_EXECUTION_DATE=2023-03-13T00:00:33+00:00
AIRFLOW_CTX_TRY_NUMBER=2
AIRFLOW_CTX_DAG_RUN_ID=scheduled__2023-03-13T00:00:33+00:00
[2023-03-13T19:36:25.855+0000] {subprocess.py:63} INFO - Tmp dir root location: 
 /tmp
[2023-03-13T19:36:25.856+0000] {subprocess.py:75} INFO - Running command: ['/usr/bin/bash', '-c', '/usr/bin/logstash --path.config /etc/logstash/conf.d/data.conf']
[2023-03-13T19:36:25.864+0000] {subprocess.py:86} INFO - Output:
[2023-03-13T19:36:25.866+0000] {subprocess.py:93} INFO - /usr/bin/bash: ligne 1: /usr/bin/logstash: Aucun fichier ou dossier de ce type
[2023-03-13T19:36:25.866+0000] {subprocess.py:97} INFO - Command exited with return code 127
[2023-03-13T19:36:25.876+0000] {taskinstance.py:1768} ERROR - Task failed with exception
Traceback (most recent call last):
  File "/home/dev/airflow/airflow/lib/python3.10/site-packages/airflow/operators/bash.py", line 196, in execute
    raise AirflowException(
airflow.exceptions.AirflowException: Bash command failed. The command returned a non-zero exit code 127.
[2023-03-13T19:36:25.881+0000] {taskinstance.py:1318} INFO - Marking task as UP_FOR_RETRY. dag_id=AUTOMATISATION, task_id=Chargement_des_données_in_ELK, execution_date=20230313T000033, start_date=20230313T193625, end_date=20230313T193625
[2023-03-13T19:36:25.901+0000] {standard_task_runner.py:100} ERROR - Failed to execute job 47 for task Chargement_des_données_in_ELK (Bash command failed. The command returned a non-zero exit code 127.; 36020)
[2023-03-13T19:36:25.932+0000] {local_task_job.py:208} INFO - Task exited with return code 1
[2023-03-13T19:36:25.953+0000] {taskinstance.py:2578} INFO - 0 downstream tasks scheduled from follow-on schedule check
[2023-03-13T19:46:56.337+0000] {taskinstance.py:1083} INFO - Dependencies all met for <TaskInstance: AUTOMATISATION.Chargement_des_données_in_ELK scheduled__2023-03-13T00:00:33+00:00 [queued]>
[2023-03-13T19:46:56.350+0000] {taskinstance.py:1083} INFO - Dependencies all met for <TaskInstance: AUTOMATISATION.Chargement_des_données_in_ELK scheduled__2023-03-13T00:00:33+00:00 [queued]>
[2023-03-13T19:46:56.350+0000] {taskinstance.py:1279} INFO - 
--------------------------------------------------------------------------------
[2023-03-13T19:46:56.350+0000] {taskinstance.py:1280} INFO - Starting attempt 2 of 4
[2023-03-13T19:46:56.351+0000] {taskinstance.py:1281} INFO - 
--------------------------------------------------------------------------------
[2023-03-13T19:46:56.371+0000] {taskinstance.py:1300} INFO - Executing <Task(BashOperator): Chargement_des_données_in_ELK> on 2023-03-13 00:00:33+00:00
[2023-03-13T19:46:56.375+0000] {standard_task_runner.py:55} INFO - Started process 37901 to run task
[2023-03-13T19:46:56.380+0000] {standard_task_runner.py:82} INFO - Running: ['airflow', 'tasks', 'run', 'AUTOMATISATION', 'Chargement_des_données_in_ELK', 'scheduled__2023-03-13T00:00:33+00:00', '--job-id', '95', '--raw', '--subdir', 'DAGS_FOLDER/main.py', '--cfg-path', '/tmp/tmpkbombo7n']
[2023-03-13T19:46:56.382+0000] {standard_task_runner.py:83} INFO - Job 95: Subtask Chargement_des_données_in_ELK
[2023-03-13T19:46:56.449+0000] {task_command.py:388} INFO - Running <TaskInstance: AUTOMATISATION.Chargement_des_données_in_ELK scheduled__2023-03-13T00:00:33+00:00 [running]> on host dev
[2023-03-13T19:46:56.518+0000] {taskinstance.py:1507} INFO - Exporting the following env vars:
AIRFLOW_CTX_DAG_OWNER=airflow
AIRFLOW_CTX_DAG_ID=AUTOMATISATION
AIRFLOW_CTX_TASK_ID=Chargement_des_données_in_ELK
AIRFLOW_CTX_EXECUTION_DATE=2023-03-13T00:00:33+00:00
AIRFLOW_CTX_TRY_NUMBER=2
AIRFLOW_CTX_DAG_RUN_ID=scheduled__2023-03-13T00:00:33+00:00
[2023-03-13T19:46:56.519+0000] {subprocess.py:63} INFO - Tmp dir root location: 
 /tmp
[2023-03-13T19:46:56.520+0000] {subprocess.py:75} INFO - Running command: ['/usr/bin/bash', '-c', 'bin/logstash --path.config /etc/logstash/conf.d/data.conf']
[2023-03-13T19:46:56.529+0000] {subprocess.py:86} INFO - Output:
[2023-03-13T19:46:56.531+0000] {subprocess.py:93} INFO - /usr/bin/bash: ligne 1: bin/logstash: Aucun fichier ou dossier de ce type
[2023-03-13T19:46:56.532+0000] {subprocess.py:97} INFO - Command exited with return code 127
[2023-03-13T19:46:56.542+0000] {taskinstance.py:1768} ERROR - Task failed with exception
Traceback (most recent call last):
  File "/home/dev/airflow/airflow/lib/python3.10/site-packages/airflow/operators/bash.py", line 196, in execute
    raise AirflowException(
airflow.exceptions.AirflowException: Bash command failed. The command returned a non-zero exit code 127.
[2023-03-13T19:46:56.547+0000] {taskinstance.py:1318} INFO - Marking task as UP_FOR_RETRY. dag_id=AUTOMATISATION, task_id=Chargement_des_données_in_ELK, execution_date=20230313T000033, start_date=20230313T194656, end_date=20230313T194656
[2023-03-13T19:46:56.567+0000] {standard_task_runner.py:100} ERROR - Failed to execute job 95 for task Chargement_des_données_in_ELK (Bash command failed. The command returned a non-zero exit code 127.; 37901)
[2023-03-13T19:46:56.591+0000] {local_task_job.py:208} INFO - Task exited with return code 1
[2023-03-13T19:46:56.610+0000] {taskinstance.py:2578} INFO - 0 downstream tasks scheduled from follow-on schedule check
[2023-03-13T20:08:26.846+0000] {taskinstance.py:1083} INFO - Dependencies all met for <TaskInstance: AUTOMATISATION.Chargement_des_données_in_ELK scheduled__2023-03-13T00:00:33+00:00 [queued]>
[2023-03-13T20:08:26.859+0000] {taskinstance.py:1083} INFO - Dependencies all met for <TaskInstance: AUTOMATISATION.Chargement_des_données_in_ELK scheduled__2023-03-13T00:00:33+00:00 [queued]>
[2023-03-13T20:08:26.860+0000] {taskinstance.py:1279} INFO - 
--------------------------------------------------------------------------------
[2023-03-13T20:08:26.860+0000] {taskinstance.py:1280} INFO - Starting attempt 2 of 4
[2023-03-13T20:08:26.860+0000] {taskinstance.py:1281} INFO - 
--------------------------------------------------------------------------------
[2023-03-13T20:08:26.882+0000] {taskinstance.py:1300} INFO - Executing <Task(BashOperator): Chargement_des_données_in_ELK> on 2023-03-13 00:00:33+00:00
[2023-03-13T20:08:26.886+0000] {standard_task_runner.py:55} INFO - Started process 41806 to run task
[2023-03-13T20:08:26.891+0000] {standard_task_runner.py:82} INFO - Running: ['airflow', 'tasks', 'run', 'AUTOMATISATION', 'Chargement_des_données_in_ELK', 'scheduled__2023-03-13T00:00:33+00:00', '--job-id', '207', '--raw', '--subdir', 'DAGS_FOLDER/main.py', '--cfg-path', '/tmp/tmpnpes37nv']
[2023-03-13T20:08:26.893+0000] {standard_task_runner.py:83} INFO - Job 207: Subtask Chargement_des_données_in_ELK
[2023-03-13T20:08:26.960+0000] {task_command.py:388} INFO - Running <TaskInstance: AUTOMATISATION.Chargement_des_données_in_ELK scheduled__2023-03-13T00:00:33+00:00 [running]> on host dev
[2023-03-13T20:08:27.026+0000] {taskinstance.py:1507} INFO - Exporting the following env vars:
AIRFLOW_CTX_DAG_OWNER=airflow
AIRFLOW_CTX_DAG_ID=AUTOMATISATION
AIRFLOW_CTX_TASK_ID=Chargement_des_données_in_ELK
AIRFLOW_CTX_EXECUTION_DATE=2023-03-13T00:00:33+00:00
AIRFLOW_CTX_TRY_NUMBER=2
AIRFLOW_CTX_DAG_RUN_ID=scheduled__2023-03-13T00:00:33+00:00
[2023-03-13T20:08:27.028+0000] {subprocess.py:63} INFO - Tmp dir root location: 
 /tmp
[2023-03-13T20:08:27.029+0000] {subprocess.py:75} INFO - Running command: ['/usr/bin/bash', '-c', 'bin/logstash -f /home/dev/etc/logstash/conf.d/data.conf']
[2023-03-13T20:08:27.038+0000] {subprocess.py:86} INFO - Output:
[2023-03-13T20:08:27.040+0000] {subprocess.py:93} INFO - /usr/bin/bash: ligne 1: bin/logstash: Aucun fichier ou dossier de ce type
[2023-03-13T20:08:27.041+0000] {subprocess.py:97} INFO - Command exited with return code 127
[2023-03-13T20:08:27.051+0000] {taskinstance.py:1768} ERROR - Task failed with exception
Traceback (most recent call last):
  File "/home/dev/airflow/airflow/lib/python3.10/site-packages/airflow/operators/bash.py", line 196, in execute
    raise AirflowException(
airflow.exceptions.AirflowException: Bash command failed. The command returned a non-zero exit code 127.
[2023-03-13T20:08:27.055+0000] {taskinstance.py:1318} INFO - Marking task as UP_FOR_RETRY. dag_id=AUTOMATISATION, task_id=Chargement_des_données_in_ELK, execution_date=20230313T000033, start_date=20230313T200826, end_date=20230313T200827
[2023-03-13T20:08:27.075+0000] {standard_task_runner.py:100} ERROR - Failed to execute job 207 for task Chargement_des_données_in_ELK (Bash command failed. The command returned a non-zero exit code 127.; 41806)
[2023-03-13T20:08:27.102+0000] {local_task_job.py:208} INFO - Task exited with return code 1
[2023-03-13T20:08:27.122+0000] {taskinstance.py:2578} INFO - 0 downstream tasks scheduled from follow-on schedule check
