[2023-03-13T19:35:46.609+0000] {taskinstance.py:1083} INFO - Dependencies all met for <TaskInstance: AUTOMATISATION.Chargement_des_données_in_ELK scheduled__2023-03-13T00:00:18+00:00 [queued]>
[2023-03-13T19:35:46.623+0000] {taskinstance.py:1083} INFO - Dependencies all met for <TaskInstance: AUTOMATISATION.Chargement_des_données_in_ELK scheduled__2023-03-13T00:00:18+00:00 [queued]>
[2023-03-13T19:35:46.623+0000] {taskinstance.py:1279} INFO - 
--------------------------------------------------------------------------------
[2023-03-13T19:35:46.623+0000] {taskinstance.py:1280} INFO - Starting attempt 2 of 4
[2023-03-13T19:35:46.624+0000] {taskinstance.py:1281} INFO - 
--------------------------------------------------------------------------------
[2023-03-13T19:35:46.645+0000] {taskinstance.py:1300} INFO - Executing <Task(BashOperator): Chargement_des_données_in_ELK> on 2023-03-13 00:00:18+00:00
[2023-03-13T19:35:46.649+0000] {standard_task_runner.py:55} INFO - Started process 35918 to run task
[2023-03-13T19:35:46.653+0000] {standard_task_runner.py:82} INFO - Running: ['airflow', 'tasks', 'run', 'AUTOMATISATION', 'Chargement_des_données_in_ELK', 'scheduled__2023-03-13T00:00:18+00:00', '--job-id', '42', '--raw', '--subdir', 'DAGS_FOLDER/main.py', '--cfg-path', '/tmp/tmpdi9ugxiq']
[2023-03-13T19:35:46.655+0000] {standard_task_runner.py:83} INFO - Job 42: Subtask Chargement_des_données_in_ELK
[2023-03-13T19:35:46.721+0000] {task_command.py:388} INFO - Running <TaskInstance: AUTOMATISATION.Chargement_des_données_in_ELK scheduled__2023-03-13T00:00:18+00:00 [running]> on host dev
[2023-03-13T19:35:46.786+0000] {taskinstance.py:1507} INFO - Exporting the following env vars:
AIRFLOW_CTX_DAG_OWNER=airflow
AIRFLOW_CTX_DAG_ID=AUTOMATISATION
AIRFLOW_CTX_TASK_ID=Chargement_des_données_in_ELK
AIRFLOW_CTX_EXECUTION_DATE=2023-03-13T00:00:18+00:00
AIRFLOW_CTX_TRY_NUMBER=2
AIRFLOW_CTX_DAG_RUN_ID=scheduled__2023-03-13T00:00:18+00:00
[2023-03-13T19:35:46.788+0000] {subprocess.py:63} INFO - Tmp dir root location: 
 /tmp
[2023-03-13T19:35:46.788+0000] {subprocess.py:75} INFO - Running command: ['/usr/bin/bash', '-c', '/usr/bin/logstash --path.config /etc/logstash/conf.d/data.conf']
[2023-03-13T19:35:46.797+0000] {subprocess.py:86} INFO - Output:
[2023-03-13T19:35:46.799+0000] {subprocess.py:93} INFO - /usr/bin/bash: ligne 1: /usr/bin/logstash: Aucun fichier ou dossier de ce type
[2023-03-13T19:35:46.799+0000] {subprocess.py:97} INFO - Command exited with return code 127
[2023-03-13T19:35:46.813+0000] {taskinstance.py:1768} ERROR - Task failed with exception
Traceback (most recent call last):
  File "/home/dev/airflow/airflow/lib/python3.10/site-packages/airflow/operators/bash.py", line 196, in execute
    raise AirflowException(
airflow.exceptions.AirflowException: Bash command failed. The command returned a non-zero exit code 127.
[2023-03-13T19:35:46.820+0000] {taskinstance.py:1318} INFO - Marking task as UP_FOR_RETRY. dag_id=AUTOMATISATION, task_id=Chargement_des_données_in_ELK, execution_date=20230313T000018, start_date=20230313T193546, end_date=20230313T193546
[2023-03-13T19:35:46.846+0000] {standard_task_runner.py:100} ERROR - Failed to execute job 42 for task Chargement_des_données_in_ELK (Bash command failed. The command returned a non-zero exit code 127.; 35918)
[2023-03-13T19:35:46.864+0000] {local_task_job.py:208} INFO - Task exited with return code 1
[2023-03-13T19:35:46.892+0000] {taskinstance.py:2578} INFO - 0 downstream tasks scheduled from follow-on schedule check
[2023-03-13T19:46:19.858+0000] {taskinstance.py:1083} INFO - Dependencies all met for <TaskInstance: AUTOMATISATION.Chargement_des_données_in_ELK scheduled__2023-03-13T00:00:18+00:00 [queued]>
[2023-03-13T19:46:19.873+0000] {taskinstance.py:1083} INFO - Dependencies all met for <TaskInstance: AUTOMATISATION.Chargement_des_données_in_ELK scheduled__2023-03-13T00:00:18+00:00 [queued]>
[2023-03-13T19:46:19.873+0000] {taskinstance.py:1279} INFO - 
--------------------------------------------------------------------------------
[2023-03-13T19:46:19.874+0000] {taskinstance.py:1280} INFO - Starting attempt 2 of 4
[2023-03-13T19:46:19.874+0000] {taskinstance.py:1281} INFO - 
--------------------------------------------------------------------------------
[2023-03-13T19:46:19.898+0000] {taskinstance.py:1300} INFO - Executing <Task(BashOperator): Chargement_des_données_in_ELK> on 2023-03-13 00:00:18+00:00
[2023-03-13T19:46:19.901+0000] {standard_task_runner.py:55} INFO - Started process 37824 to run task
[2023-03-13T19:46:19.906+0000] {standard_task_runner.py:82} INFO - Running: ['airflow', 'tasks', 'run', 'AUTOMATISATION', 'Chargement_des_données_in_ELK', 'scheduled__2023-03-13T00:00:18+00:00', '--job-id', '90', '--raw', '--subdir', 'DAGS_FOLDER/main.py', '--cfg-path', '/tmp/tmp73cpcsm3']
[2023-03-13T19:46:19.908+0000] {standard_task_runner.py:83} INFO - Job 90: Subtask Chargement_des_données_in_ELK
[2023-03-13T19:46:19.973+0000] {task_command.py:388} INFO - Running <TaskInstance: AUTOMATISATION.Chargement_des_données_in_ELK scheduled__2023-03-13T00:00:18+00:00 [running]> on host dev
[2023-03-13T19:46:20.039+0000] {taskinstance.py:1507} INFO - Exporting the following env vars:
AIRFLOW_CTX_DAG_OWNER=airflow
AIRFLOW_CTX_DAG_ID=AUTOMATISATION
AIRFLOW_CTX_TASK_ID=Chargement_des_données_in_ELK
AIRFLOW_CTX_EXECUTION_DATE=2023-03-13T00:00:18+00:00
AIRFLOW_CTX_TRY_NUMBER=2
AIRFLOW_CTX_DAG_RUN_ID=scheduled__2023-03-13T00:00:18+00:00
[2023-03-13T19:46:20.041+0000] {subprocess.py:63} INFO - Tmp dir root location: 
 /tmp
[2023-03-13T19:46:20.042+0000] {subprocess.py:75} INFO - Running command: ['/usr/bin/bash', '-c', 'bin/logstash --path.config /etc/logstash/conf.d/data.conf']
[2023-03-13T19:46:20.050+0000] {subprocess.py:86} INFO - Output:
[2023-03-13T19:46:20.052+0000] {subprocess.py:93} INFO - /usr/bin/bash: ligne 1: bin/logstash: Aucun fichier ou dossier de ce type
[2023-03-13T19:46:20.052+0000] {subprocess.py:97} INFO - Command exited with return code 127
[2023-03-13T19:46:20.062+0000] {taskinstance.py:1768} ERROR - Task failed with exception
Traceback (most recent call last):
  File "/home/dev/airflow/airflow/lib/python3.10/site-packages/airflow/operators/bash.py", line 196, in execute
    raise AirflowException(
airflow.exceptions.AirflowException: Bash command failed. The command returned a non-zero exit code 127.
[2023-03-13T19:46:20.067+0000] {taskinstance.py:1318} INFO - Marking task as UP_FOR_RETRY. dag_id=AUTOMATISATION, task_id=Chargement_des_données_in_ELK, execution_date=20230313T000018, start_date=20230313T194619, end_date=20230313T194620
[2023-03-13T19:46:20.086+0000] {standard_task_runner.py:100} ERROR - Failed to execute job 90 for task Chargement_des_données_in_ELK (Bash command failed. The command returned a non-zero exit code 127.; 37824)
[2023-03-13T19:46:20.117+0000] {local_task_job.py:208} INFO - Task exited with return code 1
[2023-03-13T19:46:20.141+0000] {taskinstance.py:2578} INFO - 0 downstream tasks scheduled from follow-on schedule check
[2023-03-13T20:07:45.424+0000] {taskinstance.py:1083} INFO - Dependencies all met for <TaskInstance: AUTOMATISATION.Chargement_des_données_in_ELK scheduled__2023-03-13T00:00:18+00:00 [queued]>
[2023-03-13T20:07:45.438+0000] {taskinstance.py:1083} INFO - Dependencies all met for <TaskInstance: AUTOMATISATION.Chargement_des_données_in_ELK scheduled__2023-03-13T00:00:18+00:00 [queued]>
[2023-03-13T20:07:45.438+0000] {taskinstance.py:1279} INFO - 
--------------------------------------------------------------------------------
[2023-03-13T20:07:45.438+0000] {taskinstance.py:1280} INFO - Starting attempt 2 of 4
[2023-03-13T20:07:45.438+0000] {taskinstance.py:1281} INFO - 
--------------------------------------------------------------------------------
[2023-03-13T20:07:45.462+0000] {taskinstance.py:1300} INFO - Executing <Task(BashOperator): Chargement_des_données_in_ELK> on 2023-03-13 00:00:18+00:00
[2023-03-13T20:07:45.466+0000] {standard_task_runner.py:55} INFO - Started process 41695 to run task
[2023-03-13T20:07:45.470+0000] {standard_task_runner.py:82} INFO - Running: ['airflow', 'tasks', 'run', 'AUTOMATISATION', 'Chargement_des_données_in_ELK', 'scheduled__2023-03-13T00:00:18+00:00', '--job-id', '202', '--raw', '--subdir', 'DAGS_FOLDER/main.py', '--cfg-path', '/tmp/tmpvy3uzwkr']
[2023-03-13T20:07:45.472+0000] {standard_task_runner.py:83} INFO - Job 202: Subtask Chargement_des_données_in_ELK
[2023-03-13T20:07:45.540+0000] {task_command.py:388} INFO - Running <TaskInstance: AUTOMATISATION.Chargement_des_données_in_ELK scheduled__2023-03-13T00:00:18+00:00 [running]> on host dev
[2023-03-13T20:07:45.610+0000] {taskinstance.py:1507} INFO - Exporting the following env vars:
AIRFLOW_CTX_DAG_OWNER=airflow
AIRFLOW_CTX_DAG_ID=AUTOMATISATION
AIRFLOW_CTX_TASK_ID=Chargement_des_données_in_ELK
AIRFLOW_CTX_EXECUTION_DATE=2023-03-13T00:00:18+00:00
AIRFLOW_CTX_TRY_NUMBER=2
AIRFLOW_CTX_DAG_RUN_ID=scheduled__2023-03-13T00:00:18+00:00
[2023-03-13T20:07:45.612+0000] {subprocess.py:63} INFO - Tmp dir root location: 
 /tmp
[2023-03-13T20:07:45.613+0000] {subprocess.py:75} INFO - Running command: ['/usr/bin/bash', '-c', 'bin/logstash -f /home/dev/etc/logstash/conf.d/data.conf']
[2023-03-13T20:07:45.622+0000] {subprocess.py:86} INFO - Output:
[2023-03-13T20:07:45.624+0000] {subprocess.py:93} INFO - /usr/bin/bash: ligne 1: bin/logstash: Aucun fichier ou dossier de ce type
[2023-03-13T20:07:45.625+0000] {subprocess.py:97} INFO - Command exited with return code 127
[2023-03-13T20:07:45.635+0000] {taskinstance.py:1768} ERROR - Task failed with exception
Traceback (most recent call last):
  File "/home/dev/airflow/airflow/lib/python3.10/site-packages/airflow/operators/bash.py", line 196, in execute
    raise AirflowException(
airflow.exceptions.AirflowException: Bash command failed. The command returned a non-zero exit code 127.
[2023-03-13T20:07:45.639+0000] {taskinstance.py:1318} INFO - Marking task as UP_FOR_RETRY. dag_id=AUTOMATISATION, task_id=Chargement_des_données_in_ELK, execution_date=20230313T000018, start_date=20230313T200745, end_date=20230313T200745
[2023-03-13T20:07:45.659+0000] {standard_task_runner.py:100} ERROR - Failed to execute job 202 for task Chargement_des_données_in_ELK (Bash command failed. The command returned a non-zero exit code 127.; 41695)
[2023-03-13T20:07:45.681+0000] {local_task_job.py:208} INFO - Task exited with return code 1
[2023-03-13T20:07:45.701+0000] {taskinstance.py:2578} INFO - 0 downstream tasks scheduled from follow-on schedule check
