[2023-03-13T19:35:53.577+0000] {taskinstance.py:1083} INFO - Dependencies all met for <TaskInstance: AUTOMATISATION.Chargement_des_données_in_ELK scheduled__2023-03-13T00:00:21+00:00 [queued]>
[2023-03-13T19:35:53.590+0000] {taskinstance.py:1083} INFO - Dependencies all met for <TaskInstance: AUTOMATISATION.Chargement_des_données_in_ELK scheduled__2023-03-13T00:00:21+00:00 [queued]>
[2023-03-13T19:35:53.591+0000] {taskinstance.py:1279} INFO - 
--------------------------------------------------------------------------------
[2023-03-13T19:35:53.591+0000] {taskinstance.py:1280} INFO - Starting attempt 2 of 4
[2023-03-13T19:35:53.591+0000] {taskinstance.py:1281} INFO - 
--------------------------------------------------------------------------------
[2023-03-13T19:35:53.612+0000] {taskinstance.py:1300} INFO - Executing <Task(BashOperator): Chargement_des_données_in_ELK> on 2023-03-13 00:00:21+00:00
[2023-03-13T19:35:53.615+0000] {standard_task_runner.py:55} INFO - Started process 35946 to run task
[2023-03-13T19:35:53.619+0000] {standard_task_runner.py:82} INFO - Running: ['airflow', 'tasks', 'run', 'AUTOMATISATION', 'Chargement_des_données_in_ELK', 'scheduled__2023-03-13T00:00:21+00:00', '--job-id', '43', '--raw', '--subdir', 'DAGS_FOLDER/main.py', '--cfg-path', '/tmp/tmp62gtxi2m']
[2023-03-13T19:35:53.621+0000] {standard_task_runner.py:83} INFO - Job 43: Subtask Chargement_des_données_in_ELK
[2023-03-13T19:35:53.686+0000] {task_command.py:388} INFO - Running <TaskInstance: AUTOMATISATION.Chargement_des_données_in_ELK scheduled__2023-03-13T00:00:21+00:00 [running]> on host dev
[2023-03-13T19:35:53.753+0000] {taskinstance.py:1507} INFO - Exporting the following env vars:
AIRFLOW_CTX_DAG_OWNER=airflow
AIRFLOW_CTX_DAG_ID=AUTOMATISATION
AIRFLOW_CTX_TASK_ID=Chargement_des_données_in_ELK
AIRFLOW_CTX_EXECUTION_DATE=2023-03-13T00:00:21+00:00
AIRFLOW_CTX_TRY_NUMBER=2
AIRFLOW_CTX_DAG_RUN_ID=scheduled__2023-03-13T00:00:21+00:00
[2023-03-13T19:35:53.754+0000] {subprocess.py:63} INFO - Tmp dir root location: 
 /tmp
[2023-03-13T19:35:53.755+0000] {subprocess.py:75} INFO - Running command: ['/usr/bin/bash', '-c', '/usr/bin/logstash --path.config /etc/logstash/conf.d/data.conf']
[2023-03-13T19:35:53.763+0000] {subprocess.py:86} INFO - Output:
[2023-03-13T19:35:53.764+0000] {subprocess.py:93} INFO - /usr/bin/bash: ligne 1: /usr/bin/logstash: Aucun fichier ou dossier de ce type
[2023-03-13T19:35:53.764+0000] {subprocess.py:97} INFO - Command exited with return code 127
[2023-03-13T19:35:53.774+0000] {taskinstance.py:1768} ERROR - Task failed with exception
Traceback (most recent call last):
  File "/home/dev/airflow/airflow/lib/python3.10/site-packages/airflow/operators/bash.py", line 196, in execute
    raise AirflowException(
airflow.exceptions.AirflowException: Bash command failed. The command returned a non-zero exit code 127.
[2023-03-13T19:35:53.779+0000] {taskinstance.py:1318} INFO - Marking task as UP_FOR_RETRY. dag_id=AUTOMATISATION, task_id=Chargement_des_données_in_ELK, execution_date=20230313T000021, start_date=20230313T193553, end_date=20230313T193553
[2023-03-13T19:35:53.800+0000] {standard_task_runner.py:100} ERROR - Failed to execute job 43 for task Chargement_des_données_in_ELK (Bash command failed. The command returned a non-zero exit code 127.; 35946)
[2023-03-13T19:35:53.831+0000] {local_task_job.py:208} INFO - Task exited with return code 1
[2023-03-13T19:35:53.850+0000] {taskinstance.py:2578} INFO - 0 downstream tasks scheduled from follow-on schedule check
[2023-03-13T19:46:27.512+0000] {taskinstance.py:1083} INFO - Dependencies all met for <TaskInstance: AUTOMATISATION.Chargement_des_données_in_ELK scheduled__2023-03-13T00:00:21+00:00 [queued]>
[2023-03-13T19:46:27.530+0000] {taskinstance.py:1083} INFO - Dependencies all met for <TaskInstance: AUTOMATISATION.Chargement_des_données_in_ELK scheduled__2023-03-13T00:00:21+00:00 [queued]>
[2023-03-13T19:46:27.530+0000] {taskinstance.py:1279} INFO - 
--------------------------------------------------------------------------------
[2023-03-13T19:46:27.531+0000] {taskinstance.py:1280} INFO - Starting attempt 2 of 4
[2023-03-13T19:46:27.531+0000] {taskinstance.py:1281} INFO - 
--------------------------------------------------------------------------------
[2023-03-13T19:46:27.561+0000] {taskinstance.py:1300} INFO - Executing <Task(BashOperator): Chargement_des_données_in_ELK> on 2023-03-13 00:00:21+00:00
[2023-03-13T19:46:27.566+0000] {standard_task_runner.py:55} INFO - Started process 37832 to run task
[2023-03-13T19:46:27.570+0000] {standard_task_runner.py:82} INFO - Running: ['airflow', 'tasks', 'run', 'AUTOMATISATION', 'Chargement_des_données_in_ELK', 'scheduled__2023-03-13T00:00:21+00:00', '--job-id', '91', '--raw', '--subdir', 'DAGS_FOLDER/main.py', '--cfg-path', '/tmp/tmp4wqr1m5x']
[2023-03-13T19:46:27.572+0000] {standard_task_runner.py:83} INFO - Job 91: Subtask Chargement_des_données_in_ELK
[2023-03-13T19:46:27.674+0000] {task_command.py:388} INFO - Running <TaskInstance: AUTOMATISATION.Chargement_des_données_in_ELK scheduled__2023-03-13T00:00:21+00:00 [running]> on host dev
[2023-03-13T19:46:27.766+0000] {taskinstance.py:1507} INFO - Exporting the following env vars:
AIRFLOW_CTX_DAG_OWNER=airflow
AIRFLOW_CTX_DAG_ID=AUTOMATISATION
AIRFLOW_CTX_TASK_ID=Chargement_des_données_in_ELK
AIRFLOW_CTX_EXECUTION_DATE=2023-03-13T00:00:21+00:00
AIRFLOW_CTX_TRY_NUMBER=2
AIRFLOW_CTX_DAG_RUN_ID=scheduled__2023-03-13T00:00:21+00:00
[2023-03-13T19:46:27.768+0000] {subprocess.py:63} INFO - Tmp dir root location: 
 /tmp
[2023-03-13T19:46:27.769+0000] {subprocess.py:75} INFO - Running command: ['/usr/bin/bash', '-c', 'bin/logstash --path.config /etc/logstash/conf.d/data.conf']
[2023-03-13T19:46:27.779+0000] {subprocess.py:86} INFO - Output:
[2023-03-13T19:46:27.781+0000] {subprocess.py:93} INFO - /usr/bin/bash: ligne 1: bin/logstash: Aucun fichier ou dossier de ce type
[2023-03-13T19:46:27.782+0000] {subprocess.py:97} INFO - Command exited with return code 127
[2023-03-13T19:46:27.796+0000] {taskinstance.py:1768} ERROR - Task failed with exception
Traceback (most recent call last):
  File "/home/dev/airflow/airflow/lib/python3.10/site-packages/airflow/operators/bash.py", line 196, in execute
    raise AirflowException(
airflow.exceptions.AirflowException: Bash command failed. The command returned a non-zero exit code 127.
[2023-03-13T19:46:27.802+0000] {taskinstance.py:1318} INFO - Marking task as UP_FOR_RETRY. dag_id=AUTOMATISATION, task_id=Chargement_des_données_in_ELK, execution_date=20230313T000021, start_date=20230313T194627, end_date=20230313T194627
[2023-03-13T19:46:27.826+0000] {standard_task_runner.py:100} ERROR - Failed to execute job 91 for task Chargement_des_données_in_ELK (Bash command failed. The command returned a non-zero exit code 127.; 37832)
[2023-03-13T19:46:27.863+0000] {local_task_job.py:208} INFO - Task exited with return code 1
[2023-03-13T19:46:27.884+0000] {taskinstance.py:2578} INFO - 0 downstream tasks scheduled from follow-on schedule check
[2023-03-13T20:07:53.704+0000] {taskinstance.py:1083} INFO - Dependencies all met for <TaskInstance: AUTOMATISATION.Chargement_des_données_in_ELK scheduled__2023-03-13T00:00:21+00:00 [queued]>
[2023-03-13T20:07:53.716+0000] {taskinstance.py:1083} INFO - Dependencies all met for <TaskInstance: AUTOMATISATION.Chargement_des_données_in_ELK scheduled__2023-03-13T00:00:21+00:00 [queued]>
[2023-03-13T20:07:53.717+0000] {taskinstance.py:1279} INFO - 
--------------------------------------------------------------------------------
[2023-03-13T20:07:53.717+0000] {taskinstance.py:1280} INFO - Starting attempt 2 of 4
[2023-03-13T20:07:53.717+0000] {taskinstance.py:1281} INFO - 
--------------------------------------------------------------------------------
[2023-03-13T20:07:53.738+0000] {taskinstance.py:1300} INFO - Executing <Task(BashOperator): Chargement_des_données_in_ELK> on 2023-03-13 00:00:21+00:00
[2023-03-13T20:07:53.741+0000] {standard_task_runner.py:55} INFO - Started process 41724 to run task
[2023-03-13T20:07:53.745+0000] {standard_task_runner.py:82} INFO - Running: ['airflow', 'tasks', 'run', 'AUTOMATISATION', 'Chargement_des_données_in_ELK', 'scheduled__2023-03-13T00:00:21+00:00', '--job-id', '203', '--raw', '--subdir', 'DAGS_FOLDER/main.py', '--cfg-path', '/tmp/tmpqjrn0n1l']
[2023-03-13T20:07:53.747+0000] {standard_task_runner.py:83} INFO - Job 203: Subtask Chargement_des_données_in_ELK
[2023-03-13T20:07:53.813+0000] {task_command.py:388} INFO - Running <TaskInstance: AUTOMATISATION.Chargement_des_données_in_ELK scheduled__2023-03-13T00:00:21+00:00 [running]> on host dev
[2023-03-13T20:07:53.882+0000] {taskinstance.py:1507} INFO - Exporting the following env vars:
AIRFLOW_CTX_DAG_OWNER=airflow
AIRFLOW_CTX_DAG_ID=AUTOMATISATION
AIRFLOW_CTX_TASK_ID=Chargement_des_données_in_ELK
AIRFLOW_CTX_EXECUTION_DATE=2023-03-13T00:00:21+00:00
AIRFLOW_CTX_TRY_NUMBER=2
AIRFLOW_CTX_DAG_RUN_ID=scheduled__2023-03-13T00:00:21+00:00
[2023-03-13T20:07:53.884+0000] {subprocess.py:63} INFO - Tmp dir root location: 
 /tmp
[2023-03-13T20:07:53.885+0000] {subprocess.py:75} INFO - Running command: ['/usr/bin/bash', '-c', 'bin/logstash -f /home/dev/etc/logstash/conf.d/data.conf']
[2023-03-13T20:07:53.893+0000] {subprocess.py:86} INFO - Output:
[2023-03-13T20:07:53.895+0000] {subprocess.py:93} INFO - /usr/bin/bash: ligne 1: bin/logstash: Aucun fichier ou dossier de ce type
[2023-03-13T20:07:53.895+0000] {subprocess.py:97} INFO - Command exited with return code 127
[2023-03-13T20:07:53.906+0000] {taskinstance.py:1768} ERROR - Task failed with exception
Traceback (most recent call last):
  File "/home/dev/airflow/airflow/lib/python3.10/site-packages/airflow/operators/bash.py", line 196, in execute
    raise AirflowException(
airflow.exceptions.AirflowException: Bash command failed. The command returned a non-zero exit code 127.
[2023-03-13T20:07:53.910+0000] {taskinstance.py:1318} INFO - Marking task as UP_FOR_RETRY. dag_id=AUTOMATISATION, task_id=Chargement_des_données_in_ELK, execution_date=20230313T000021, start_date=20230313T200753, end_date=20230313T200753
[2023-03-13T20:07:53.930+0000] {standard_task_runner.py:100} ERROR - Failed to execute job 203 for task Chargement_des_données_in_ELK (Bash command failed. The command returned a non-zero exit code 127.; 41724)
[2023-03-13T20:07:53.956+0000] {local_task_job.py:208} INFO - Task exited with return code 1
[2023-03-13T20:07:53.977+0000] {taskinstance.py:2578} INFO - 0 downstream tasks scheduled from follow-on schedule check
