[2023-03-13T19:51:30.811+0000] {taskinstance.py:1083} INFO - Dependencies all met for <TaskInstance: AUTOMATISATION.Chargement_des_données_in_ELK scheduled__2023-03-13T00:00:21+00:00 [queued]>
[2023-03-13T19:51:30.823+0000] {taskinstance.py:1083} INFO - Dependencies all met for <TaskInstance: AUTOMATISATION.Chargement_des_données_in_ELK scheduled__2023-03-13T00:00:21+00:00 [queued]>
[2023-03-13T19:51:30.824+0000] {taskinstance.py:1279} INFO - 
--------------------------------------------------------------------------------
[2023-03-13T19:51:30.824+0000] {taskinstance.py:1280} INFO - Starting attempt 3 of 4
[2023-03-13T19:51:30.824+0000] {taskinstance.py:1281} INFO - 
--------------------------------------------------------------------------------
[2023-03-13T19:51:30.844+0000] {taskinstance.py:1300} INFO - Executing <Task(BashOperator): Chargement_des_données_in_ELK> on 2023-03-13 00:00:21+00:00
[2023-03-13T19:51:30.847+0000] {standard_task_runner.py:55} INFO - Started process 38598 to run task
[2023-03-13T19:51:30.851+0000] {standard_task_runner.py:82} INFO - Running: ['airflow', 'tasks', 'run', 'AUTOMATISATION', 'Chargement_des_données_in_ELK', 'scheduled__2023-03-13T00:00:21+00:00', '--job-id', '107', '--raw', '--subdir', 'DAGS_FOLDER/main.py', '--cfg-path', '/tmp/tmpmf9d2431']
[2023-03-13T19:51:30.853+0000] {standard_task_runner.py:83} INFO - Job 107: Subtask Chargement_des_données_in_ELK
[2023-03-13T19:51:30.932+0000] {task_command.py:388} INFO - Running <TaskInstance: AUTOMATISATION.Chargement_des_données_in_ELK scheduled__2023-03-13T00:00:21+00:00 [running]> on host dev
[2023-03-13T19:51:30.992+0000] {taskinstance.py:1507} INFO - Exporting the following env vars:
AIRFLOW_CTX_DAG_OWNER=airflow
AIRFLOW_CTX_DAG_ID=AUTOMATISATION
AIRFLOW_CTX_TASK_ID=Chargement_des_données_in_ELK
AIRFLOW_CTX_EXECUTION_DATE=2023-03-13T00:00:21+00:00
AIRFLOW_CTX_TRY_NUMBER=3
AIRFLOW_CTX_DAG_RUN_ID=scheduled__2023-03-13T00:00:21+00:00
[2023-03-13T19:51:30.994+0000] {subprocess.py:63} INFO - Tmp dir root location: 
 /tmp
[2023-03-13T19:51:30.995+0000] {subprocess.py:75} INFO - Running command: ['/usr/bin/bash', '-c', 'bin/logstash --path.config /etc/logstash/conf.d/data.conf']
[2023-03-13T19:51:31.002+0000] {subprocess.py:86} INFO - Output:
[2023-03-13T19:51:31.004+0000] {subprocess.py:93} INFO - /usr/bin/bash: ligne 1: bin/logstash: Aucun fichier ou dossier de ce type
[2023-03-13T19:51:31.004+0000] {subprocess.py:97} INFO - Command exited with return code 127
[2023-03-13T19:51:31.014+0000] {taskinstance.py:1768} ERROR - Task failed with exception
Traceback (most recent call last):
  File "/home/dev/airflow/airflow/lib/python3.10/site-packages/airflow/operators/bash.py", line 196, in execute
    raise AirflowException(
airflow.exceptions.AirflowException: Bash command failed. The command returned a non-zero exit code 127.
[2023-03-13T19:51:31.019+0000] {taskinstance.py:1318} INFO - Marking task as UP_FOR_RETRY. dag_id=AUTOMATISATION, task_id=Chargement_des_données_in_ELK, execution_date=20230313T000021, start_date=20230313T195130, end_date=20230313T195131
[2023-03-13T19:51:31.037+0000] {standard_task_runner.py:100} ERROR - Failed to execute job 107 for task Chargement_des_données_in_ELK (Bash command failed. The command returned a non-zero exit code 127.; 38598)
[2023-03-13T19:51:31.062+0000] {local_task_job.py:208} INFO - Task exited with return code 1
[2023-03-13T19:51:31.082+0000] {taskinstance.py:2578} INFO - 0 downstream tasks scheduled from follow-on schedule check
[2023-03-13T20:12:57.016+0000] {taskinstance.py:1083} INFO - Dependencies all met for <TaskInstance: AUTOMATISATION.Chargement_des_données_in_ELK scheduled__2023-03-13T00:00:21+00:00 [queued]>
[2023-03-13T20:12:57.030+0000] {taskinstance.py:1083} INFO - Dependencies all met for <TaskInstance: AUTOMATISATION.Chargement_des_données_in_ELK scheduled__2023-03-13T00:00:21+00:00 [queued]>
[2023-03-13T20:12:57.030+0000] {taskinstance.py:1279} INFO - 
--------------------------------------------------------------------------------
[2023-03-13T20:12:57.030+0000] {taskinstance.py:1280} INFO - Starting attempt 3 of 4
[2023-03-13T20:12:57.031+0000] {taskinstance.py:1281} INFO - 
--------------------------------------------------------------------------------
[2023-03-13T20:12:57.054+0000] {taskinstance.py:1300} INFO - Executing <Task(BashOperator): Chargement_des_données_in_ELK> on 2023-03-13 00:00:21+00:00
[2023-03-13T20:12:57.058+0000] {standard_task_runner.py:55} INFO - Started process 42477 to run task
[2023-03-13T20:12:57.063+0000] {standard_task_runner.py:82} INFO - Running: ['airflow', 'tasks', 'run', 'AUTOMATISATION', 'Chargement_des_données_in_ELK', 'scheduled__2023-03-13T00:00:21+00:00', '--job-id', '219', '--raw', '--subdir', 'DAGS_FOLDER/main.py', '--cfg-path', '/tmp/tmp_2iu3cqc']
[2023-03-13T20:12:57.065+0000] {standard_task_runner.py:83} INFO - Job 219: Subtask Chargement_des_données_in_ELK
[2023-03-13T20:12:57.131+0000] {task_command.py:388} INFO - Running <TaskInstance: AUTOMATISATION.Chargement_des_données_in_ELK scheduled__2023-03-13T00:00:21+00:00 [running]> on host dev
[2023-03-13T20:12:57.198+0000] {taskinstance.py:1507} INFO - Exporting the following env vars:
AIRFLOW_CTX_DAG_OWNER=airflow
AIRFLOW_CTX_DAG_ID=AUTOMATISATION
AIRFLOW_CTX_TASK_ID=Chargement_des_données_in_ELK
AIRFLOW_CTX_EXECUTION_DATE=2023-03-13T00:00:21+00:00
AIRFLOW_CTX_TRY_NUMBER=3
AIRFLOW_CTX_DAG_RUN_ID=scheduled__2023-03-13T00:00:21+00:00
[2023-03-13T20:12:57.200+0000] {subprocess.py:63} INFO - Tmp dir root location: 
 /tmp
[2023-03-13T20:12:57.201+0000] {subprocess.py:75} INFO - Running command: ['/usr/bin/bash', '-c', 'bin/logstash -f /home/dev/etc/logstash/conf.d/data.conf']
[2023-03-13T20:12:57.210+0000] {subprocess.py:86} INFO - Output:
[2023-03-13T20:12:57.211+0000] {subprocess.py:93} INFO - /usr/bin/bash: ligne 1: bin/logstash: Aucun fichier ou dossier de ce type
[2023-03-13T20:12:57.212+0000] {subprocess.py:97} INFO - Command exited with return code 127
[2023-03-13T20:12:57.222+0000] {taskinstance.py:1768} ERROR - Task failed with exception
Traceback (most recent call last):
  File "/home/dev/airflow/airflow/lib/python3.10/site-packages/airflow/operators/bash.py", line 196, in execute
    raise AirflowException(
airflow.exceptions.AirflowException: Bash command failed. The command returned a non-zero exit code 127.
[2023-03-13T20:12:57.227+0000] {taskinstance.py:1318} INFO - Marking task as UP_FOR_RETRY. dag_id=AUTOMATISATION, task_id=Chargement_des_données_in_ELK, execution_date=20230313T000021, start_date=20230313T201257, end_date=20230313T201257
[2023-03-13T20:12:57.245+0000] {standard_task_runner.py:100} ERROR - Failed to execute job 219 for task Chargement_des_données_in_ELK (Bash command failed. The command returned a non-zero exit code 127.; 42477)
[2023-03-13T20:12:57.274+0000] {local_task_job.py:208} INFO - Task exited with return code 1
[2023-03-13T20:12:57.294+0000] {taskinstance.py:2578} INFO - 0 downstream tasks scheduled from follow-on schedule check
