[2023-03-13T19:36:40.927+0000] {taskinstance.py:1083} INFO - Dependencies all met for <TaskInstance: AUTOMATISATION.Chargement_des_données_in_ELK scheduled__2023-03-13T00:00:39+00:00 [queued]>
[2023-03-13T19:36:40.939+0000] {taskinstance.py:1083} INFO - Dependencies all met for <TaskInstance: AUTOMATISATION.Chargement_des_données_in_ELK scheduled__2023-03-13T00:00:39+00:00 [queued]>
[2023-03-13T19:36:40.940+0000] {taskinstance.py:1279} INFO - 
--------------------------------------------------------------------------------
[2023-03-13T19:36:40.940+0000] {taskinstance.py:1280} INFO - Starting attempt 2 of 4
[2023-03-13T19:36:40.940+0000] {taskinstance.py:1281} INFO - 
--------------------------------------------------------------------------------
[2023-03-13T19:36:40.961+0000] {taskinstance.py:1300} INFO - Executing <Task(BashOperator): Chargement_des_données_in_ELK> on 2023-03-13 00:00:39+00:00
[2023-03-13T19:36:40.965+0000] {standard_task_runner.py:55} INFO - Started process 36031 to run task
[2023-03-13T19:36:40.969+0000] {standard_task_runner.py:82} INFO - Running: ['airflow', 'tasks', 'run', 'AUTOMATISATION', 'Chargement_des_données_in_ELK', 'scheduled__2023-03-13T00:00:39+00:00', '--job-id', '49', '--raw', '--subdir', 'DAGS_FOLDER/main.py', '--cfg-path', '/tmp/tmp096wfrhf']
[2023-03-13T19:36:40.971+0000] {standard_task_runner.py:83} INFO - Job 49: Subtask Chargement_des_données_in_ELK
[2023-03-13T19:36:41.037+0000] {task_command.py:388} INFO - Running <TaskInstance: AUTOMATISATION.Chargement_des_données_in_ELK scheduled__2023-03-13T00:00:39+00:00 [running]> on host dev
[2023-03-13T19:36:41.105+0000] {taskinstance.py:1507} INFO - Exporting the following env vars:
AIRFLOW_CTX_DAG_OWNER=airflow
AIRFLOW_CTX_DAG_ID=AUTOMATISATION
AIRFLOW_CTX_TASK_ID=Chargement_des_données_in_ELK
AIRFLOW_CTX_EXECUTION_DATE=2023-03-13T00:00:39+00:00
AIRFLOW_CTX_TRY_NUMBER=2
AIRFLOW_CTX_DAG_RUN_ID=scheduled__2023-03-13T00:00:39+00:00
[2023-03-13T19:36:41.107+0000] {subprocess.py:63} INFO - Tmp dir root location: 
 /tmp
[2023-03-13T19:36:41.108+0000] {subprocess.py:75} INFO - Running command: ['/usr/bin/bash', '-c', '/usr/bin/logstash --path.config /etc/logstash/conf.d/data.conf']
[2023-03-13T19:36:41.117+0000] {subprocess.py:86} INFO - Output:
[2023-03-13T19:36:41.118+0000] {subprocess.py:93} INFO - /usr/bin/bash: ligne 1: /usr/bin/logstash: Aucun fichier ou dossier de ce type
[2023-03-13T19:36:41.119+0000] {subprocess.py:97} INFO - Command exited with return code 127
[2023-03-13T19:36:41.128+0000] {taskinstance.py:1768} ERROR - Task failed with exception
Traceback (most recent call last):
  File "/home/dev/airflow/airflow/lib/python3.10/site-packages/airflow/operators/bash.py", line 196, in execute
    raise AirflowException(
airflow.exceptions.AirflowException: Bash command failed. The command returned a non-zero exit code 127.
[2023-03-13T19:36:41.133+0000] {taskinstance.py:1318} INFO - Marking task as UP_FOR_RETRY. dag_id=AUTOMATISATION, task_id=Chargement_des_données_in_ELK, execution_date=20230313T000039, start_date=20230313T193640, end_date=20230313T193641
[2023-03-13T19:36:41.150+0000] {standard_task_runner.py:100} ERROR - Failed to execute job 49 for task Chargement_des_données_in_ELK (Bash command failed. The command returned a non-zero exit code 127.; 36031)
[2023-03-13T19:36:41.180+0000] {local_task_job.py:208} INFO - Task exited with return code 1
[2023-03-13T19:36:41.201+0000] {taskinstance.py:2578} INFO - 0 downstream tasks scheduled from follow-on schedule check
[2023-03-13T19:47:12.361+0000] {taskinstance.py:1083} INFO - Dependencies all met for <TaskInstance: AUTOMATISATION.Chargement_des_données_in_ELK scheduled__2023-03-13T00:00:39+00:00 [queued]>
[2023-03-13T19:47:12.375+0000] {taskinstance.py:1083} INFO - Dependencies all met for <TaskInstance: AUTOMATISATION.Chargement_des_données_in_ELK scheduled__2023-03-13T00:00:39+00:00 [queued]>
[2023-03-13T19:47:12.375+0000] {taskinstance.py:1279} INFO - 
--------------------------------------------------------------------------------
[2023-03-13T19:47:12.375+0000] {taskinstance.py:1280} INFO - Starting attempt 2 of 4
[2023-03-13T19:47:12.376+0000] {taskinstance.py:1281} INFO - 
--------------------------------------------------------------------------------
[2023-03-13T19:47:12.399+0000] {taskinstance.py:1300} INFO - Executing <Task(BashOperator): Chargement_des_données_in_ELK> on 2023-03-13 00:00:39+00:00
[2023-03-13T19:47:12.402+0000] {standard_task_runner.py:55} INFO - Started process 37967 to run task
[2023-03-13T19:47:12.406+0000] {standard_task_runner.py:82} INFO - Running: ['airflow', 'tasks', 'run', 'AUTOMATISATION', 'Chargement_des_données_in_ELK', 'scheduled__2023-03-13T00:00:39+00:00', '--job-id', '97', '--raw', '--subdir', 'DAGS_FOLDER/main.py', '--cfg-path', '/tmp/tmpavsckqan']
[2023-03-13T19:47:12.408+0000] {standard_task_runner.py:83} INFO - Job 97: Subtask Chargement_des_données_in_ELK
[2023-03-13T19:47:12.481+0000] {task_command.py:388} INFO - Running <TaskInstance: AUTOMATISATION.Chargement_des_données_in_ELK scheduled__2023-03-13T00:00:39+00:00 [running]> on host dev
[2023-03-13T19:47:12.546+0000] {taskinstance.py:1507} INFO - Exporting the following env vars:
AIRFLOW_CTX_DAG_OWNER=airflow
AIRFLOW_CTX_DAG_ID=AUTOMATISATION
AIRFLOW_CTX_TASK_ID=Chargement_des_données_in_ELK
AIRFLOW_CTX_EXECUTION_DATE=2023-03-13T00:00:39+00:00
AIRFLOW_CTX_TRY_NUMBER=2
AIRFLOW_CTX_DAG_RUN_ID=scheduled__2023-03-13T00:00:39+00:00
[2023-03-13T19:47:12.548+0000] {subprocess.py:63} INFO - Tmp dir root location: 
 /tmp
[2023-03-13T19:47:12.548+0000] {subprocess.py:75} INFO - Running command: ['/usr/bin/bash', '-c', 'bin/logstash --path.config /etc/logstash/conf.d/data.conf']
[2023-03-13T19:47:12.557+0000] {subprocess.py:86} INFO - Output:
[2023-03-13T19:47:12.559+0000] {subprocess.py:93} INFO - /usr/bin/bash: ligne 1: bin/logstash: Aucun fichier ou dossier de ce type
[2023-03-13T19:47:12.559+0000] {subprocess.py:97} INFO - Command exited with return code 127
[2023-03-13T19:47:12.570+0000] {taskinstance.py:1768} ERROR - Task failed with exception
Traceback (most recent call last):
  File "/home/dev/airflow/airflow/lib/python3.10/site-packages/airflow/operators/bash.py", line 196, in execute
    raise AirflowException(
airflow.exceptions.AirflowException: Bash command failed. The command returned a non-zero exit code 127.
[2023-03-13T19:47:12.574+0000] {taskinstance.py:1318} INFO - Marking task as UP_FOR_RETRY. dag_id=AUTOMATISATION, task_id=Chargement_des_données_in_ELK, execution_date=20230313T000039, start_date=20230313T194712, end_date=20230313T194712
[2023-03-13T19:47:12.593+0000] {standard_task_runner.py:100} ERROR - Failed to execute job 97 for task Chargement_des_données_in_ELK (Bash command failed. The command returned a non-zero exit code 127.; 37967)
[2023-03-13T19:47:12.617+0000] {local_task_job.py:208} INFO - Task exited with return code 1
[2023-03-13T19:47:12.637+0000] {taskinstance.py:2578} INFO - 0 downstream tasks scheduled from follow-on schedule check
[2023-03-13T20:08:42.562+0000] {taskinstance.py:1083} INFO - Dependencies all met for <TaskInstance: AUTOMATISATION.Chargement_des_données_in_ELK scheduled__2023-03-13T00:00:39+00:00 [queued]>
[2023-03-13T20:08:42.575+0000] {taskinstance.py:1083} INFO - Dependencies all met for <TaskInstance: AUTOMATISATION.Chargement_des_données_in_ELK scheduled__2023-03-13T00:00:39+00:00 [queued]>
[2023-03-13T20:08:42.575+0000] {taskinstance.py:1279} INFO - 
--------------------------------------------------------------------------------
[2023-03-13T20:08:42.575+0000] {taskinstance.py:1280} INFO - Starting attempt 2 of 4
[2023-03-13T20:08:42.576+0000] {taskinstance.py:1281} INFO - 
--------------------------------------------------------------------------------
[2023-03-13T20:08:42.598+0000] {taskinstance.py:1300} INFO - Executing <Task(BashOperator): Chargement_des_données_in_ELK> on 2023-03-13 00:00:39+00:00
[2023-03-13T20:08:42.602+0000] {standard_task_runner.py:55} INFO - Started process 41829 to run task
[2023-03-13T20:08:42.606+0000] {standard_task_runner.py:82} INFO - Running: ['airflow', 'tasks', 'run', 'AUTOMATISATION', 'Chargement_des_données_in_ELK', 'scheduled__2023-03-13T00:00:39+00:00', '--job-id', '209', '--raw', '--subdir', 'DAGS_FOLDER/main.py', '--cfg-path', '/tmp/tmpmssqg0ic']
[2023-03-13T20:08:42.608+0000] {standard_task_runner.py:83} INFO - Job 209: Subtask Chargement_des_données_in_ELK
[2023-03-13T20:08:42.674+0000] {task_command.py:388} INFO - Running <TaskInstance: AUTOMATISATION.Chargement_des_données_in_ELK scheduled__2023-03-13T00:00:39+00:00 [running]> on host dev
[2023-03-13T20:08:42.742+0000] {taskinstance.py:1507} INFO - Exporting the following env vars:
AIRFLOW_CTX_DAG_OWNER=airflow
AIRFLOW_CTX_DAG_ID=AUTOMATISATION
AIRFLOW_CTX_TASK_ID=Chargement_des_données_in_ELK
AIRFLOW_CTX_EXECUTION_DATE=2023-03-13T00:00:39+00:00
AIRFLOW_CTX_TRY_NUMBER=2
AIRFLOW_CTX_DAG_RUN_ID=scheduled__2023-03-13T00:00:39+00:00
[2023-03-13T20:08:42.744+0000] {subprocess.py:63} INFO - Tmp dir root location: 
 /tmp
[2023-03-13T20:08:42.745+0000] {subprocess.py:75} INFO - Running command: ['/usr/bin/bash', '-c', 'bin/logstash -f /home/dev/etc/logstash/conf.d/data.conf']
[2023-03-13T20:08:42.754+0000] {subprocess.py:86} INFO - Output:
[2023-03-13T20:08:42.755+0000] {subprocess.py:93} INFO - /usr/bin/bash: ligne 1: bin/logstash: Aucun fichier ou dossier de ce type
[2023-03-13T20:08:42.756+0000] {subprocess.py:97} INFO - Command exited with return code 127
[2023-03-13T20:08:42.765+0000] {taskinstance.py:1768} ERROR - Task failed with exception
Traceback (most recent call last):
  File "/home/dev/airflow/airflow/lib/python3.10/site-packages/airflow/operators/bash.py", line 196, in execute
    raise AirflowException(
airflow.exceptions.AirflowException: Bash command failed. The command returned a non-zero exit code 127.
[2023-03-13T20:08:42.770+0000] {taskinstance.py:1318} INFO - Marking task as UP_FOR_RETRY. dag_id=AUTOMATISATION, task_id=Chargement_des_données_in_ELK, execution_date=20230313T000039, start_date=20230313T200842, end_date=20230313T200842
[2023-03-13T20:08:42.788+0000] {standard_task_runner.py:100} ERROR - Failed to execute job 209 for task Chargement_des_données_in_ELK (Bash command failed. The command returned a non-zero exit code 127.; 41829)
[2023-03-13T20:08:42.818+0000] {local_task_job.py:208} INFO - Task exited with return code 1
[2023-03-13T20:08:42.840+0000] {taskinstance.py:2578} INFO - 0 downstream tasks scheduled from follow-on schedule check
