[2023-03-13T19:57:23.723+0000] {taskinstance.py:1083} INFO - Dependencies all met for <TaskInstance: AUTOMATISATION.Chargement_des_données_in_ELK scheduled__2023-03-13T00:00:39+00:00 [queued]>
[2023-03-13T19:57:23.735+0000] {taskinstance.py:1083} INFO - Dependencies all met for <TaskInstance: AUTOMATISATION.Chargement_des_données_in_ELK scheduled__2023-03-13T00:00:39+00:00 [queued]>
[2023-03-13T19:57:23.735+0000] {taskinstance.py:1279} INFO - 
--------------------------------------------------------------------------------
[2023-03-13T19:57:23.735+0000] {taskinstance.py:1280} INFO - Starting attempt 4 of 4
[2023-03-13T19:57:23.735+0000] {taskinstance.py:1281} INFO - 
--------------------------------------------------------------------------------
[2023-03-13T19:57:23.757+0000] {taskinstance.py:1300} INFO - Executing <Task(BashOperator): Chargement_des_données_in_ELK> on 2023-03-13 00:00:39+00:00
[2023-03-13T19:57:23.761+0000] {standard_task_runner.py:55} INFO - Started process 39523 to run task
[2023-03-13T19:57:23.765+0000] {standard_task_runner.py:82} INFO - Running: ['airflow', 'tasks', 'run', 'AUTOMATISATION', 'Chargement_des_données_in_ELK', 'scheduled__2023-03-13T00:00:39+00:00', '--job-id', '139', '--raw', '--subdir', 'DAGS_FOLDER/main.py', '--cfg-path', '/tmp/tmpxgff8hag']
[2023-03-13T19:57:23.767+0000] {standard_task_runner.py:83} INFO - Job 139: Subtask Chargement_des_données_in_ELK
[2023-03-13T19:57:23.835+0000] {task_command.py:388} INFO - Running <TaskInstance: AUTOMATISATION.Chargement_des_données_in_ELK scheduled__2023-03-13T00:00:39+00:00 [running]> on host dev
[2023-03-13T19:57:23.905+0000] {taskinstance.py:1507} INFO - Exporting the following env vars:
AIRFLOW_CTX_DAG_OWNER=airflow
AIRFLOW_CTX_DAG_ID=AUTOMATISATION
AIRFLOW_CTX_TASK_ID=Chargement_des_données_in_ELK
AIRFLOW_CTX_EXECUTION_DATE=2023-03-13T00:00:39+00:00
AIRFLOW_CTX_TRY_NUMBER=4
AIRFLOW_CTX_DAG_RUN_ID=scheduled__2023-03-13T00:00:39+00:00
[2023-03-13T19:57:23.908+0000] {subprocess.py:63} INFO - Tmp dir root location: 
 /tmp
[2023-03-13T19:57:23.909+0000] {subprocess.py:75} INFO - Running command: ['/usr/bin/bash', '-c', 'bin/logstash --path.config /etc/logstash/conf.d/data.conf']
[2023-03-13T19:57:23.918+0000] {subprocess.py:86} INFO - Output:
[2023-03-13T19:57:23.919+0000] {subprocess.py:93} INFO - /usr/bin/bash: ligne 1: bin/logstash: Aucun fichier ou dossier de ce type
[2023-03-13T19:57:23.920+0000] {subprocess.py:97} INFO - Command exited with return code 127
[2023-03-13T19:57:23.930+0000] {taskinstance.py:1768} ERROR - Task failed with exception
Traceback (most recent call last):
  File "/home/dev/airflow/airflow/lib/python3.10/site-packages/airflow/operators/bash.py", line 196, in execute
    raise AirflowException(
airflow.exceptions.AirflowException: Bash command failed. The command returned a non-zero exit code 127.
[2023-03-13T19:57:23.934+0000] {taskinstance.py:1318} INFO - Marking task as FAILED. dag_id=AUTOMATISATION, task_id=Chargement_des_données_in_ELK, execution_date=20230313T000039, start_date=20230313T195723, end_date=20230313T195723
[2023-03-13T19:57:23.954+0000] {standard_task_runner.py:100} ERROR - Failed to execute job 139 for task Chargement_des_données_in_ELK (Bash command failed. The command returned a non-zero exit code 127.; 39523)
[2023-03-13T19:57:23.976+0000] {local_task_job.py:208} INFO - Task exited with return code 1
[2023-03-13T19:57:23.998+0000] {taskinstance.py:2578} INFO - 0 downstream tasks scheduled from follow-on schedule check
[2023-03-13T20:18:52.980+0000] {taskinstance.py:1083} INFO - Dependencies all met for <TaskInstance: AUTOMATISATION.Chargement_des_données_in_ELK scheduled__2023-03-13T00:00:39+00:00 [queued]>
[2023-03-13T20:18:52.993+0000] {taskinstance.py:1083} INFO - Dependencies all met for <TaskInstance: AUTOMATISATION.Chargement_des_données_in_ELK scheduled__2023-03-13T00:00:39+00:00 [queued]>
[2023-03-13T20:18:52.993+0000] {taskinstance.py:1279} INFO - 
--------------------------------------------------------------------------------
[2023-03-13T20:18:52.993+0000] {taskinstance.py:1280} INFO - Starting attempt 4 of 4
[2023-03-13T20:18:52.993+0000] {taskinstance.py:1281} INFO - 
--------------------------------------------------------------------------------
[2023-03-13T20:18:53.014+0000] {taskinstance.py:1300} INFO - Executing <Task(BashOperator): Chargement_des_données_in_ELK> on 2023-03-13 00:00:39+00:00
[2023-03-13T20:18:53.018+0000] {standard_task_runner.py:55} INFO - Started process 43372 to run task
[2023-03-13T20:18:53.022+0000] {standard_task_runner.py:82} INFO - Running: ['airflow', 'tasks', 'run', 'AUTOMATISATION', 'Chargement_des_données_in_ELK', 'scheduled__2023-03-13T00:00:39+00:00', '--job-id', '255', '--raw', '--subdir', 'DAGS_FOLDER/main.py', '--cfg-path', '/tmp/tmpokpr20ff']
[2023-03-13T20:18:53.024+0000] {standard_task_runner.py:83} INFO - Job 255: Subtask Chargement_des_données_in_ELK
[2023-03-13T20:18:53.091+0000] {task_command.py:388} INFO - Running <TaskInstance: AUTOMATISATION.Chargement_des_données_in_ELK scheduled__2023-03-13T00:00:39+00:00 [running]> on host dev
[2023-03-13T20:18:53.159+0000] {taskinstance.py:1507} INFO - Exporting the following env vars:
AIRFLOW_CTX_DAG_OWNER=airflow
AIRFLOW_CTX_DAG_ID=AUTOMATISATION
AIRFLOW_CTX_TASK_ID=Chargement_des_données_in_ELK
AIRFLOW_CTX_EXECUTION_DATE=2023-03-13T00:00:39+00:00
AIRFLOW_CTX_TRY_NUMBER=4
AIRFLOW_CTX_DAG_RUN_ID=scheduled__2023-03-13T00:00:39+00:00
[2023-03-13T20:18:53.160+0000] {subprocess.py:63} INFO - Tmp dir root location: 
 /tmp
[2023-03-13T20:18:53.161+0000] {subprocess.py:75} INFO - Running command: ['/usr/bin/bash', '-c', 'bin/logstash -f /home/dev/etc/logstash/conf.d/data.conf']
[2023-03-13T20:18:53.171+0000] {subprocess.py:86} INFO - Output:
[2023-03-13T20:18:53.173+0000] {subprocess.py:93} INFO - /usr/bin/bash: ligne 1: bin/logstash: Aucun fichier ou dossier de ce type
[2023-03-13T20:18:53.173+0000] {subprocess.py:97} INFO - Command exited with return code 127
[2023-03-13T20:18:53.183+0000] {taskinstance.py:1768} ERROR - Task failed with exception
Traceback (most recent call last):
  File "/home/dev/airflow/airflow/lib/python3.10/site-packages/airflow/operators/bash.py", line 196, in execute
    raise AirflowException(
airflow.exceptions.AirflowException: Bash command failed. The command returned a non-zero exit code 127.
[2023-03-13T20:18:53.188+0000] {taskinstance.py:1318} INFO - Marking task as FAILED. dag_id=AUTOMATISATION, task_id=Chargement_des_données_in_ELK, execution_date=20230313T000039, start_date=20230313T201852, end_date=20230313T201853
[2023-03-13T20:18:53.206+0000] {standard_task_runner.py:100} ERROR - Failed to execute job 255 for task Chargement_des_données_in_ELK (Bash command failed. The command returned a non-zero exit code 127.; 43372)
[2023-03-13T20:18:53.233+0000] {local_task_job.py:208} INFO - Task exited with return code 1
[2023-03-13T20:18:53.253+0000] {taskinstance.py:2578} INFO - 0 downstream tasks scheduled from follow-on schedule check
