[2023-03-13T19:56:41.852+0000] {taskinstance.py:1083} INFO - Dependencies all met for <TaskInstance: AUTOMATISATION.Chargement_des_données_in_ELK scheduled__2023-03-13T00:00:24+00:00 [queued]>
[2023-03-13T19:56:41.867+0000] {taskinstance.py:1083} INFO - Dependencies all met for <TaskInstance: AUTOMATISATION.Chargement_des_données_in_ELK scheduled__2023-03-13T00:00:24+00:00 [queued]>
[2023-03-13T19:56:41.867+0000] {taskinstance.py:1279} INFO - 
--------------------------------------------------------------------------------
[2023-03-13T19:56:41.868+0000] {taskinstance.py:1280} INFO - Starting attempt 4 of 4
[2023-03-13T19:56:41.868+0000] {taskinstance.py:1281} INFO - 
--------------------------------------------------------------------------------
[2023-03-13T19:56:41.892+0000] {taskinstance.py:1300} INFO - Executing <Task(BashOperator): Chargement_des_données_in_ELK> on 2023-03-13 00:00:24+00:00
[2023-03-13T19:56:41.896+0000] {standard_task_runner.py:55} INFO - Started process 39372 to run task
[2023-03-13T19:56:41.900+0000] {standard_task_runner.py:82} INFO - Running: ['airflow', 'tasks', 'run', 'AUTOMATISATION', 'Chargement_des_données_in_ELK', 'scheduled__2023-03-13T00:00:24+00:00', '--job-id', '130', '--raw', '--subdir', 'DAGS_FOLDER/main.py', '--cfg-path', '/tmp/tmpms_fipt2']
[2023-03-13T19:56:41.902+0000] {standard_task_runner.py:83} INFO - Job 130: Subtask Chargement_des_données_in_ELK
[2023-03-13T19:56:41.971+0000] {task_command.py:388} INFO - Running <TaskInstance: AUTOMATISATION.Chargement_des_données_in_ELK scheduled__2023-03-13T00:00:24+00:00 [running]> on host dev
[2023-03-13T19:56:42.035+0000] {taskinstance.py:1507} INFO - Exporting the following env vars:
AIRFLOW_CTX_DAG_OWNER=airflow
AIRFLOW_CTX_DAG_ID=AUTOMATISATION
AIRFLOW_CTX_TASK_ID=Chargement_des_données_in_ELK
AIRFLOW_CTX_EXECUTION_DATE=2023-03-13T00:00:24+00:00
AIRFLOW_CTX_TRY_NUMBER=4
AIRFLOW_CTX_DAG_RUN_ID=scheduled__2023-03-13T00:00:24+00:00
[2023-03-13T19:56:42.037+0000] {subprocess.py:63} INFO - Tmp dir root location: 
 /tmp
[2023-03-13T19:56:42.038+0000] {subprocess.py:75} INFO - Running command: ['/usr/bin/bash', '-c', 'bin/logstash --path.config /etc/logstash/conf.d/data.conf']
[2023-03-13T19:56:42.047+0000] {subprocess.py:86} INFO - Output:
[2023-03-13T19:56:42.049+0000] {subprocess.py:93} INFO - /usr/bin/bash: ligne 1: bin/logstash: Aucun fichier ou dossier de ce type
[2023-03-13T19:56:42.049+0000] {subprocess.py:97} INFO - Command exited with return code 127
[2023-03-13T19:56:42.060+0000] {taskinstance.py:1768} ERROR - Task failed with exception
Traceback (most recent call last):
  File "/home/dev/airflow/airflow/lib/python3.10/site-packages/airflow/operators/bash.py", line 196, in execute
    raise AirflowException(
airflow.exceptions.AirflowException: Bash command failed. The command returned a non-zero exit code 127.
[2023-03-13T19:56:42.064+0000] {taskinstance.py:1318} INFO - Marking task as FAILED. dag_id=AUTOMATISATION, task_id=Chargement_des_données_in_ELK, execution_date=20230313T000024, start_date=20230313T195641, end_date=20230313T195642
[2023-03-13T19:56:42.083+0000] {standard_task_runner.py:100} ERROR - Failed to execute job 130 for task Chargement_des_données_in_ELK (Bash command failed. The command returned a non-zero exit code 127.; 39372)
[2023-03-13T19:56:42.111+0000] {local_task_job.py:208} INFO - Task exited with return code 1
[2023-03-13T19:56:42.132+0000] {taskinstance.py:2578} INFO - 0 downstream tasks scheduled from follow-on schedule check
[2023-03-13T20:18:14.612+0000] {taskinstance.py:1083} INFO - Dependencies all met for <TaskInstance: AUTOMATISATION.Chargement_des_données_in_ELK scheduled__2023-03-13T00:00:24+00:00 [queued]>
[2023-03-13T20:18:14.626+0000] {taskinstance.py:1083} INFO - Dependencies all met for <TaskInstance: AUTOMATISATION.Chargement_des_données_in_ELK scheduled__2023-03-13T00:00:24+00:00 [queued]>
[2023-03-13T20:18:14.627+0000] {taskinstance.py:1279} INFO - 
--------------------------------------------------------------------------------
[2023-03-13T20:18:14.627+0000] {taskinstance.py:1280} INFO - Starting attempt 4 of 4
[2023-03-13T20:18:14.627+0000] {taskinstance.py:1281} INFO - 
--------------------------------------------------------------------------------
[2023-03-13T20:18:14.648+0000] {taskinstance.py:1300} INFO - Executing <Task(BashOperator): Chargement_des_données_in_ELK> on 2023-03-13 00:00:24+00:00
[2023-03-13T20:18:14.651+0000] {standard_task_runner.py:55} INFO - Started process 43251 to run task
[2023-03-13T20:18:14.656+0000] {standard_task_runner.py:82} INFO - Running: ['airflow', 'tasks', 'run', 'AUTOMATISATION', 'Chargement_des_données_in_ELK', 'scheduled__2023-03-13T00:00:24+00:00', '--job-id', '244', '--raw', '--subdir', 'DAGS_FOLDER/main.py', '--cfg-path', '/tmp/tmpy0v1_wwe']
[2023-03-13T20:18:14.658+0000] {standard_task_runner.py:83} INFO - Job 244: Subtask Chargement_des_données_in_ELK
[2023-03-13T20:18:14.724+0000] {task_command.py:388} INFO - Running <TaskInstance: AUTOMATISATION.Chargement_des_données_in_ELK scheduled__2023-03-13T00:00:24+00:00 [running]> on host dev
[2023-03-13T20:18:14.791+0000] {taskinstance.py:1507} INFO - Exporting the following env vars:
AIRFLOW_CTX_DAG_OWNER=airflow
AIRFLOW_CTX_DAG_ID=AUTOMATISATION
AIRFLOW_CTX_TASK_ID=Chargement_des_données_in_ELK
AIRFLOW_CTX_EXECUTION_DATE=2023-03-13T00:00:24+00:00
AIRFLOW_CTX_TRY_NUMBER=4
AIRFLOW_CTX_DAG_RUN_ID=scheduled__2023-03-13T00:00:24+00:00
[2023-03-13T20:18:14.793+0000] {subprocess.py:63} INFO - Tmp dir root location: 
 /tmp
[2023-03-13T20:18:14.794+0000] {subprocess.py:75} INFO - Running command: ['/usr/bin/bash', '-c', 'bin/logstash -f /home/dev/etc/logstash/conf.d/data.conf']
[2023-03-13T20:18:14.802+0000] {subprocess.py:86} INFO - Output:
[2023-03-13T20:18:14.804+0000] {subprocess.py:93} INFO - /usr/bin/bash: ligne 1: bin/logstash: Aucun fichier ou dossier de ce type
[2023-03-13T20:18:14.804+0000] {subprocess.py:97} INFO - Command exited with return code 127
[2023-03-13T20:18:14.815+0000] {taskinstance.py:1768} ERROR - Task failed with exception
Traceback (most recent call last):
  File "/home/dev/airflow/airflow/lib/python3.10/site-packages/airflow/operators/bash.py", line 196, in execute
    raise AirflowException(
airflow.exceptions.AirflowException: Bash command failed. The command returned a non-zero exit code 127.
[2023-03-13T20:18:14.821+0000] {taskinstance.py:1318} INFO - Marking task as FAILED. dag_id=AUTOMATISATION, task_id=Chargement_des_données_in_ELK, execution_date=20230313T000024, start_date=20230313T201814, end_date=20230313T201814
[2023-03-13T20:18:14.841+0000] {standard_task_runner.py:100} ERROR - Failed to execute job 244 for task Chargement_des_données_in_ELK (Bash command failed. The command returned a non-zero exit code 127.; 43251)
[2023-03-13T20:18:14.867+0000] {local_task_job.py:208} INFO - Task exited with return code 1
[2023-03-13T20:18:14.887+0000] {taskinstance.py:2578} INFO - 0 downstream tasks scheduled from follow-on schedule check
