[2023-03-13T19:51:37.874+0000] {taskinstance.py:1083} INFO - Dependencies all met for <TaskInstance: AUTOMATISATION.Chargement_des_données_in_ELK scheduled__2023-03-13T00:00:24+00:00 [queued]>
[2023-03-13T19:51:37.885+0000] {taskinstance.py:1083} INFO - Dependencies all met for <TaskInstance: AUTOMATISATION.Chargement_des_données_in_ELK scheduled__2023-03-13T00:00:24+00:00 [queued]>
[2023-03-13T19:51:37.885+0000] {taskinstance.py:1279} INFO - 
--------------------------------------------------------------------------------
[2023-03-13T19:51:37.886+0000] {taskinstance.py:1280} INFO - Starting attempt 3 of 4
[2023-03-13T19:51:37.886+0000] {taskinstance.py:1281} INFO - 
--------------------------------------------------------------------------------
[2023-03-13T19:51:37.906+0000] {taskinstance.py:1300} INFO - Executing <Task(BashOperator): Chargement_des_données_in_ELK> on 2023-03-13 00:00:24+00:00
[2023-03-13T19:51:37.909+0000] {standard_task_runner.py:55} INFO - Started process 38626 to run task
[2023-03-13T19:51:37.913+0000] {standard_task_runner.py:82} INFO - Running: ['airflow', 'tasks', 'run', 'AUTOMATISATION', 'Chargement_des_données_in_ELK', 'scheduled__2023-03-13T00:00:24+00:00', '--job-id', '108', '--raw', '--subdir', 'DAGS_FOLDER/main.py', '--cfg-path', '/tmp/tmpa8hkd1o9']
[2023-03-13T19:51:37.915+0000] {standard_task_runner.py:83} INFO - Job 108: Subtask Chargement_des_données_in_ELK
[2023-03-13T19:51:37.980+0000] {task_command.py:388} INFO - Running <TaskInstance: AUTOMATISATION.Chargement_des_données_in_ELK scheduled__2023-03-13T00:00:24+00:00 [running]> on host dev
[2023-03-13T19:51:38.039+0000] {taskinstance.py:1507} INFO - Exporting the following env vars:
AIRFLOW_CTX_DAG_OWNER=airflow
AIRFLOW_CTX_DAG_ID=AUTOMATISATION
AIRFLOW_CTX_TASK_ID=Chargement_des_données_in_ELK
AIRFLOW_CTX_EXECUTION_DATE=2023-03-13T00:00:24+00:00
AIRFLOW_CTX_TRY_NUMBER=3
AIRFLOW_CTX_DAG_RUN_ID=scheduled__2023-03-13T00:00:24+00:00
[2023-03-13T19:51:38.040+0000] {subprocess.py:63} INFO - Tmp dir root location: 
 /tmp
[2023-03-13T19:51:38.041+0000] {subprocess.py:75} INFO - Running command: ['/usr/bin/bash', '-c', 'bin/logstash --path.config /etc/logstash/conf.d/data.conf']
[2023-03-13T19:51:38.049+0000] {subprocess.py:86} INFO - Output:
[2023-03-13T19:51:38.051+0000] {subprocess.py:93} INFO - /usr/bin/bash: ligne 1: bin/logstash: Aucun fichier ou dossier de ce type
[2023-03-13T19:51:38.051+0000] {subprocess.py:97} INFO - Command exited with return code 127
[2023-03-13T19:51:38.061+0000] {taskinstance.py:1768} ERROR - Task failed with exception
Traceback (most recent call last):
  File "/home/dev/airflow/airflow/lib/python3.10/site-packages/airflow/operators/bash.py", line 196, in execute
    raise AirflowException(
airflow.exceptions.AirflowException: Bash command failed. The command returned a non-zero exit code 127.
[2023-03-13T19:51:38.065+0000] {taskinstance.py:1318} INFO - Marking task as UP_FOR_RETRY. dag_id=AUTOMATISATION, task_id=Chargement_des_données_in_ELK, execution_date=20230313T000024, start_date=20230313T195137, end_date=20230313T195138
[2023-03-13T19:51:38.083+0000] {standard_task_runner.py:100} ERROR - Failed to execute job 108 for task Chargement_des_données_in_ELK (Bash command failed. The command returned a non-zero exit code 127.; 38626)
[2023-03-13T19:51:38.124+0000] {local_task_job.py:208} INFO - Task exited with return code 1
[2023-03-13T19:51:38.144+0000] {taskinstance.py:2578} INFO - 0 downstream tasks scheduled from follow-on schedule check
[2023-03-13T20:13:05.759+0000] {taskinstance.py:1083} INFO - Dependencies all met for <TaskInstance: AUTOMATISATION.Chargement_des_données_in_ELK scheduled__2023-03-13T00:00:24+00:00 [queued]>
[2023-03-13T20:13:05.772+0000] {taskinstance.py:1083} INFO - Dependencies all met for <TaskInstance: AUTOMATISATION.Chargement_des_données_in_ELK scheduled__2023-03-13T00:00:24+00:00 [queued]>
[2023-03-13T20:13:05.772+0000] {taskinstance.py:1279} INFO - 
--------------------------------------------------------------------------------
[2023-03-13T20:13:05.773+0000] {taskinstance.py:1280} INFO - Starting attempt 3 of 4
[2023-03-13T20:13:05.773+0000] {taskinstance.py:1281} INFO - 
--------------------------------------------------------------------------------
[2023-03-13T20:13:05.861+0000] {taskinstance.py:1300} INFO - Executing <Task(BashOperator): Chargement_des_données_in_ELK> on 2023-03-13 00:00:24+00:00
[2023-03-13T20:13:05.864+0000] {standard_task_runner.py:55} INFO - Started process 42503 to run task
[2023-03-13T20:13:05.869+0000] {standard_task_runner.py:82} INFO - Running: ['airflow', 'tasks', 'run', 'AUTOMATISATION', 'Chargement_des_données_in_ELK', 'scheduled__2023-03-13T00:00:24+00:00', '--job-id', '220', '--raw', '--subdir', 'DAGS_FOLDER/main.py', '--cfg-path', '/tmp/tmpjlq8tc6a']
[2023-03-13T20:13:05.871+0000] {standard_task_runner.py:83} INFO - Job 220: Subtask Chargement_des_données_in_ELK
[2023-03-13T20:13:06.017+0000] {task_command.py:388} INFO - Running <TaskInstance: AUTOMATISATION.Chargement_des_données_in_ELK scheduled__2023-03-13T00:00:24+00:00 [running]> on host dev
[2023-03-13T20:13:06.185+0000] {taskinstance.py:1507} INFO - Exporting the following env vars:
AIRFLOW_CTX_DAG_OWNER=airflow
AIRFLOW_CTX_DAG_ID=AUTOMATISATION
AIRFLOW_CTX_TASK_ID=Chargement_des_données_in_ELK
AIRFLOW_CTX_EXECUTION_DATE=2023-03-13T00:00:24+00:00
AIRFLOW_CTX_TRY_NUMBER=3
AIRFLOW_CTX_DAG_RUN_ID=scheduled__2023-03-13T00:00:24+00:00
[2023-03-13T20:13:06.186+0000] {subprocess.py:63} INFO - Tmp dir root location: 
 /tmp
[2023-03-13T20:13:06.187+0000] {subprocess.py:75} INFO - Running command: ['/usr/bin/bash', '-c', 'bin/logstash -f /home/dev/etc/logstash/conf.d/data.conf']
[2023-03-13T20:13:06.195+0000] {subprocess.py:86} INFO - Output:
[2023-03-13T20:13:06.197+0000] {subprocess.py:93} INFO - /usr/bin/bash: ligne 1: bin/logstash: Aucun fichier ou dossier de ce type
[2023-03-13T20:13:06.197+0000] {subprocess.py:97} INFO - Command exited with return code 127
[2023-03-13T20:13:06.215+0000] {taskinstance.py:1768} ERROR - Task failed with exception
Traceback (most recent call last):
  File "/home/dev/airflow/airflow/lib/python3.10/site-packages/airflow/operators/bash.py", line 196, in execute
    raise AirflowException(
airflow.exceptions.AirflowException: Bash command failed. The command returned a non-zero exit code 127.
[2023-03-13T20:13:06.220+0000] {taskinstance.py:1318} INFO - Marking task as UP_FOR_RETRY. dag_id=AUTOMATISATION, task_id=Chargement_des_données_in_ELK, execution_date=20230313T000024, start_date=20230313T201305, end_date=20230313T201306
[2023-03-13T20:13:06.901+0000] {standard_task_runner.py:100} ERROR - Failed to execute job 220 for task Chargement_des_données_in_ELK (Bash command failed. The command returned a non-zero exit code 127.; 42503)
[2023-03-13T20:13:06.923+0000] {local_task_job.py:208} INFO - Task exited with return code 1
[2023-03-13T20:13:06.943+0000] {taskinstance.py:2578} INFO - 0 downstream tasks scheduled from follow-on schedule check
