[2023-03-13T19:35:24.381+0000] {taskinstance.py:1083} INFO - Dependencies all met for <TaskInstance: AUTOMATISATION.Chargement_des_données_in_ELK scheduled__2023-03-13T00:00:09+00:00 [queued]>
[2023-03-13T19:35:24.394+0000] {taskinstance.py:1083} INFO - Dependencies all met for <TaskInstance: AUTOMATISATION.Chargement_des_données_in_ELK scheduled__2023-03-13T00:00:09+00:00 [queued]>
[2023-03-13T19:35:24.394+0000] {taskinstance.py:1279} INFO - 
--------------------------------------------------------------------------------
[2023-03-13T19:35:24.394+0000] {taskinstance.py:1280} INFO - Starting attempt 2 of 4
[2023-03-13T19:35:24.395+0000] {taskinstance.py:1281} INFO - 
--------------------------------------------------------------------------------
[2023-03-13T19:35:24.416+0000] {taskinstance.py:1300} INFO - Executing <Task(BashOperator): Chargement_des_données_in_ELK> on 2023-03-13 00:00:09+00:00
[2023-03-13T19:35:24.419+0000] {standard_task_runner.py:55} INFO - Started process 35872 to run task
[2023-03-13T19:35:24.424+0000] {standard_task_runner.py:82} INFO - Running: ['airflow', 'tasks', 'run', 'AUTOMATISATION', 'Chargement_des_données_in_ELK', 'scheduled__2023-03-13T00:00:09+00:00', '--job-id', '39', '--raw', '--subdir', 'DAGS_FOLDER/main.py', '--cfg-path', '/tmp/tmpfa7qgjol']
[2023-03-13T19:35:24.426+0000] {standard_task_runner.py:83} INFO - Job 39: Subtask Chargement_des_données_in_ELK
[2023-03-13T19:35:24.492+0000] {task_command.py:388} INFO - Running <TaskInstance: AUTOMATISATION.Chargement_des_données_in_ELK scheduled__2023-03-13T00:00:09+00:00 [running]> on host dev
[2023-03-13T19:35:24.559+0000] {taskinstance.py:1507} INFO - Exporting the following env vars:
AIRFLOW_CTX_DAG_OWNER=airflow
AIRFLOW_CTX_DAG_ID=AUTOMATISATION
AIRFLOW_CTX_TASK_ID=Chargement_des_données_in_ELK
AIRFLOW_CTX_EXECUTION_DATE=2023-03-13T00:00:09+00:00
AIRFLOW_CTX_TRY_NUMBER=2
AIRFLOW_CTX_DAG_RUN_ID=scheduled__2023-03-13T00:00:09+00:00
[2023-03-13T19:35:24.561+0000] {subprocess.py:63} INFO - Tmp dir root location: 
 /tmp
[2023-03-13T19:35:24.561+0000] {subprocess.py:75} INFO - Running command: ['/usr/bin/bash', '-c', '/usr/bin/logstash --path.config /etc/logstash/conf.d/data.conf']
[2023-03-13T19:35:24.569+0000] {subprocess.py:86} INFO - Output:
[2023-03-13T19:35:24.571+0000] {subprocess.py:93} INFO - /usr/bin/bash: ligne 1: /usr/bin/logstash: Aucun fichier ou dossier de ce type
[2023-03-13T19:35:24.571+0000] {subprocess.py:97} INFO - Command exited with return code 127
[2023-03-13T19:35:24.582+0000] {taskinstance.py:1768} ERROR - Task failed with exception
Traceback (most recent call last):
  File "/home/dev/airflow/airflow/lib/python3.10/site-packages/airflow/operators/bash.py", line 196, in execute
    raise AirflowException(
airflow.exceptions.AirflowException: Bash command failed. The command returned a non-zero exit code 127.
[2023-03-13T19:35:24.586+0000] {taskinstance.py:1318} INFO - Marking task as UP_FOR_RETRY. dag_id=AUTOMATISATION, task_id=Chargement_des_données_in_ELK, execution_date=20230313T000009, start_date=20230313T193524, end_date=20230313T193524
[2023-03-13T19:35:24.608+0000] {standard_task_runner.py:100} ERROR - Failed to execute job 39 for task Chargement_des_données_in_ELK (Bash command failed. The command returned a non-zero exit code 127.; 35872)
[2023-03-13T19:35:24.635+0000] {local_task_job.py:208} INFO - Task exited with return code 1
[2023-03-13T19:35:24.655+0000] {taskinstance.py:2578} INFO - 0 downstream tasks scheduled from follow-on schedule check
[2023-03-13T19:45:56.565+0000] {taskinstance.py:1083} INFO - Dependencies all met for <TaskInstance: AUTOMATISATION.Chargement_des_données_in_ELK scheduled__2023-03-13T00:00:09+00:00 [queued]>
[2023-03-13T19:45:56.578+0000] {taskinstance.py:1083} INFO - Dependencies all met for <TaskInstance: AUTOMATISATION.Chargement_des_données_in_ELK scheduled__2023-03-13T00:00:09+00:00 [queued]>
[2023-03-13T19:45:56.578+0000] {taskinstance.py:1279} INFO - 
--------------------------------------------------------------------------------
[2023-03-13T19:45:56.578+0000] {taskinstance.py:1280} INFO - Starting attempt 2 of 4
[2023-03-13T19:45:56.578+0000] {taskinstance.py:1281} INFO - 
--------------------------------------------------------------------------------
[2023-03-13T19:45:56.600+0000] {taskinstance.py:1300} INFO - Executing <Task(BashOperator): Chargement_des_données_in_ELK> on 2023-03-13 00:00:09+00:00
[2023-03-13T19:45:56.604+0000] {standard_task_runner.py:55} INFO - Started process 37750 to run task
[2023-03-13T19:45:56.608+0000] {standard_task_runner.py:82} INFO - Running: ['airflow', 'tasks', 'run', 'AUTOMATISATION', 'Chargement_des_données_in_ELK', 'scheduled__2023-03-13T00:00:09+00:00', '--job-id', '87', '--raw', '--subdir', 'DAGS_FOLDER/main.py', '--cfg-path', '/tmp/tmpxxotl1o1']
[2023-03-13T19:45:56.610+0000] {standard_task_runner.py:83} INFO - Job 87: Subtask Chargement_des_données_in_ELK
[2023-03-13T19:45:56.678+0000] {task_command.py:388} INFO - Running <TaskInstance: AUTOMATISATION.Chargement_des_données_in_ELK scheduled__2023-03-13T00:00:09+00:00 [running]> on host dev
[2023-03-13T19:45:56.745+0000] {taskinstance.py:1507} INFO - Exporting the following env vars:
AIRFLOW_CTX_DAG_OWNER=airflow
AIRFLOW_CTX_DAG_ID=AUTOMATISATION
AIRFLOW_CTX_TASK_ID=Chargement_des_données_in_ELK
AIRFLOW_CTX_EXECUTION_DATE=2023-03-13T00:00:09+00:00
AIRFLOW_CTX_TRY_NUMBER=2
AIRFLOW_CTX_DAG_RUN_ID=scheduled__2023-03-13T00:00:09+00:00
[2023-03-13T19:45:56.747+0000] {subprocess.py:63} INFO - Tmp dir root location: 
 /tmp
[2023-03-13T19:45:56.748+0000] {subprocess.py:75} INFO - Running command: ['/usr/bin/bash', '-c', 'bin/logstash --path.config /etc/logstash/conf.d/data.conf']
[2023-03-13T19:45:56.756+0000] {subprocess.py:86} INFO - Output:
[2023-03-13T19:45:56.758+0000] {subprocess.py:93} INFO - /usr/bin/bash: ligne 1: bin/logstash: Aucun fichier ou dossier de ce type
[2023-03-13T19:45:56.758+0000] {subprocess.py:97} INFO - Command exited with return code 127
[2023-03-13T19:45:56.768+0000] {taskinstance.py:1768} ERROR - Task failed with exception
Traceback (most recent call last):
  File "/home/dev/airflow/airflow/lib/python3.10/site-packages/airflow/operators/bash.py", line 196, in execute
    raise AirflowException(
airflow.exceptions.AirflowException: Bash command failed. The command returned a non-zero exit code 127.
[2023-03-13T19:45:56.773+0000] {taskinstance.py:1318} INFO - Marking task as UP_FOR_RETRY. dag_id=AUTOMATISATION, task_id=Chargement_des_données_in_ELK, execution_date=20230313T000009, start_date=20230313T194556, end_date=20230313T194556
[2023-03-13T19:45:56.790+0000] {standard_task_runner.py:100} ERROR - Failed to execute job 87 for task Chargement_des_données_in_ELK (Bash command failed. The command returned a non-zero exit code 127.; 37750)
[2023-03-13T19:45:56.819+0000] {local_task_job.py:208} INFO - Task exited with return code 1
[2023-03-13T19:45:56.839+0000] {taskinstance.py:2578} INFO - 0 downstream tasks scheduled from follow-on schedule check
[2023-03-13T20:07:24.402+0000] {taskinstance.py:1083} INFO - Dependencies all met for <TaskInstance: AUTOMATISATION.Chargement_des_données_in_ELK scheduled__2023-03-13T00:00:09+00:00 [queued]>
[2023-03-13T20:07:24.418+0000] {taskinstance.py:1083} INFO - Dependencies all met for <TaskInstance: AUTOMATISATION.Chargement_des_données_in_ELK scheduled__2023-03-13T00:00:09+00:00 [queued]>
[2023-03-13T20:07:24.419+0000] {taskinstance.py:1279} INFO - 
--------------------------------------------------------------------------------
[2023-03-13T20:07:24.419+0000] {taskinstance.py:1280} INFO - Starting attempt 2 of 4
[2023-03-13T20:07:24.419+0000] {taskinstance.py:1281} INFO - 
--------------------------------------------------------------------------------
[2023-03-13T20:07:24.445+0000] {taskinstance.py:1300} INFO - Executing <Task(BashOperator): Chargement_des_données_in_ELK> on 2023-03-13 00:00:09+00:00
[2023-03-13T20:07:24.449+0000] {standard_task_runner.py:55} INFO - Started process 41652 to run task
[2023-03-13T20:07:24.453+0000] {standard_task_runner.py:82} INFO - Running: ['airflow', 'tasks', 'run', 'AUTOMATISATION', 'Chargement_des_données_in_ELK', 'scheduled__2023-03-13T00:00:09+00:00', '--job-id', '199', '--raw', '--subdir', 'DAGS_FOLDER/main.py', '--cfg-path', '/tmp/tmpz99e9y51']
[2023-03-13T20:07:24.456+0000] {standard_task_runner.py:83} INFO - Job 199: Subtask Chargement_des_données_in_ELK
[2023-03-13T20:07:24.548+0000] {task_command.py:388} INFO - Running <TaskInstance: AUTOMATISATION.Chargement_des_données_in_ELK scheduled__2023-03-13T00:00:09+00:00 [running]> on host dev
[2023-03-13T20:07:24.626+0000] {taskinstance.py:1507} INFO - Exporting the following env vars:
AIRFLOW_CTX_DAG_OWNER=airflow
AIRFLOW_CTX_DAG_ID=AUTOMATISATION
AIRFLOW_CTX_TASK_ID=Chargement_des_données_in_ELK
AIRFLOW_CTX_EXECUTION_DATE=2023-03-13T00:00:09+00:00
AIRFLOW_CTX_TRY_NUMBER=2
AIRFLOW_CTX_DAG_RUN_ID=scheduled__2023-03-13T00:00:09+00:00
[2023-03-13T20:07:24.628+0000] {subprocess.py:63} INFO - Tmp dir root location: 
 /tmp
[2023-03-13T20:07:24.629+0000] {subprocess.py:75} INFO - Running command: ['/usr/bin/bash', '-c', 'bin/logstash -f /home/dev/etc/logstash/conf.d/data.conf']
[2023-03-13T20:07:24.641+0000] {subprocess.py:86} INFO - Output:
[2023-03-13T20:07:24.643+0000] {subprocess.py:93} INFO - /usr/bin/bash: ligne 1: bin/logstash: Aucun fichier ou dossier de ce type
[2023-03-13T20:07:24.643+0000] {subprocess.py:97} INFO - Command exited with return code 127
[2023-03-13T20:07:24.655+0000] {taskinstance.py:1768} ERROR - Task failed with exception
Traceback (most recent call last):
  File "/home/dev/airflow/airflow/lib/python3.10/site-packages/airflow/operators/bash.py", line 196, in execute
    raise AirflowException(
airflow.exceptions.AirflowException: Bash command failed. The command returned a non-zero exit code 127.
[2023-03-13T20:07:24.660+0000] {taskinstance.py:1318} INFO - Marking task as UP_FOR_RETRY. dag_id=AUTOMATISATION, task_id=Chargement_des_données_in_ELK, execution_date=20230313T000009, start_date=20230313T200724, end_date=20230313T200724
[2023-03-13T20:07:24.681+0000] {standard_task_runner.py:100} ERROR - Failed to execute job 199 for task Chargement_des_données_in_ELK (Bash command failed. The command returned a non-zero exit code 127.; 41652)
[2023-03-13T20:07:24.705+0000] {local_task_job.py:208} INFO - Task exited with return code 1
[2023-03-13T20:07:24.734+0000] {taskinstance.py:2578} INFO - 0 downstream tasks scheduled from follow-on schedule check
