[2023-03-13T19:50:59.179+0000] {taskinstance.py:1083} INFO - Dependencies all met for <TaskInstance: AUTOMATISATION.Chargement_des_données_in_ELK scheduled__2023-03-13T00:00:09+00:00 [queued]>
[2023-03-13T19:50:59.190+0000] {taskinstance.py:1083} INFO - Dependencies all met for <TaskInstance: AUTOMATISATION.Chargement_des_données_in_ELK scheduled__2023-03-13T00:00:09+00:00 [queued]>
[2023-03-13T19:50:59.190+0000] {taskinstance.py:1279} INFO - 
--------------------------------------------------------------------------------
[2023-03-13T19:50:59.190+0000] {taskinstance.py:1280} INFO - Starting attempt 3 of 4
[2023-03-13T19:50:59.190+0000] {taskinstance.py:1281} INFO - 
--------------------------------------------------------------------------------
[2023-03-13T19:50:59.210+0000] {taskinstance.py:1300} INFO - Executing <Task(BashOperator): Chargement_des_données_in_ELK> on 2023-03-13 00:00:09+00:00
[2023-03-13T19:50:59.213+0000] {standard_task_runner.py:55} INFO - Started process 38498 to run task
[2023-03-13T19:50:59.217+0000] {standard_task_runner.py:82} INFO - Running: ['airflow', 'tasks', 'run', 'AUTOMATISATION', 'Chargement_des_données_in_ELK', 'scheduled__2023-03-13T00:00:09+00:00', '--job-id', '103', '--raw', '--subdir', 'DAGS_FOLDER/main.py', '--cfg-path', '/tmp/tmp8g3rprn9']
[2023-03-13T19:50:59.219+0000] {standard_task_runner.py:83} INFO - Job 103: Subtask Chargement_des_données_in_ELK
[2023-03-13T19:50:59.281+0000] {task_command.py:388} INFO - Running <TaskInstance: AUTOMATISATION.Chargement_des_données_in_ELK scheduled__2023-03-13T00:00:09+00:00 [running]> on host dev
[2023-03-13T19:50:59.345+0000] {taskinstance.py:1507} INFO - Exporting the following env vars:
AIRFLOW_CTX_DAG_OWNER=airflow
AIRFLOW_CTX_DAG_ID=AUTOMATISATION
AIRFLOW_CTX_TASK_ID=Chargement_des_données_in_ELK
AIRFLOW_CTX_EXECUTION_DATE=2023-03-13T00:00:09+00:00
AIRFLOW_CTX_TRY_NUMBER=3
AIRFLOW_CTX_DAG_RUN_ID=scheduled__2023-03-13T00:00:09+00:00
[2023-03-13T19:50:59.347+0000] {subprocess.py:63} INFO - Tmp dir root location: 
 /tmp
[2023-03-13T19:50:59.348+0000] {subprocess.py:75} INFO - Running command: ['/usr/bin/bash', '-c', 'bin/logstash --path.config /etc/logstash/conf.d/data.conf']
[2023-03-13T19:50:59.357+0000] {subprocess.py:86} INFO - Output:
[2023-03-13T19:50:59.359+0000] {subprocess.py:93} INFO - /usr/bin/bash: ligne 1: bin/logstash: Aucun fichier ou dossier de ce type
[2023-03-13T19:50:59.359+0000] {subprocess.py:97} INFO - Command exited with return code 127
[2023-03-13T19:50:59.369+0000] {taskinstance.py:1768} ERROR - Task failed with exception
Traceback (most recent call last):
  File "/home/dev/airflow/airflow/lib/python3.10/site-packages/airflow/operators/bash.py", line 196, in execute
    raise AirflowException(
airflow.exceptions.AirflowException: Bash command failed. The command returned a non-zero exit code 127.
[2023-03-13T19:50:59.374+0000] {taskinstance.py:1318} INFO - Marking task as UP_FOR_RETRY. dag_id=AUTOMATISATION, task_id=Chargement_des_données_in_ELK, execution_date=20230313T000009, start_date=20230313T195059, end_date=20230313T195059
[2023-03-13T19:50:59.390+0000] {standard_task_runner.py:100} ERROR - Failed to execute job 103 for task Chargement_des_données_in_ELK (Bash command failed. The command returned a non-zero exit code 127.; 38498)
[2023-03-13T19:50:59.428+0000] {local_task_job.py:208} INFO - Task exited with return code 1
[2023-03-13T19:50:59.448+0000] {taskinstance.py:2578} INFO - 0 downstream tasks scheduled from follow-on schedule check
[2023-03-13T20:12:27.792+0000] {taskinstance.py:1083} INFO - Dependencies all met for <TaskInstance: AUTOMATISATION.Chargement_des_données_in_ELK scheduled__2023-03-13T00:00:09+00:00 [queued]>
[2023-03-13T20:12:27.804+0000] {taskinstance.py:1083} INFO - Dependencies all met for <TaskInstance: AUTOMATISATION.Chargement_des_données_in_ELK scheduled__2023-03-13T00:00:09+00:00 [queued]>
[2023-03-13T20:12:27.805+0000] {taskinstance.py:1279} INFO - 
--------------------------------------------------------------------------------
[2023-03-13T20:12:27.805+0000] {taskinstance.py:1280} INFO - Starting attempt 3 of 4
[2023-03-13T20:12:27.805+0000] {taskinstance.py:1281} INFO - 
--------------------------------------------------------------------------------
[2023-03-13T20:12:27.829+0000] {taskinstance.py:1300} INFO - Executing <Task(BashOperator): Chargement_des_données_in_ELK> on 2023-03-13 00:00:09+00:00
[2023-03-13T20:12:27.832+0000] {standard_task_runner.py:55} INFO - Started process 42403 to run task
[2023-03-13T20:12:27.836+0000] {standard_task_runner.py:82} INFO - Running: ['airflow', 'tasks', 'run', 'AUTOMATISATION', 'Chargement_des_données_in_ELK', 'scheduled__2023-03-13T00:00:09+00:00', '--job-id', '215', '--raw', '--subdir', 'DAGS_FOLDER/main.py', '--cfg-path', '/tmp/tmpulsgax46']
[2023-03-13T20:12:27.838+0000] {standard_task_runner.py:83} INFO - Job 215: Subtask Chargement_des_données_in_ELK
[2023-03-13T20:12:27.901+0000] {task_command.py:388} INFO - Running <TaskInstance: AUTOMATISATION.Chargement_des_données_in_ELK scheduled__2023-03-13T00:00:09+00:00 [running]> on host dev
[2023-03-13T20:12:27.965+0000] {taskinstance.py:1507} INFO - Exporting the following env vars:
AIRFLOW_CTX_DAG_OWNER=airflow
AIRFLOW_CTX_DAG_ID=AUTOMATISATION
AIRFLOW_CTX_TASK_ID=Chargement_des_données_in_ELK
AIRFLOW_CTX_EXECUTION_DATE=2023-03-13T00:00:09+00:00
AIRFLOW_CTX_TRY_NUMBER=3
AIRFLOW_CTX_DAG_RUN_ID=scheduled__2023-03-13T00:00:09+00:00
[2023-03-13T20:12:27.966+0000] {subprocess.py:63} INFO - Tmp dir root location: 
 /tmp
[2023-03-13T20:12:27.967+0000] {subprocess.py:75} INFO - Running command: ['/usr/bin/bash', '-c', 'bin/logstash -f /home/dev/etc/logstash/conf.d/data.conf']
[2023-03-13T20:12:27.976+0000] {subprocess.py:86} INFO - Output:
[2023-03-13T20:12:27.978+0000] {subprocess.py:93} INFO - /usr/bin/bash: ligne 1: bin/logstash: Aucun fichier ou dossier de ce type
[2023-03-13T20:12:27.978+0000] {subprocess.py:97} INFO - Command exited with return code 127
[2023-03-13T20:12:27.988+0000] {taskinstance.py:1768} ERROR - Task failed with exception
Traceback (most recent call last):
  File "/home/dev/airflow/airflow/lib/python3.10/site-packages/airflow/operators/bash.py", line 196, in execute
    raise AirflowException(
airflow.exceptions.AirflowException: Bash command failed. The command returned a non-zero exit code 127.
[2023-03-13T20:12:27.992+0000] {taskinstance.py:1318} INFO - Marking task as UP_FOR_RETRY. dag_id=AUTOMATISATION, task_id=Chargement_des_données_in_ELK, execution_date=20230313T000009, start_date=20230313T201227, end_date=20230313T201227
[2023-03-13T20:12:28.011+0000] {standard_task_runner.py:100} ERROR - Failed to execute job 215 for task Chargement_des_données_in_ELK (Bash command failed. The command returned a non-zero exit code 127.; 42403)
[2023-03-13T20:12:28.047+0000] {local_task_job.py:208} INFO - Task exited with return code 1
[2023-03-13T20:12:28.070+0000] {taskinstance.py:2578} INFO - 0 downstream tasks scheduled from follow-on schedule check
