[2023-03-13T19:56:11.945+0000] {taskinstance.py:1083} INFO - Dependencies all met for <TaskInstance: AUTOMATISATION.Chargement_des_données_in_ELK scheduled__2023-03-13T00:00:12+00:00 [queued]>
[2023-03-13T19:56:11.958+0000] {taskinstance.py:1083} INFO - Dependencies all met for <TaskInstance: AUTOMATISATION.Chargement_des_données_in_ELK scheduled__2023-03-13T00:00:12+00:00 [queued]>
[2023-03-13T19:56:11.958+0000] {taskinstance.py:1279} INFO - 
--------------------------------------------------------------------------------
[2023-03-13T19:56:11.958+0000] {taskinstance.py:1280} INFO - Starting attempt 4 of 4
[2023-03-13T19:56:11.959+0000] {taskinstance.py:1281} INFO - 
--------------------------------------------------------------------------------
[2023-03-13T19:56:11.982+0000] {taskinstance.py:1300} INFO - Executing <Task(BashOperator): Chargement_des_données_in_ELK> on 2023-03-13 00:00:12+00:00
[2023-03-13T19:56:11.985+0000] {standard_task_runner.py:55} INFO - Started process 39264 to run task
[2023-03-13T19:56:11.990+0000] {standard_task_runner.py:82} INFO - Running: ['airflow', 'tasks', 'run', 'AUTOMATISATION', 'Chargement_des_données_in_ELK', 'scheduled__2023-03-13T00:00:12+00:00', '--job-id', '123', '--raw', '--subdir', 'DAGS_FOLDER/main.py', '--cfg-path', '/tmp/tmp3b90bq2q']
[2023-03-13T19:56:11.992+0000] {standard_task_runner.py:83} INFO - Job 123: Subtask Chargement_des_données_in_ELK
[2023-03-13T19:56:12.057+0000] {task_command.py:388} INFO - Running <TaskInstance: AUTOMATISATION.Chargement_des_données_in_ELK scheduled__2023-03-13T00:00:12+00:00 [running]> on host dev
[2023-03-13T19:56:12.125+0000] {taskinstance.py:1507} INFO - Exporting the following env vars:
AIRFLOW_CTX_DAG_OWNER=airflow
AIRFLOW_CTX_DAG_ID=AUTOMATISATION
AIRFLOW_CTX_TASK_ID=Chargement_des_données_in_ELK
AIRFLOW_CTX_EXECUTION_DATE=2023-03-13T00:00:12+00:00
AIRFLOW_CTX_TRY_NUMBER=4
AIRFLOW_CTX_DAG_RUN_ID=scheduled__2023-03-13T00:00:12+00:00
[2023-03-13T19:56:12.127+0000] {subprocess.py:63} INFO - Tmp dir root location: 
 /tmp
[2023-03-13T19:56:12.128+0000] {subprocess.py:75} INFO - Running command: ['/usr/bin/bash', '-c', 'bin/logstash --path.config /etc/logstash/conf.d/data.conf']
[2023-03-13T19:56:12.136+0000] {subprocess.py:86} INFO - Output:
[2023-03-13T19:56:12.138+0000] {subprocess.py:93} INFO - /usr/bin/bash: ligne 1: bin/logstash: Aucun fichier ou dossier de ce type
[2023-03-13T19:56:12.138+0000] {subprocess.py:97} INFO - Command exited with return code 127
[2023-03-13T19:56:12.148+0000] {taskinstance.py:1768} ERROR - Task failed with exception
Traceback (most recent call last):
  File "/home/dev/airflow/airflow/lib/python3.10/site-packages/airflow/operators/bash.py", line 196, in execute
    raise AirflowException(
airflow.exceptions.AirflowException: Bash command failed. The command returned a non-zero exit code 127.
[2023-03-13T19:56:12.152+0000] {taskinstance.py:1318} INFO - Marking task as FAILED. dag_id=AUTOMATISATION, task_id=Chargement_des_données_in_ELK, execution_date=20230313T000012, start_date=20230313T195611, end_date=20230313T195612
[2023-03-13T19:56:12.170+0000] {standard_task_runner.py:100} ERROR - Failed to execute job 123 for task Chargement_des_données_in_ELK (Bash command failed. The command returned a non-zero exit code 127.; 39264)
[2023-03-13T19:56:12.201+0000] {local_task_job.py:208} INFO - Task exited with return code 1
[2023-03-13T19:56:12.221+0000] {taskinstance.py:2578} INFO - 0 downstream tasks scheduled from follow-on schedule check
[2023-03-13T20:17:47.057+0000] {taskinstance.py:1083} INFO - Dependencies all met for <TaskInstance: AUTOMATISATION.Chargement_des_données_in_ELK scheduled__2023-03-13T00:00:12+00:00 [queued]>
[2023-03-13T20:17:47.070+0000] {taskinstance.py:1083} INFO - Dependencies all met for <TaskInstance: AUTOMATISATION.Chargement_des_données_in_ELK scheduled__2023-03-13T00:00:12+00:00 [queued]>
[2023-03-13T20:17:47.071+0000] {taskinstance.py:1279} INFO - 
--------------------------------------------------------------------------------
[2023-03-13T20:17:47.071+0000] {taskinstance.py:1280} INFO - Starting attempt 4 of 4
[2023-03-13T20:17:47.071+0000] {taskinstance.py:1281} INFO - 
--------------------------------------------------------------------------------
[2023-03-13T20:17:47.092+0000] {taskinstance.py:1300} INFO - Executing <Task(BashOperator): Chargement_des_données_in_ELK> on 2023-03-13 00:00:12+00:00
[2023-03-13T20:17:47.096+0000] {standard_task_runner.py:55} INFO - Started process 43152 to run task
[2023-03-13T20:17:47.100+0000] {standard_task_runner.py:82} INFO - Running: ['airflow', 'tasks', 'run', 'AUTOMATISATION', 'Chargement_des_données_in_ELK', 'scheduled__2023-03-13T00:00:12+00:00', '--job-id', '237', '--raw', '--subdir', 'DAGS_FOLDER/main.py', '--cfg-path', '/tmp/tmp5r94o3_t']
[2023-03-13T20:17:47.102+0000] {standard_task_runner.py:83} INFO - Job 237: Subtask Chargement_des_données_in_ELK
[2023-03-13T20:17:47.169+0000] {task_command.py:388} INFO - Running <TaskInstance: AUTOMATISATION.Chargement_des_données_in_ELK scheduled__2023-03-13T00:00:12+00:00 [running]> on host dev
[2023-03-13T20:17:47.235+0000] {taskinstance.py:1507} INFO - Exporting the following env vars:
AIRFLOW_CTX_DAG_OWNER=airflow
AIRFLOW_CTX_DAG_ID=AUTOMATISATION
AIRFLOW_CTX_TASK_ID=Chargement_des_données_in_ELK
AIRFLOW_CTX_EXECUTION_DATE=2023-03-13T00:00:12+00:00
AIRFLOW_CTX_TRY_NUMBER=4
AIRFLOW_CTX_DAG_RUN_ID=scheduled__2023-03-13T00:00:12+00:00
[2023-03-13T20:17:47.237+0000] {subprocess.py:63} INFO - Tmp dir root location: 
 /tmp
[2023-03-13T20:17:47.238+0000] {subprocess.py:75} INFO - Running command: ['/usr/bin/bash', '-c', 'bin/logstash -f /home/dev/etc/logstash/conf.d/data.conf']
[2023-03-13T20:17:47.246+0000] {subprocess.py:86} INFO - Output:
[2023-03-13T20:17:47.248+0000] {subprocess.py:93} INFO - /usr/bin/bash: ligne 1: bin/logstash: Aucun fichier ou dossier de ce type
[2023-03-13T20:17:47.248+0000] {subprocess.py:97} INFO - Command exited with return code 127
[2023-03-13T20:17:47.258+0000] {taskinstance.py:1768} ERROR - Task failed with exception
Traceback (most recent call last):
  File "/home/dev/airflow/airflow/lib/python3.10/site-packages/airflow/operators/bash.py", line 196, in execute
    raise AirflowException(
airflow.exceptions.AirflowException: Bash command failed. The command returned a non-zero exit code 127.
[2023-03-13T20:17:47.262+0000] {taskinstance.py:1318} INFO - Marking task as FAILED. dag_id=AUTOMATISATION, task_id=Chargement_des_données_in_ELK, execution_date=20230313T000012, start_date=20230313T201747, end_date=20230313T201747
[2023-03-13T20:17:47.284+0000] {standard_task_runner.py:100} ERROR - Failed to execute job 237 for task Chargement_des_données_in_ELK (Bash command failed. The command returned a non-zero exit code 127.; 43152)
[2023-03-13T20:17:47.311+0000] {local_task_job.py:208} INFO - Task exited with return code 1
[2023-03-13T20:17:47.332+0000] {taskinstance.py:2578} INFO - 0 downstream tasks scheduled from follow-on schedule check
