[2023-03-13T19:35:31.621+0000] {taskinstance.py:1083} INFO - Dependencies all met for <TaskInstance: AUTOMATISATION.Chargement_des_données_in_ELK scheduled__2023-03-13T00:00:12+00:00 [queued]>
[2023-03-13T19:35:31.633+0000] {taskinstance.py:1083} INFO - Dependencies all met for <TaskInstance: AUTOMATISATION.Chargement_des_données_in_ELK scheduled__2023-03-13T00:00:12+00:00 [queued]>
[2023-03-13T19:35:31.634+0000] {taskinstance.py:1279} INFO - 
--------------------------------------------------------------------------------
[2023-03-13T19:35:31.634+0000] {taskinstance.py:1280} INFO - Starting attempt 2 of 4
[2023-03-13T19:35:31.634+0000] {taskinstance.py:1281} INFO - 
--------------------------------------------------------------------------------
[2023-03-13T19:35:31.654+0000] {taskinstance.py:1300} INFO - Executing <Task(BashOperator): Chargement_des_données_in_ELK> on 2023-03-13 00:00:12+00:00
[2023-03-13T19:35:31.657+0000] {standard_task_runner.py:55} INFO - Started process 35879 to run task
[2023-03-13T19:35:31.662+0000] {standard_task_runner.py:82} INFO - Running: ['airflow', 'tasks', 'run', 'AUTOMATISATION', 'Chargement_des_données_in_ELK', 'scheduled__2023-03-13T00:00:12+00:00', '--job-id', '40', '--raw', '--subdir', 'DAGS_FOLDER/main.py', '--cfg-path', '/tmp/tmppolpmqhg']
[2023-03-13T19:35:31.664+0000] {standard_task_runner.py:83} INFO - Job 40: Subtask Chargement_des_données_in_ELK
[2023-03-13T19:35:31.731+0000] {task_command.py:388} INFO - Running <TaskInstance: AUTOMATISATION.Chargement_des_données_in_ELK scheduled__2023-03-13T00:00:12+00:00 [running]> on host dev
[2023-03-13T19:35:31.799+0000] {taskinstance.py:1507} INFO - Exporting the following env vars:
AIRFLOW_CTX_DAG_OWNER=airflow
AIRFLOW_CTX_DAG_ID=AUTOMATISATION
AIRFLOW_CTX_TASK_ID=Chargement_des_données_in_ELK
AIRFLOW_CTX_EXECUTION_DATE=2023-03-13T00:00:12+00:00
AIRFLOW_CTX_TRY_NUMBER=2
AIRFLOW_CTX_DAG_RUN_ID=scheduled__2023-03-13T00:00:12+00:00
[2023-03-13T19:35:31.800+0000] {subprocess.py:63} INFO - Tmp dir root location: 
 /tmp
[2023-03-13T19:35:31.801+0000] {subprocess.py:75} INFO - Running command: ['/usr/bin/bash', '-c', '/usr/bin/logstash --path.config /etc/logstash/conf.d/data.conf']
[2023-03-13T19:35:31.809+0000] {subprocess.py:86} INFO - Output:
[2023-03-13T19:35:31.810+0000] {subprocess.py:93} INFO - /usr/bin/bash: ligne 1: /usr/bin/logstash: Aucun fichier ou dossier de ce type
[2023-03-13T19:35:31.811+0000] {subprocess.py:97} INFO - Command exited with return code 127
[2023-03-13T19:35:31.822+0000] {taskinstance.py:1768} ERROR - Task failed with exception
Traceback (most recent call last):
  File "/home/dev/airflow/airflow/lib/python3.10/site-packages/airflow/operators/bash.py", line 196, in execute
    raise AirflowException(
airflow.exceptions.AirflowException: Bash command failed. The command returned a non-zero exit code 127.
[2023-03-13T19:35:31.826+0000] {taskinstance.py:1318} INFO - Marking task as UP_FOR_RETRY. dag_id=AUTOMATISATION, task_id=Chargement_des_données_in_ELK, execution_date=20230313T000012, start_date=20230313T193531, end_date=20230313T193531
[2023-03-13T19:35:31.845+0000] {standard_task_runner.py:100} ERROR - Failed to execute job 40 for task Chargement_des_données_in_ELK (Bash command failed. The command returned a non-zero exit code 127.; 35879)
[2023-03-13T19:35:31.873+0000] {local_task_job.py:208} INFO - Task exited with return code 1
[2023-03-13T19:35:31.893+0000] {taskinstance.py:2578} INFO - 0 downstream tasks scheduled from follow-on schedule check
[2023-03-13T19:46:05.273+0000] {taskinstance.py:1083} INFO - Dependencies all met for <TaskInstance: AUTOMATISATION.Chargement_des_données_in_ELK scheduled__2023-03-13T00:00:12+00:00 [queued]>
[2023-03-13T19:46:05.288+0000] {taskinstance.py:1083} INFO - Dependencies all met for <TaskInstance: AUTOMATISATION.Chargement_des_données_in_ELK scheduled__2023-03-13T00:00:12+00:00 [queued]>
[2023-03-13T19:46:05.288+0000] {taskinstance.py:1279} INFO - 
--------------------------------------------------------------------------------
[2023-03-13T19:46:05.289+0000] {taskinstance.py:1280} INFO - Starting attempt 2 of 4
[2023-03-13T19:46:05.289+0000] {taskinstance.py:1281} INFO - 
--------------------------------------------------------------------------------
[2023-03-13T19:46:05.313+0000] {taskinstance.py:1300} INFO - Executing <Task(BashOperator): Chargement_des_données_in_ELK> on 2023-03-13 00:00:12+00:00
[2023-03-13T19:46:05.316+0000] {standard_task_runner.py:55} INFO - Started process 37797 to run task
[2023-03-13T19:46:05.321+0000] {standard_task_runner.py:82} INFO - Running: ['airflow', 'tasks', 'run', 'AUTOMATISATION', 'Chargement_des_données_in_ELK', 'scheduled__2023-03-13T00:00:12+00:00', '--job-id', '88', '--raw', '--subdir', 'DAGS_FOLDER/main.py', '--cfg-path', '/tmp/tmposekddyc']
[2023-03-13T19:46:05.323+0000] {standard_task_runner.py:83} INFO - Job 88: Subtask Chargement_des_données_in_ELK
[2023-03-13T19:46:05.390+0000] {task_command.py:388} INFO - Running <TaskInstance: AUTOMATISATION.Chargement_des_données_in_ELK scheduled__2023-03-13T00:00:12+00:00 [running]> on host dev
[2023-03-13T19:46:05.460+0000] {taskinstance.py:1507} INFO - Exporting the following env vars:
AIRFLOW_CTX_DAG_OWNER=airflow
AIRFLOW_CTX_DAG_ID=AUTOMATISATION
AIRFLOW_CTX_TASK_ID=Chargement_des_données_in_ELK
AIRFLOW_CTX_EXECUTION_DATE=2023-03-13T00:00:12+00:00
AIRFLOW_CTX_TRY_NUMBER=2
AIRFLOW_CTX_DAG_RUN_ID=scheduled__2023-03-13T00:00:12+00:00
[2023-03-13T19:46:05.462+0000] {subprocess.py:63} INFO - Tmp dir root location: 
 /tmp
[2023-03-13T19:46:05.463+0000] {subprocess.py:75} INFO - Running command: ['/usr/bin/bash', '-c', 'bin/logstash --path.config /etc/logstash/conf.d/data.conf']
[2023-03-13T19:46:05.472+0000] {subprocess.py:86} INFO - Output:
[2023-03-13T19:46:05.474+0000] {subprocess.py:93} INFO - /usr/bin/bash: ligne 1: bin/logstash: Aucun fichier ou dossier de ce type
[2023-03-13T19:46:05.474+0000] {subprocess.py:97} INFO - Command exited with return code 127
[2023-03-13T19:46:05.485+0000] {taskinstance.py:1768} ERROR - Task failed with exception
Traceback (most recent call last):
  File "/home/dev/airflow/airflow/lib/python3.10/site-packages/airflow/operators/bash.py", line 196, in execute
    raise AirflowException(
airflow.exceptions.AirflowException: Bash command failed. The command returned a non-zero exit code 127.
[2023-03-13T19:46:05.489+0000] {taskinstance.py:1318} INFO - Marking task as UP_FOR_RETRY. dag_id=AUTOMATISATION, task_id=Chargement_des_données_in_ELK, execution_date=20230313T000012, start_date=20230313T194605, end_date=20230313T194605
[2023-03-13T19:46:05.510+0000] {standard_task_runner.py:100} ERROR - Failed to execute job 88 for task Chargement_des_données_in_ELK (Bash command failed. The command returned a non-zero exit code 127.; 37797)
[2023-03-13T19:46:05.531+0000] {local_task_job.py:208} INFO - Task exited with return code 1
[2023-03-13T19:46:05.552+0000] {taskinstance.py:2578} INFO - 0 downstream tasks scheduled from follow-on schedule check
[2023-03-13T20:07:30.373+0000] {taskinstance.py:1083} INFO - Dependencies all met for <TaskInstance: AUTOMATISATION.Chargement_des_données_in_ELK scheduled__2023-03-13T00:00:12+00:00 [queued]>
[2023-03-13T20:07:30.387+0000] {taskinstance.py:1083} INFO - Dependencies all met for <TaskInstance: AUTOMATISATION.Chargement_des_données_in_ELK scheduled__2023-03-13T00:00:12+00:00 [queued]>
[2023-03-13T20:07:30.388+0000] {taskinstance.py:1279} INFO - 
--------------------------------------------------------------------------------
[2023-03-13T20:07:30.388+0000] {taskinstance.py:1280} INFO - Starting attempt 2 of 4
[2023-03-13T20:07:30.388+0000] {taskinstance.py:1281} INFO - 
--------------------------------------------------------------------------------
[2023-03-13T20:07:30.411+0000] {taskinstance.py:1300} INFO - Executing <Task(BashOperator): Chargement_des_données_in_ELK> on 2023-03-13 00:00:12+00:00
[2023-03-13T20:07:30.415+0000] {standard_task_runner.py:55} INFO - Started process 41672 to run task
[2023-03-13T20:07:30.420+0000] {standard_task_runner.py:82} INFO - Running: ['airflow', 'tasks', 'run', 'AUTOMATISATION', 'Chargement_des_données_in_ELK', 'scheduled__2023-03-13T00:00:12+00:00', '--job-id', '200', '--raw', '--subdir', 'DAGS_FOLDER/main.py', '--cfg-path', '/tmp/tmpxay9_jy8']
[2023-03-13T20:07:30.422+0000] {standard_task_runner.py:83} INFO - Job 200: Subtask Chargement_des_données_in_ELK
[2023-03-13T20:07:30.488+0000] {task_command.py:388} INFO - Running <TaskInstance: AUTOMATISATION.Chargement_des_données_in_ELK scheduled__2023-03-13T00:00:12+00:00 [running]> on host dev
[2023-03-13T20:07:30.556+0000] {taskinstance.py:1507} INFO - Exporting the following env vars:
AIRFLOW_CTX_DAG_OWNER=airflow
AIRFLOW_CTX_DAG_ID=AUTOMATISATION
AIRFLOW_CTX_TASK_ID=Chargement_des_données_in_ELK
AIRFLOW_CTX_EXECUTION_DATE=2023-03-13T00:00:12+00:00
AIRFLOW_CTX_TRY_NUMBER=2
AIRFLOW_CTX_DAG_RUN_ID=scheduled__2023-03-13T00:00:12+00:00
[2023-03-13T20:07:30.558+0000] {subprocess.py:63} INFO - Tmp dir root location: 
 /tmp
[2023-03-13T20:07:30.559+0000] {subprocess.py:75} INFO - Running command: ['/usr/bin/bash', '-c', 'bin/logstash -f /home/dev/etc/logstash/conf.d/data.conf']
[2023-03-13T20:07:30.567+0000] {subprocess.py:86} INFO - Output:
[2023-03-13T20:07:30.568+0000] {subprocess.py:93} INFO - /usr/bin/bash: ligne 1: bin/logstash: Aucun fichier ou dossier de ce type
[2023-03-13T20:07:30.569+0000] {subprocess.py:97} INFO - Command exited with return code 127
[2023-03-13T20:07:30.579+0000] {taskinstance.py:1768} ERROR - Task failed with exception
Traceback (most recent call last):
  File "/home/dev/airflow/airflow/lib/python3.10/site-packages/airflow/operators/bash.py", line 196, in execute
    raise AirflowException(
airflow.exceptions.AirflowException: Bash command failed. The command returned a non-zero exit code 127.
[2023-03-13T20:07:30.583+0000] {taskinstance.py:1318} INFO - Marking task as UP_FOR_RETRY. dag_id=AUTOMATISATION, task_id=Chargement_des_données_in_ELK, execution_date=20230313T000012, start_date=20230313T200730, end_date=20230313T200730
[2023-03-13T20:07:30.602+0000] {standard_task_runner.py:100} ERROR - Failed to execute job 200 for task Chargement_des_données_in_ELK (Bash command failed. The command returned a non-zero exit code 127.; 41672)
[2023-03-13T20:07:30.631+0000] {local_task_job.py:208} INFO - Task exited with return code 1
[2023-03-13T20:07:30.651+0000] {taskinstance.py:2578} INFO - 0 downstream tasks scheduled from follow-on schedule check
