[2023-03-13T19:50:35.093+0000] {taskinstance.py:1083} INFO - Dependencies all met for <TaskInstance: AUTOMATISATION.Chargement_des_données_in_ELK scheduled__2023-03-13T00:00:00+00:00 [queued]>
[2023-03-13T19:50:35.105+0000] {taskinstance.py:1083} INFO - Dependencies all met for <TaskInstance: AUTOMATISATION.Chargement_des_données_in_ELK scheduled__2023-03-13T00:00:00+00:00 [queued]>
[2023-03-13T19:50:35.105+0000] {taskinstance.py:1279} INFO - 
--------------------------------------------------------------------------------
[2023-03-13T19:50:35.105+0000] {taskinstance.py:1280} INFO - Starting attempt 3 of 4
[2023-03-13T19:50:35.105+0000] {taskinstance.py:1281} INFO - 
--------------------------------------------------------------------------------
[2023-03-13T19:50:35.125+0000] {taskinstance.py:1300} INFO - Executing <Task(BashOperator): Chargement_des_données_in_ELK> on 2023-03-13 00:00:00+00:00
[2023-03-13T19:50:35.128+0000] {standard_task_runner.py:55} INFO - Started process 38439 to run task
[2023-03-13T19:50:35.132+0000] {standard_task_runner.py:82} INFO - Running: ['airflow', 'tasks', 'run', 'AUTOMATISATION', 'Chargement_des_données_in_ELK', 'scheduled__2023-03-13T00:00:00+00:00', '--job-id', '99', '--raw', '--subdir', 'DAGS_FOLDER/main.py', '--cfg-path', '/tmp/tmpcqhixogj']
[2023-03-13T19:50:35.133+0000] {standard_task_runner.py:83} INFO - Job 99: Subtask Chargement_des_données_in_ELK
[2023-03-13T19:50:35.196+0000] {task_command.py:388} INFO - Running <TaskInstance: AUTOMATISATION.Chargement_des_données_in_ELK scheduled__2023-03-13T00:00:00+00:00 [running]> on host dev
[2023-03-13T19:50:35.255+0000] {taskinstance.py:1507} INFO - Exporting the following env vars:
AIRFLOW_CTX_DAG_OWNER=airflow
AIRFLOW_CTX_DAG_ID=AUTOMATISATION
AIRFLOW_CTX_TASK_ID=Chargement_des_données_in_ELK
AIRFLOW_CTX_EXECUTION_DATE=2023-03-13T00:00:00+00:00
AIRFLOW_CTX_TRY_NUMBER=3
AIRFLOW_CTX_DAG_RUN_ID=scheduled__2023-03-13T00:00:00+00:00
[2023-03-13T19:50:35.256+0000] {subprocess.py:63} INFO - Tmp dir root location: 
 /tmp
[2023-03-13T19:50:35.257+0000] {subprocess.py:75} INFO - Running command: ['/usr/bin/bash', '-c', 'bin/logstash --path.config /etc/logstash/conf.d/data.conf']
[2023-03-13T19:50:35.264+0000] {subprocess.py:86} INFO - Output:
[2023-03-13T19:50:35.265+0000] {subprocess.py:93} INFO - /usr/bin/bash: ligne 1: bin/logstash: Aucun fichier ou dossier de ce type
[2023-03-13T19:50:35.265+0000] {subprocess.py:97} INFO - Command exited with return code 127
[2023-03-13T19:50:35.275+0000] {taskinstance.py:1768} ERROR - Task failed with exception
Traceback (most recent call last):
  File "/home/dev/airflow/airflow/lib/python3.10/site-packages/airflow/operators/bash.py", line 196, in execute
    raise AirflowException(
airflow.exceptions.AirflowException: Bash command failed. The command returned a non-zero exit code 127.
[2023-03-13T19:50:35.279+0000] {taskinstance.py:1318} INFO - Marking task as UP_FOR_RETRY. dag_id=AUTOMATISATION, task_id=Chargement_des_données_in_ELK, execution_date=20230313T000000, start_date=20230313T195035, end_date=20230313T195035
[2023-03-13T19:50:35.297+0000] {standard_task_runner.py:100} ERROR - Failed to execute job 99 for task Chargement_des_données_in_ELK (Bash command failed. The command returned a non-zero exit code 127.; 38439)
[2023-03-13T19:50:35.303+0000] {local_task_job.py:208} INFO - Task exited with return code 1
[2023-03-13T19:50:35.321+0000] {taskinstance.py:2578} INFO - 0 downstream tasks scheduled from follow-on schedule check
[2023-03-13T20:12:00.777+0000] {taskinstance.py:1083} INFO - Dependencies all met for <TaskInstance: AUTOMATISATION.Chargement_des_données_in_ELK scheduled__2023-03-13T00:00:00+00:00 [queued]>
[2023-03-13T20:12:00.789+0000] {taskinstance.py:1083} INFO - Dependencies all met for <TaskInstance: AUTOMATISATION.Chargement_des_données_in_ELK scheduled__2023-03-13T00:00:00+00:00 [queued]>
[2023-03-13T20:12:00.789+0000] {taskinstance.py:1279} INFO - 
--------------------------------------------------------------------------------
[2023-03-13T20:12:00.790+0000] {taskinstance.py:1280} INFO - Starting attempt 3 of 4
[2023-03-13T20:12:00.790+0000] {taskinstance.py:1281} INFO - 
--------------------------------------------------------------------------------
[2023-03-13T20:12:00.810+0000] {taskinstance.py:1300} INFO - Executing <Task(BashOperator): Chargement_des_données_in_ELK> on 2023-03-13 00:00:00+00:00
[2023-03-13T20:12:00.813+0000] {standard_task_runner.py:55} INFO - Started process 42352 to run task
[2023-03-13T20:12:00.818+0000] {standard_task_runner.py:82} INFO - Running: ['airflow', 'tasks', 'run', 'AUTOMATISATION', 'Chargement_des_données_in_ELK', 'scheduled__2023-03-13T00:00:00+00:00', '--job-id', '211', '--raw', '--subdir', 'DAGS_FOLDER/main.py', '--cfg-path', '/tmp/tmp_gultlx4']
[2023-03-13T20:12:00.820+0000] {standard_task_runner.py:83} INFO - Job 211: Subtask Chargement_des_données_in_ELK
[2023-03-13T20:12:00.888+0000] {task_command.py:388} INFO - Running <TaskInstance: AUTOMATISATION.Chargement_des_données_in_ELK scheduled__2023-03-13T00:00:00+00:00 [running]> on host dev
[2023-03-13T20:12:00.953+0000] {taskinstance.py:1507} INFO - Exporting the following env vars:
AIRFLOW_CTX_DAG_OWNER=airflow
AIRFLOW_CTX_DAG_ID=AUTOMATISATION
AIRFLOW_CTX_TASK_ID=Chargement_des_données_in_ELK
AIRFLOW_CTX_EXECUTION_DATE=2023-03-13T00:00:00+00:00
AIRFLOW_CTX_TRY_NUMBER=3
AIRFLOW_CTX_DAG_RUN_ID=scheduled__2023-03-13T00:00:00+00:00
[2023-03-13T20:12:00.955+0000] {subprocess.py:63} INFO - Tmp dir root location: 
 /tmp
[2023-03-13T20:12:00.956+0000] {subprocess.py:75} INFO - Running command: ['/usr/bin/bash', '-c', 'bin/logstash -f /home/dev/etc/logstash/conf.d/data.conf']
[2023-03-13T20:12:00.965+0000] {subprocess.py:86} INFO - Output:
[2023-03-13T20:12:00.967+0000] {subprocess.py:93} INFO - /usr/bin/bash: ligne 1: bin/logstash: Aucun fichier ou dossier de ce type
[2023-03-13T20:12:00.967+0000] {subprocess.py:97} INFO - Command exited with return code 127
[2023-03-13T20:12:00.978+0000] {taskinstance.py:1768} ERROR - Task failed with exception
Traceback (most recent call last):
  File "/home/dev/airflow/airflow/lib/python3.10/site-packages/airflow/operators/bash.py", line 196, in execute
    raise AirflowException(
airflow.exceptions.AirflowException: Bash command failed. The command returned a non-zero exit code 127.
[2023-03-13T20:12:00.982+0000] {taskinstance.py:1318} INFO - Marking task as UP_FOR_RETRY. dag_id=AUTOMATISATION, task_id=Chargement_des_données_in_ELK, execution_date=20230313T000000, start_date=20230313T201200, end_date=20230313T201200
[2023-03-13T20:12:01.003+0000] {standard_task_runner.py:100} ERROR - Failed to execute job 211 for task Chargement_des_données_in_ELK (Bash command failed. The command returned a non-zero exit code 127.; 42352)
[2023-03-13T20:12:01.029+0000] {local_task_job.py:208} INFO - Task exited with return code 1
[2023-03-13T20:12:01.056+0000] {taskinstance.py:2578} INFO - 0 downstream tasks scheduled from follow-on schedule check
