[2023-03-13T19:55:44.730+0000] {taskinstance.py:1083} INFO - Dependencies all met for <TaskInstance: AUTOMATISATION.Chargement_des_données_in_ELK scheduled__2023-03-13T00:00:03+00:00 [queued]>
[2023-03-13T19:55:44.744+0000] {taskinstance.py:1083} INFO - Dependencies all met for <TaskInstance: AUTOMATISATION.Chargement_des_données_in_ELK scheduled__2023-03-13T00:00:03+00:00 [queued]>
[2023-03-13T19:55:44.744+0000] {taskinstance.py:1279} INFO - 
--------------------------------------------------------------------------------
[2023-03-13T19:55:44.744+0000] {taskinstance.py:1280} INFO - Starting attempt 4 of 4
[2023-03-13T19:55:44.745+0000] {taskinstance.py:1281} INFO - 
--------------------------------------------------------------------------------
[2023-03-13T19:55:44.771+0000] {taskinstance.py:1300} INFO - Executing <Task(BashOperator): Chargement_des_données_in_ELK> on 2023-03-13 00:00:03+00:00
[2023-03-13T19:55:44.775+0000] {standard_task_runner.py:55} INFO - Started process 39153 to run task
[2023-03-13T19:55:44.780+0000] {standard_task_runner.py:82} INFO - Running: ['airflow', 'tasks', 'run', 'AUTOMATISATION', 'Chargement_des_données_in_ELK', 'scheduled__2023-03-13T00:00:03+00:00', '--job-id', '116', '--raw', '--subdir', 'DAGS_FOLDER/main.py', '--cfg-path', '/tmp/tmpgu14p4mk']
[2023-03-13T19:55:44.782+0000] {standard_task_runner.py:83} INFO - Job 116: Subtask Chargement_des_données_in_ELK
[2023-03-13T19:55:44.849+0000] {task_command.py:388} INFO - Running <TaskInstance: AUTOMATISATION.Chargement_des_données_in_ELK scheduled__2023-03-13T00:00:03+00:00 [running]> on host dev
[2023-03-13T19:55:44.916+0000] {taskinstance.py:1507} INFO - Exporting the following env vars:
AIRFLOW_CTX_DAG_OWNER=airflow
AIRFLOW_CTX_DAG_ID=AUTOMATISATION
AIRFLOW_CTX_TASK_ID=Chargement_des_données_in_ELK
AIRFLOW_CTX_EXECUTION_DATE=2023-03-13T00:00:03+00:00
AIRFLOW_CTX_TRY_NUMBER=4
AIRFLOW_CTX_DAG_RUN_ID=scheduled__2023-03-13T00:00:03+00:00
[2023-03-13T19:55:44.918+0000] {subprocess.py:63} INFO - Tmp dir root location: 
 /tmp
[2023-03-13T19:55:44.918+0000] {subprocess.py:75} INFO - Running command: ['/usr/bin/bash', '-c', 'bin/logstash --path.config /etc/logstash/conf.d/data.conf']
[2023-03-13T19:55:44.927+0000] {subprocess.py:86} INFO - Output:
[2023-03-13T19:55:44.928+0000] {subprocess.py:93} INFO - /usr/bin/bash: ligne 1: bin/logstash: Aucun fichier ou dossier de ce type
[2023-03-13T19:55:44.929+0000] {subprocess.py:97} INFO - Command exited with return code 127
[2023-03-13T19:55:44.939+0000] {taskinstance.py:1768} ERROR - Task failed with exception
Traceback (most recent call last):
  File "/home/dev/airflow/airflow/lib/python3.10/site-packages/airflow/operators/bash.py", line 196, in execute
    raise AirflowException(
airflow.exceptions.AirflowException: Bash command failed. The command returned a non-zero exit code 127.
[2023-03-13T19:55:44.944+0000] {taskinstance.py:1318} INFO - Marking task as FAILED. dag_id=AUTOMATISATION, task_id=Chargement_des_données_in_ELK, execution_date=20230313T000003, start_date=20230313T195544, end_date=20230313T195544
[2023-03-13T19:55:44.963+0000] {standard_task_runner.py:100} ERROR - Failed to execute job 116 for task Chargement_des_données_in_ELK (Bash command failed. The command returned a non-zero exit code 127.; 39153)
[2023-03-13T19:55:44.991+0000] {local_task_job.py:208} INFO - Task exited with return code 1
[2023-03-13T19:55:45.011+0000] {taskinstance.py:2578} INFO - 0 downstream tasks scheduled from follow-on schedule check
[2023-03-13T20:17:10.560+0000] {taskinstance.py:1083} INFO - Dependencies all met for <TaskInstance: AUTOMATISATION.Chargement_des_données_in_ELK scheduled__2023-03-13T00:00:03+00:00 [queued]>
[2023-03-13T20:17:10.577+0000] {taskinstance.py:1083} INFO - Dependencies all met for <TaskInstance: AUTOMATISATION.Chargement_des_données_in_ELK scheduled__2023-03-13T00:00:03+00:00 [queued]>
[2023-03-13T20:17:10.577+0000] {taskinstance.py:1279} INFO - 
--------------------------------------------------------------------------------
[2023-03-13T20:17:10.577+0000] {taskinstance.py:1280} INFO - Starting attempt 4 of 4
[2023-03-13T20:17:10.578+0000] {taskinstance.py:1281} INFO - 
--------------------------------------------------------------------------------
[2023-03-13T20:17:10.599+0000] {taskinstance.py:1300} INFO - Executing <Task(BashOperator): Chargement_des_données_in_ELK> on 2023-03-13 00:00:03+00:00
[2023-03-13T20:17:10.603+0000] {standard_task_runner.py:55} INFO - Started process 43015 to run task
[2023-03-13T20:17:10.607+0000] {standard_task_runner.py:82} INFO - Running: ['airflow', 'tasks', 'run', 'AUTOMATISATION', 'Chargement_des_données_in_ELK', 'scheduled__2023-03-13T00:00:03+00:00', '--job-id', '228', '--raw', '--subdir', 'DAGS_FOLDER/main.py', '--cfg-path', '/tmp/tmp22055s80']
[2023-03-13T20:17:10.609+0000] {standard_task_runner.py:83} INFO - Job 228: Subtask Chargement_des_données_in_ELK
[2023-03-13T20:17:10.677+0000] {task_command.py:388} INFO - Running <TaskInstance: AUTOMATISATION.Chargement_des_données_in_ELK scheduled__2023-03-13T00:00:03+00:00 [running]> on host dev
[2023-03-13T20:17:10.743+0000] {taskinstance.py:1507} INFO - Exporting the following env vars:
AIRFLOW_CTX_DAG_OWNER=airflow
AIRFLOW_CTX_DAG_ID=AUTOMATISATION
AIRFLOW_CTX_TASK_ID=Chargement_des_données_in_ELK
AIRFLOW_CTX_EXECUTION_DATE=2023-03-13T00:00:03+00:00
AIRFLOW_CTX_TRY_NUMBER=4
AIRFLOW_CTX_DAG_RUN_ID=scheduled__2023-03-13T00:00:03+00:00
[2023-03-13T20:17:10.744+0000] {subprocess.py:63} INFO - Tmp dir root location: 
 /tmp
[2023-03-13T20:17:10.745+0000] {subprocess.py:75} INFO - Running command: ['/usr/bin/bash', '-c', 'bin/logstash -f /home/dev/etc/logstash/conf.d/data.conf']
[2023-03-13T20:17:10.753+0000] {subprocess.py:86} INFO - Output:
[2023-03-13T20:17:10.755+0000] {subprocess.py:93} INFO - /usr/bin/bash: ligne 1: bin/logstash: Aucun fichier ou dossier de ce type
[2023-03-13T20:17:10.755+0000] {subprocess.py:97} INFO - Command exited with return code 127
[2023-03-13T20:17:10.766+0000] {taskinstance.py:1768} ERROR - Task failed with exception
Traceback (most recent call last):
  File "/home/dev/airflow/airflow/lib/python3.10/site-packages/airflow/operators/bash.py", line 196, in execute
    raise AirflowException(
airflow.exceptions.AirflowException: Bash command failed. The command returned a non-zero exit code 127.
[2023-03-13T20:17:10.771+0000] {taskinstance.py:1318} INFO - Marking task as FAILED. dag_id=AUTOMATISATION, task_id=Chargement_des_données_in_ELK, execution_date=20230313T000003, start_date=20230313T201710, end_date=20230313T201710
[2023-03-13T20:17:10.793+0000] {standard_task_runner.py:100} ERROR - Failed to execute job 228 for task Chargement_des_données_in_ELK (Bash command failed. The command returned a non-zero exit code 127.; 43015)
[2023-03-13T20:17:10.818+0000] {local_task_job.py:208} INFO - Task exited with return code 1
[2023-03-13T20:17:10.838+0000] {taskinstance.py:2578} INFO - 0 downstream tasks scheduled from follow-on schedule check
