[2023-03-13T19:56:56.544+0000] {taskinstance.py:1083} INFO - Dependencies all met for <TaskInstance: AUTOMATISATION.Chargement_des_données_in_ELK scheduled__2023-03-13T00:00:30+00:00 [queued]>
[2023-03-13T19:56:56.557+0000] {taskinstance.py:1083} INFO - Dependencies all met for <TaskInstance: AUTOMATISATION.Chargement_des_données_in_ELK scheduled__2023-03-13T00:00:30+00:00 [queued]>
[2023-03-13T19:56:56.557+0000] {taskinstance.py:1279} INFO - 
--------------------------------------------------------------------------------
[2023-03-13T19:56:56.557+0000] {taskinstance.py:1280} INFO - Starting attempt 4 of 4
[2023-03-13T19:56:56.557+0000] {taskinstance.py:1281} INFO - 
--------------------------------------------------------------------------------
[2023-03-13T19:56:56.579+0000] {taskinstance.py:1300} INFO - Executing <Task(BashOperator): Chargement_des_données_in_ELK> on 2023-03-13 00:00:30+00:00
[2023-03-13T19:56:56.582+0000] {standard_task_runner.py:55} INFO - Started process 39417 to run task
[2023-03-13T19:56:56.586+0000] {standard_task_runner.py:82} INFO - Running: ['airflow', 'tasks', 'run', 'AUTOMATISATION', 'Chargement_des_données_in_ELK', 'scheduled__2023-03-13T00:00:30+00:00', '--job-id', '133', '--raw', '--subdir', 'DAGS_FOLDER/main.py', '--cfg-path', '/tmp/tmpox99_5l3']
[2023-03-13T19:56:56.588+0000] {standard_task_runner.py:83} INFO - Job 133: Subtask Chargement_des_données_in_ELK
[2023-03-13T19:56:56.654+0000] {task_command.py:388} INFO - Running <TaskInstance: AUTOMATISATION.Chargement_des_données_in_ELK scheduled__2023-03-13T00:00:30+00:00 [running]> on host dev
[2023-03-13T19:56:56.721+0000] {taskinstance.py:1507} INFO - Exporting the following env vars:
AIRFLOW_CTX_DAG_OWNER=airflow
AIRFLOW_CTX_DAG_ID=AUTOMATISATION
AIRFLOW_CTX_TASK_ID=Chargement_des_données_in_ELK
AIRFLOW_CTX_EXECUTION_DATE=2023-03-13T00:00:30+00:00
AIRFLOW_CTX_TRY_NUMBER=4
AIRFLOW_CTX_DAG_RUN_ID=scheduled__2023-03-13T00:00:30+00:00
[2023-03-13T19:56:56.723+0000] {subprocess.py:63} INFO - Tmp dir root location: 
 /tmp
[2023-03-13T19:56:56.724+0000] {subprocess.py:75} INFO - Running command: ['/usr/bin/bash', '-c', 'bin/logstash --path.config /etc/logstash/conf.d/data.conf']
[2023-03-13T19:56:56.732+0000] {subprocess.py:86} INFO - Output:
[2023-03-13T19:56:56.733+0000] {subprocess.py:93} INFO - /usr/bin/bash: ligne 1: bin/logstash: Aucun fichier ou dossier de ce type
[2023-03-13T19:56:56.734+0000] {subprocess.py:97} INFO - Command exited with return code 127
[2023-03-13T19:56:56.744+0000] {taskinstance.py:1768} ERROR - Task failed with exception
Traceback (most recent call last):
  File "/home/dev/airflow/airflow/lib/python3.10/site-packages/airflow/operators/bash.py", line 196, in execute
    raise AirflowException(
airflow.exceptions.AirflowException: Bash command failed. The command returned a non-zero exit code 127.
[2023-03-13T19:56:56.748+0000] {taskinstance.py:1318} INFO - Marking task as FAILED. dag_id=AUTOMATISATION, task_id=Chargement_des_données_in_ELK, execution_date=20230313T000030, start_date=20230313T195656, end_date=20230313T195656
[2023-03-13T19:56:56.769+0000] {standard_task_runner.py:100} ERROR - Failed to execute job 133 for task Chargement_des_données_in_ELK (Bash command failed. The command returned a non-zero exit code 127.; 39417)
[2023-03-13T19:56:56.797+0000] {local_task_job.py:208} INFO - Task exited with return code 1
[2023-03-13T19:56:56.818+0000] {taskinstance.py:2578} INFO - 0 downstream tasks scheduled from follow-on schedule check
[2023-03-13T20:18:32.041+0000] {taskinstance.py:1083} INFO - Dependencies all met for <TaskInstance: AUTOMATISATION.Chargement_des_données_in_ELK scheduled__2023-03-13T00:00:30+00:00 [queued]>
[2023-03-13T20:18:32.055+0000] {taskinstance.py:1083} INFO - Dependencies all met for <TaskInstance: AUTOMATISATION.Chargement_des_données_in_ELK scheduled__2023-03-13T00:00:30+00:00 [queued]>
[2023-03-13T20:18:32.055+0000] {taskinstance.py:1279} INFO - 
--------------------------------------------------------------------------------
[2023-03-13T20:18:32.056+0000] {taskinstance.py:1280} INFO - Starting attempt 4 of 4
[2023-03-13T20:18:32.056+0000] {taskinstance.py:1281} INFO - 
--------------------------------------------------------------------------------
[2023-03-13T20:18:32.078+0000] {taskinstance.py:1300} INFO - Executing <Task(BashOperator): Chargement_des_données_in_ELK> on 2023-03-13 00:00:30+00:00
[2023-03-13T20:18:32.082+0000] {standard_task_runner.py:55} INFO - Started process 43301 to run task
[2023-03-13T20:18:32.087+0000] {standard_task_runner.py:82} INFO - Running: ['airflow', 'tasks', 'run', 'AUTOMATISATION', 'Chargement_des_données_in_ELK', 'scheduled__2023-03-13T00:00:30+00:00', '--job-id', '249', '--raw', '--subdir', 'DAGS_FOLDER/main.py', '--cfg-path', '/tmp/tmp0ohaui81']
[2023-03-13T20:18:32.089+0000] {standard_task_runner.py:83} INFO - Job 249: Subtask Chargement_des_données_in_ELK
[2023-03-13T20:18:32.157+0000] {task_command.py:388} INFO - Running <TaskInstance: AUTOMATISATION.Chargement_des_données_in_ELK scheduled__2023-03-13T00:00:30+00:00 [running]> on host dev
[2023-03-13T20:18:32.228+0000] {taskinstance.py:1507} INFO - Exporting the following env vars:
AIRFLOW_CTX_DAG_OWNER=airflow
AIRFLOW_CTX_DAG_ID=AUTOMATISATION
AIRFLOW_CTX_TASK_ID=Chargement_des_données_in_ELK
AIRFLOW_CTX_EXECUTION_DATE=2023-03-13T00:00:30+00:00
AIRFLOW_CTX_TRY_NUMBER=4
AIRFLOW_CTX_DAG_RUN_ID=scheduled__2023-03-13T00:00:30+00:00
[2023-03-13T20:18:32.229+0000] {subprocess.py:63} INFO - Tmp dir root location: 
 /tmp
[2023-03-13T20:18:32.230+0000] {subprocess.py:75} INFO - Running command: ['/usr/bin/bash', '-c', 'bin/logstash -f /home/dev/etc/logstash/conf.d/data.conf']
[2023-03-13T20:18:32.239+0000] {subprocess.py:86} INFO - Output:
[2023-03-13T20:18:32.241+0000] {subprocess.py:93} INFO - /usr/bin/bash: ligne 1: bin/logstash: Aucun fichier ou dossier de ce type
[2023-03-13T20:18:32.241+0000] {subprocess.py:97} INFO - Command exited with return code 127
[2023-03-13T20:18:32.251+0000] {taskinstance.py:1768} ERROR - Task failed with exception
Traceback (most recent call last):
  File "/home/dev/airflow/airflow/lib/python3.10/site-packages/airflow/operators/bash.py", line 196, in execute
    raise AirflowException(
airflow.exceptions.AirflowException: Bash command failed. The command returned a non-zero exit code 127.
[2023-03-13T20:18:32.256+0000] {taskinstance.py:1318} INFO - Marking task as FAILED. dag_id=AUTOMATISATION, task_id=Chargement_des_données_in_ELK, execution_date=20230313T000030, start_date=20230313T201832, end_date=20230313T201832
[2023-03-13T20:18:32.275+0000] {standard_task_runner.py:100} ERROR - Failed to execute job 249 for task Chargement_des_données_in_ELK (Bash command failed. The command returned a non-zero exit code 127.; 43301)
[2023-03-13T20:18:32.297+0000] {local_task_job.py:208} INFO - Task exited with return code 1
[2023-03-13T20:18:32.319+0000] {taskinstance.py:2578} INFO - 0 downstream tasks scheduled from follow-on schedule check
