[2023-03-13T19:51:53.555+0000] {taskinstance.py:1083} INFO - Dependencies all met for <TaskInstance: AUTOMATISATION.Chargement_des_données_in_ELK scheduled__2023-03-13T00:00:30+00:00 [queued]>
[2023-03-13T19:51:53.566+0000] {taskinstance.py:1083} INFO - Dependencies all met for <TaskInstance: AUTOMATISATION.Chargement_des_données_in_ELK scheduled__2023-03-13T00:00:30+00:00 [queued]>
[2023-03-13T19:51:53.566+0000] {taskinstance.py:1279} INFO - 
--------------------------------------------------------------------------------
[2023-03-13T19:51:53.567+0000] {taskinstance.py:1280} INFO - Starting attempt 3 of 4
[2023-03-13T19:51:53.567+0000] {taskinstance.py:1281} INFO - 
--------------------------------------------------------------------------------
[2023-03-13T19:51:53.587+0000] {taskinstance.py:1300} INFO - Executing <Task(BashOperator): Chargement_des_données_in_ELK> on 2023-03-13 00:00:30+00:00
[2023-03-13T19:51:53.590+0000] {standard_task_runner.py:55} INFO - Started process 38662 to run task
[2023-03-13T19:51:53.594+0000] {standard_task_runner.py:82} INFO - Running: ['airflow', 'tasks', 'run', 'AUTOMATISATION', 'Chargement_des_données_in_ELK', 'scheduled__2023-03-13T00:00:30+00:00', '--job-id', '110', '--raw', '--subdir', 'DAGS_FOLDER/main.py', '--cfg-path', '/tmp/tmpo6oc0gyw']
[2023-03-13T19:51:53.595+0000] {standard_task_runner.py:83} INFO - Job 110: Subtask Chargement_des_données_in_ELK
[2023-03-13T19:51:53.657+0000] {task_command.py:388} INFO - Running <TaskInstance: AUTOMATISATION.Chargement_des_données_in_ELK scheduled__2023-03-13T00:00:30+00:00 [running]> on host dev
[2023-03-13T19:51:53.717+0000] {taskinstance.py:1507} INFO - Exporting the following env vars:
AIRFLOW_CTX_DAG_OWNER=airflow
AIRFLOW_CTX_DAG_ID=AUTOMATISATION
AIRFLOW_CTX_TASK_ID=Chargement_des_données_in_ELK
AIRFLOW_CTX_EXECUTION_DATE=2023-03-13T00:00:30+00:00
AIRFLOW_CTX_TRY_NUMBER=3
AIRFLOW_CTX_DAG_RUN_ID=scheduled__2023-03-13T00:00:30+00:00
[2023-03-13T19:51:53.719+0000] {subprocess.py:63} INFO - Tmp dir root location: 
 /tmp
[2023-03-13T19:51:53.719+0000] {subprocess.py:75} INFO - Running command: ['/usr/bin/bash', '-c', 'bin/logstash --path.config /etc/logstash/conf.d/data.conf']
[2023-03-13T19:51:53.727+0000] {subprocess.py:86} INFO - Output:
[2023-03-13T19:51:53.728+0000] {subprocess.py:93} INFO - /usr/bin/bash: ligne 1: bin/logstash: Aucun fichier ou dossier de ce type
[2023-03-13T19:51:53.729+0000] {subprocess.py:97} INFO - Command exited with return code 127
[2023-03-13T19:51:53.739+0000] {taskinstance.py:1768} ERROR - Task failed with exception
Traceback (most recent call last):
  File "/home/dev/airflow/airflow/lib/python3.10/site-packages/airflow/operators/bash.py", line 196, in execute
    raise AirflowException(
airflow.exceptions.AirflowException: Bash command failed. The command returned a non-zero exit code 127.
[2023-03-13T19:51:53.743+0000] {taskinstance.py:1318} INFO - Marking task as UP_FOR_RETRY. dag_id=AUTOMATISATION, task_id=Chargement_des_données_in_ELK, execution_date=20230313T000030, start_date=20230313T195153, end_date=20230313T195153
[2023-03-13T19:51:53.761+0000] {standard_task_runner.py:100} ERROR - Failed to execute job 110 for task Chargement_des_données_in_ELK (Bash command failed. The command returned a non-zero exit code 127.; 38662)
[2023-03-13T19:51:53.805+0000] {local_task_job.py:208} INFO - Task exited with return code 1
[2023-03-13T19:51:53.827+0000] {taskinstance.py:2578} INFO - 0 downstream tasks scheduled from follow-on schedule check
[2023-03-13T20:13:23.135+0000] {taskinstance.py:1083} INFO - Dependencies all met for <TaskInstance: AUTOMATISATION.Chargement_des_données_in_ELK scheduled__2023-03-13T00:00:30+00:00 [queued]>
[2023-03-13T20:13:23.148+0000] {taskinstance.py:1083} INFO - Dependencies all met for <TaskInstance: AUTOMATISATION.Chargement_des_données_in_ELK scheduled__2023-03-13T00:00:30+00:00 [queued]>
[2023-03-13T20:13:23.149+0000] {taskinstance.py:1279} INFO - 
--------------------------------------------------------------------------------
[2023-03-13T20:13:23.149+0000] {taskinstance.py:1280} INFO - Starting attempt 3 of 4
[2023-03-13T20:13:23.149+0000] {taskinstance.py:1281} INFO - 
--------------------------------------------------------------------------------
[2023-03-13T20:13:23.172+0000] {taskinstance.py:1300} INFO - Executing <Task(BashOperator): Chargement_des_données_in_ELK> on 2023-03-13 00:00:30+00:00
[2023-03-13T20:13:23.176+0000] {standard_task_runner.py:55} INFO - Started process 42518 to run task
[2023-03-13T20:13:23.180+0000] {standard_task_runner.py:82} INFO - Running: ['airflow', 'tasks', 'run', 'AUTOMATISATION', 'Chargement_des_données_in_ELK', 'scheduled__2023-03-13T00:00:30+00:00', '--job-id', '222', '--raw', '--subdir', 'DAGS_FOLDER/main.py', '--cfg-path', '/tmp/tmpmbf5bs12']
[2023-03-13T20:13:23.182+0000] {standard_task_runner.py:83} INFO - Job 222: Subtask Chargement_des_données_in_ELK
[2023-03-13T20:13:23.251+0000] {task_command.py:388} INFO - Running <TaskInstance: AUTOMATISATION.Chargement_des_données_in_ELK scheduled__2023-03-13T00:00:30+00:00 [running]> on host dev
[2023-03-13T20:13:23.317+0000] {taskinstance.py:1507} INFO - Exporting the following env vars:
AIRFLOW_CTX_DAG_OWNER=airflow
AIRFLOW_CTX_DAG_ID=AUTOMATISATION
AIRFLOW_CTX_TASK_ID=Chargement_des_données_in_ELK
AIRFLOW_CTX_EXECUTION_DATE=2023-03-13T00:00:30+00:00
AIRFLOW_CTX_TRY_NUMBER=3
AIRFLOW_CTX_DAG_RUN_ID=scheduled__2023-03-13T00:00:30+00:00
[2023-03-13T20:13:23.319+0000] {subprocess.py:63} INFO - Tmp dir root location: 
 /tmp
[2023-03-13T20:13:23.319+0000] {subprocess.py:75} INFO - Running command: ['/usr/bin/bash', '-c', 'bin/logstash -f /home/dev/etc/logstash/conf.d/data.conf']
[2023-03-13T20:13:23.328+0000] {subprocess.py:86} INFO - Output:
[2023-03-13T20:13:23.330+0000] {subprocess.py:93} INFO - /usr/bin/bash: ligne 1: bin/logstash: Aucun fichier ou dossier de ce type
[2023-03-13T20:13:23.331+0000] {subprocess.py:97} INFO - Command exited with return code 127
[2023-03-13T20:13:23.340+0000] {taskinstance.py:1768} ERROR - Task failed with exception
Traceback (most recent call last):
  File "/home/dev/airflow/airflow/lib/python3.10/site-packages/airflow/operators/bash.py", line 196, in execute
    raise AirflowException(
airflow.exceptions.AirflowException: Bash command failed. The command returned a non-zero exit code 127.
[2023-03-13T20:13:23.345+0000] {taskinstance.py:1318} INFO - Marking task as UP_FOR_RETRY. dag_id=AUTOMATISATION, task_id=Chargement_des_données_in_ELK, execution_date=20230313T000030, start_date=20230313T201323, end_date=20230313T201323
[2023-03-13T20:13:23.364+0000] {standard_task_runner.py:100} ERROR - Failed to execute job 222 for task Chargement_des_données_in_ELK (Bash command failed. The command returned a non-zero exit code 127.; 42518)
[2023-03-13T20:13:23.391+0000] {local_task_job.py:208} INFO - Task exited with return code 1
[2023-03-13T20:13:23.411+0000] {taskinstance.py:2578} INFO - 0 downstream tasks scheduled from follow-on schedule check
