[2023-03-13T19:57:34.443+0000] {taskinstance.py:1083} INFO - Dependencies all met for <TaskInstance: AUTOMATISATION.Chargement_des_données_in_ELK scheduled__2023-03-13T00:00:42+00:00 [queued]>
[2023-03-13T19:57:34.456+0000] {taskinstance.py:1083} INFO - Dependencies all met for <TaskInstance: AUTOMATISATION.Chargement_des_données_in_ELK scheduled__2023-03-13T00:00:42+00:00 [queued]>
[2023-03-13T19:57:34.457+0000] {taskinstance.py:1279} INFO - 
--------------------------------------------------------------------------------
[2023-03-13T19:57:34.457+0000] {taskinstance.py:1280} INFO - Starting attempt 4 of 4
[2023-03-13T19:57:34.457+0000] {taskinstance.py:1281} INFO - 
--------------------------------------------------------------------------------
[2023-03-13T19:57:34.481+0000] {taskinstance.py:1300} INFO - Executing <Task(BashOperator): Chargement_des_données_in_ELK> on 2023-03-13 00:00:42+00:00
[2023-03-13T19:57:34.489+0000] {standard_task_runner.py:55} INFO - Started process 39569 to run task
[2023-03-13T19:57:34.500+0000] {standard_task_runner.py:82} INFO - Running: ['airflow', 'tasks', 'run', 'AUTOMATISATION', 'Chargement_des_données_in_ELK', 'scheduled__2023-03-13T00:00:42+00:00', '--job-id', '142', '--raw', '--subdir', 'DAGS_FOLDER/main.py', '--cfg-path', '/tmp/tmpnt28kzug']
[2023-03-13T19:57:34.503+0000] {standard_task_runner.py:83} INFO - Job 142: Subtask Chargement_des_données_in_ELK
[2023-03-13T19:57:34.577+0000] {task_command.py:388} INFO - Running <TaskInstance: AUTOMATISATION.Chargement_des_données_in_ELK scheduled__2023-03-13T00:00:42+00:00 [running]> on host dev
[2023-03-13T19:57:34.644+0000] {taskinstance.py:1507} INFO - Exporting the following env vars:
AIRFLOW_CTX_DAG_OWNER=airflow
AIRFLOW_CTX_DAG_ID=AUTOMATISATION
AIRFLOW_CTX_TASK_ID=Chargement_des_données_in_ELK
AIRFLOW_CTX_EXECUTION_DATE=2023-03-13T00:00:42+00:00
AIRFLOW_CTX_TRY_NUMBER=4
AIRFLOW_CTX_DAG_RUN_ID=scheduled__2023-03-13T00:00:42+00:00
[2023-03-13T19:57:34.646+0000] {subprocess.py:63} INFO - Tmp dir root location: 
 /tmp
[2023-03-13T19:57:34.646+0000] {subprocess.py:75} INFO - Running command: ['/usr/bin/bash', '-c', 'bin/logstash --path.config /etc/logstash/conf.d/data.conf']
[2023-03-13T19:57:34.654+0000] {subprocess.py:86} INFO - Output:
[2023-03-13T19:57:34.656+0000] {subprocess.py:93} INFO - /usr/bin/bash: ligne 1: bin/logstash: Aucun fichier ou dossier de ce type
[2023-03-13T19:57:34.656+0000] {subprocess.py:97} INFO - Command exited with return code 127
[2023-03-13T19:57:34.666+0000] {taskinstance.py:1768} ERROR - Task failed with exception
Traceback (most recent call last):
  File "/home/dev/airflow/airflow/lib/python3.10/site-packages/airflow/operators/bash.py", line 196, in execute
    raise AirflowException(
airflow.exceptions.AirflowException: Bash command failed. The command returned a non-zero exit code 127.
[2023-03-13T19:57:34.670+0000] {taskinstance.py:1318} INFO - Marking task as FAILED. dag_id=AUTOMATISATION, task_id=Chargement_des_données_in_ELK, execution_date=20230313T000042, start_date=20230313T195734, end_date=20230313T195734
[2023-03-13T19:57:34.689+0000] {standard_task_runner.py:100} ERROR - Failed to execute job 142 for task Chargement_des_données_in_ELK (Bash command failed. The command returned a non-zero exit code 127.; 39569)
[2023-03-13T19:57:34.714+0000] {local_task_job.py:208} INFO - Task exited with return code 1
[2023-03-13T19:57:34.734+0000] {taskinstance.py:2578} INFO - 0 downstream tasks scheduled from follow-on schedule check
[2023-03-13T20:18:56.129+0000] {taskinstance.py:1083} INFO - Dependencies all met for <TaskInstance: AUTOMATISATION.Chargement_des_données_in_ELK scheduled__2023-03-13T00:00:42+00:00 [queued]>
[2023-03-13T20:18:56.143+0000] {taskinstance.py:1083} INFO - Dependencies all met for <TaskInstance: AUTOMATISATION.Chargement_des_données_in_ELK scheduled__2023-03-13T00:00:42+00:00 [queued]>
[2023-03-13T20:18:56.143+0000] {taskinstance.py:1279} INFO - 
--------------------------------------------------------------------------------
[2023-03-13T20:18:56.143+0000] {taskinstance.py:1280} INFO - Starting attempt 4 of 4
[2023-03-13T20:18:56.143+0000] {taskinstance.py:1281} INFO - 
--------------------------------------------------------------------------------
[2023-03-13T20:18:56.165+0000] {taskinstance.py:1300} INFO - Executing <Task(BashOperator): Chargement_des_données_in_ELK> on 2023-03-13 00:00:42+00:00
[2023-03-13T20:18:56.169+0000] {standard_task_runner.py:55} INFO - Started process 43377 to run task
[2023-03-13T20:18:56.173+0000] {standard_task_runner.py:82} INFO - Running: ['airflow', 'tasks', 'run', 'AUTOMATISATION', 'Chargement_des_données_in_ELK', 'scheduled__2023-03-13T00:00:42+00:00', '--job-id', '256', '--raw', '--subdir', 'DAGS_FOLDER/main.py', '--cfg-path', '/tmp/tmpdltjkdrg']
[2023-03-13T20:18:56.175+0000] {standard_task_runner.py:83} INFO - Job 256: Subtask Chargement_des_données_in_ELK
[2023-03-13T20:18:56.242+0000] {task_command.py:388} INFO - Running <TaskInstance: AUTOMATISATION.Chargement_des_données_in_ELK scheduled__2023-03-13T00:00:42+00:00 [running]> on host dev
[2023-03-13T20:18:56.308+0000] {taskinstance.py:1507} INFO - Exporting the following env vars:
AIRFLOW_CTX_DAG_OWNER=airflow
AIRFLOW_CTX_DAG_ID=AUTOMATISATION
AIRFLOW_CTX_TASK_ID=Chargement_des_données_in_ELK
AIRFLOW_CTX_EXECUTION_DATE=2023-03-13T00:00:42+00:00
AIRFLOW_CTX_TRY_NUMBER=4
AIRFLOW_CTX_DAG_RUN_ID=scheduled__2023-03-13T00:00:42+00:00
[2023-03-13T20:18:56.310+0000] {subprocess.py:63} INFO - Tmp dir root location: 
 /tmp
[2023-03-13T20:18:56.311+0000] {subprocess.py:75} INFO - Running command: ['/usr/bin/bash', '-c', 'bin/logstash -f /home/dev/etc/logstash/conf.d/data.conf']
[2023-03-13T20:18:56.319+0000] {subprocess.py:86} INFO - Output:
[2023-03-13T20:18:56.321+0000] {subprocess.py:93} INFO - /usr/bin/bash: ligne 1: bin/logstash: Aucun fichier ou dossier de ce type
[2023-03-13T20:18:56.321+0000] {subprocess.py:97} INFO - Command exited with return code 127
[2023-03-13T20:18:56.331+0000] {taskinstance.py:1768} ERROR - Task failed with exception
Traceback (most recent call last):
  File "/home/dev/airflow/airflow/lib/python3.10/site-packages/airflow/operators/bash.py", line 196, in execute
    raise AirflowException(
airflow.exceptions.AirflowException: Bash command failed. The command returned a non-zero exit code 127.
[2023-03-13T20:18:56.336+0000] {taskinstance.py:1318} INFO - Marking task as FAILED. dag_id=AUTOMATISATION, task_id=Chargement_des_données_in_ELK, execution_date=20230313T000042, start_date=20230313T201856, end_date=20230313T201856
[2023-03-13T20:18:56.355+0000] {standard_task_runner.py:100} ERROR - Failed to execute job 256 for task Chargement_des_données_in_ELK (Bash command failed. The command returned a non-zero exit code 127.; 43377)
[2023-03-13T20:18:56.384+0000] {local_task_job.py:208} INFO - Task exited with return code 1
[2023-03-13T20:18:56.404+0000] {taskinstance.py:2578} INFO - 0 downstream tasks scheduled from follow-on schedule check
